2022-06-30 12:05:19,697 - 23048 - hummingbot.core.utils.async_utils - ERROR - Unhandled error in background task: Return value already set. Application.exit() failed.
Traceback (most recent call last):
  File "/mnt/e/Projects/hummingbot/hummingbot/hummingbot/core/utils/async_utils.py", line 9, in safe_wrapper
    return await c
  File "/mnt/e/Projects/hummingbot/hummingbot/hummingbot/client/command/exit_command.py", line 37, in exit_loop
    self.app.exit()
  File "/mnt/e/Projects/hummingbot/hummingbot/hummingbot/client/ui/hummingbot_cli.py", line 193, in exit
    self.app.exit()
  File "/home/knight/miniconda3/envs/hummingbot/lib/python3.8/site-packages/prompt_toolkit/application/application.py", line 1086, in exit
    raise Exception("Return value already set. Application.exit() failed.")
Exception: Return value already set. Application.exit() failed.
2022-06-30 12:05:19,931 - 23048 - hummingbot.core.utils.trading_pair_fetcher - ERROR - Connector bitmart failed to retrieve its trading pairs. Trading pairs autocompletion won't work.
Traceback (most recent call last):
  File "/mnt/e/Projects/hummingbot/hummingbot/hummingbot/core/utils/trading_pair_fetcher.py", line 74, in call_fetch_pairs
    self.trading_pairs[exchange_name] = await fetch_fn
  File "/mnt/e/Projects/hummingbot/hummingbot/hummingbot/connector/exchange/bitmart/bitmart_api_order_book_data_source.py", line 89, in fetch_trading_pairs
    response = await rest_assistant.call(request=request, timeout=10)
  File "/mnt/e/Projects/hummingbot/hummingbot/hummingbot/core/web_assistant/rest_assistant.py", line 35, in call
    resp = await wait_for(self._connection.call(request), timeout)
  File "/home/knight/miniconda3/envs/hummingbot/lib/python3.8/asyncio/tasks.py", line 490, in wait_for
    raise exceptions.TimeoutError()
asyncio.exceptions.TimeoutError
2022-06-30 12:05:19,962 - 23048 - root - INFO - Error fetching data from https://api.gateio.ws/api/v4/spot/currency_pairs. HTTP status is None. Retrying in 4s.
2022-06-30 12:05:19,962 - 23048 - root - INFO - Error fetching data from https://api.gateio.ws/api/v4/spot/currency_pairs. HTTP status is None. Retrying in 4s.
2022-06-30 12:06:32,429 - 23292 - hummingbot.connector.exchange.altmarkets.altmarkets_api_order_book_data_source - NETWORK - Error fetching data from https://v2.altmarkets.io/api/v2/peatio/public/markets. HTTP status is 403. Retrying in 4s. <!DOCTYPE html>
<html lang="en">
<head>
    <meta charset="utf-8" />
    <title>AltMarkets.io | Sche ... (truncated)
2022-06-30 12:06:38,120 - 23292 - hummingbot.connector.time_synchronizer - NETWORK - Error getting server time.
Traceback (most recent call last):
  File "/mnt/e/Projects/hummingbot/hummingbot/hummingbot/connector/time_synchronizer.py", line 59, in update_server_time_offset_with_time_provider
    server_time_ms: float = await time_provider
  File "/mnt/e/Projects/hummingbot/hummingbot/hummingbot/connector/exchange/binance/binance_web_utils.py", line 127, in get_current_server_time
    response = await api_request(
  File "/mnt/e/Projects/hummingbot/hummingbot/hummingbot/connector/exchange/binance/binance_web_utils.py", line 115, in api_request
    raise IOError(f"Error executing request {method.name} {path}. "
OSError: Error executing request GET /time. HTTP status is 403. Error: <!DOCTYPE HTML PUBLIC "-//W3C//DTD HTML 4.01 Transitional//EN" "http://www.w3.org/TR/html4/loose.dtd">
<HTML><HEAD><META HTTP-EQUIV="Content-Type" CONTENT="text/html; charset=iso-8859-1">
<TITLE>ERROR: The request could not be satisfied</TITLE>
</HEAD><BODY>
<H1>403 ERROR</H1>
<H2>The request could not be satisfied.</H2>
<HR noshade size="1px">
The Amazon CloudFront distribution is configured to block access from your country.
We can't connect to the server for this app or website at this time. There might be too much traffic or a configuration error. Try again later, or contact the app or website owner.
<BR clear="all">
If you provide content to customers through CloudFront, you can find steps to troubleshoot and help prevent this error by reviewing the CloudFront documentation.
<BR clear="all">
<HR noshade size="1px">
<PRE>
Generated by cloudfront (CloudFront)
Request ID: f4tVBkHGzXVX4VDXUIXQthX2LFv09-i9cht3tGoMPQlcC_LVyRepxw==
</PRE>
<ADDRESS>
</ADDRESS>
</BODY></HTML>
2022-06-30 12:06:38,160 - 23292 - hummingbot.connector.time_synchronizer - WARNING - Could not refresh server time. Check network connection.
2022-06-30 12:06:38,662 - 23292 - hummingbot.connector.exchange.altmarkets.altmarkets_api_order_book_data_source - NETWORK - Error fetching data from https://v2.altmarkets.io/api/v2/peatio/public/markets. HTTP status is 403. Retrying in 7s. <!DOCTYPE html>
<html lang="en">
<head>
    <meta charset="utf-8" />
    <title>AltMarkets.io | Sche ... (truncated)
2022-06-30 12:06:39,715 - 23292 - hummingbot.connector.exchange.binance.binance_api_order_book_data_source - ERROR - There was an error requesting exchange info (Error executing request GET /exchangeInfo. HTTP status is 403. Error: <!DOCTYPE HTML PUBLIC "-//W3C//DTD HTML 4.01 Transitional//EN" "http://www.w3.org/TR/html4/loose.dtd">
<HTML><HEAD><META HTTP-EQUIV="Content-Type" CONTENT="text/html; charset=iso-8859-1">
<TITLE>ERROR: The request could not be satisfied</TITLE>
</HEAD><BODY>
<H1>403 ERROR</H1>
<H2>The request could not be satisfied.</H2>
<HR noshade size="1px">
The Amazon CloudFront distribution is configured to block access from your country.
We can't connect to the server for this app or website at this time. There might be too much traffic or a configuration error. Try again later, or contact the app or website owner.
<BR clear="all">
If you provide content to customers through CloudFront, you can find steps to troubleshoot and help prevent this error by reviewing the CloudFront documentation.
<BR clear="all">
<HR noshade size="1px">
<PRE>
Generated by cloudfront (CloudFront)
Request ID: Ju54oNBC4TqqeZXXJHxPgDF1dZY3plymUyQy613CQLQQ9ee3m5TSDA==
</PRE>
<ADDRESS>
</ADDRESS>
</BODY></HTML>)
2022-06-30 12:06:47,435 - 23292 - hummingbot.connector.exchange.altmarkets.altmarkets_api_order_book_data_source - NETWORK - Error fetching data from https://v2.altmarkets.io/api/v2/peatio/public/markets. HTTP status is 403. Retrying in 31s. <!DOCTYPE html>
<html lang="en">
<head>
    <meta charset="utf-8" />
    <title>AltMarkets.io | Sche ... (truncated)
2022-06-30 12:07:13,879 - 23292 - hummingbot.core.utils.async_utils - ERROR - Unhandled error in background task: __init__() got an unexpected keyword argument 'dexfin_secret_key'
Traceback (most recent call last):
  File "/mnt/e/Projects/hummingbot/hummingbot/hummingbot/core/utils/async_utils.py", line 9, in safe_wrapper
    return await c
  File "/mnt/e/Projects/hummingbot/hummingbot/hummingbot/client/command/connect_command.py", line 76, in connect_exchange
    err_msg = await asyncio.wait_for(
  File "/home/knight/miniconda3/envs/hummingbot/lib/python3.8/asyncio/tasks.py", line 483, in wait_for
    return fut.result()
  File "/mnt/e/Projects/hummingbot/hummingbot/hummingbot/user/user_balances.py", line 55, in add_exchange
    market = UserBalances.connect_market(exchange, **api_details)
  File "/mnt/e/Projects/hummingbot/hummingbot/hummingbot/user/user_balances.py", line 23, in connect_market
    connector = connector_class(**init_params)
TypeError: __init__() got an unexpected keyword argument 'dexfin_secret_key'
2022-06-30 12:07:19,983 - 23292 - hummingbot.connector.exchange.altmarkets.altmarkets_api_order_book_data_source - NETWORK - Error fetching data from https://v2.altmarkets.io/api/v2/peatio/public/markets. HTTP status is 403. Retrying in 280s. <!DOCTYPE html>
<html lang="en">
<head>
    <meta charset="utf-8" />
    <title>AltMarkets.io | Sche ... (truncated)
2022-06-30 12:07:43,498 - 23336 - hummingbot.connector.exchange.altmarkets.altmarkets_api_order_book_data_source - NETWORK - Error fetching data from https://v2.altmarkets.io/api/v2/peatio/public/markets. HTTP status is 403. Retrying in 4s. <!DOCTYPE html>
<html lang="en">
<head>
    <meta charset="utf-8" />
    <title>AltMarkets.io | Sche ... (truncated)
2022-06-30 12:07:47,731 - 23336 - hummingbot.connector.time_synchronizer - NETWORK - Error getting server time.
Traceback (most recent call last):
  File "/mnt/e/Projects/hummingbot/hummingbot/hummingbot/connector/time_synchronizer.py", line 59, in update_server_time_offset_with_time_provider
    server_time_ms: float = await time_provider
  File "/mnt/e/Projects/hummingbot/hummingbot/hummingbot/connector/exchange/binance/binance_web_utils.py", line 127, in get_current_server_time
    response = await api_request(
  File "/mnt/e/Projects/hummingbot/hummingbot/hummingbot/connector/exchange/binance/binance_web_utils.py", line 115, in api_request
    raise IOError(f"Error executing request {method.name} {path}. "
OSError: Error executing request GET /time. HTTP status is 403. Error: <!DOCTYPE HTML PUBLIC "-//W3C//DTD HTML 4.01 Transitional//EN" "http://www.w3.org/TR/html4/loose.dtd">
<HTML><HEAD><META HTTP-EQUIV="Content-Type" CONTENT="text/html; charset=iso-8859-1">
<TITLE>ERROR: The request could not be satisfied</TITLE>
</HEAD><BODY>
<H1>403 ERROR</H1>
<H2>The request could not be satisfied.</H2>
<HR noshade size="1px">
The Amazon CloudFront distribution is configured to block access from your country.
We can't connect to the server for this app or website at this time. There might be too much traffic or a configuration error. Try again later, or contact the app or website owner.
<BR clear="all">
If you provide content to customers through CloudFront, you can find steps to troubleshoot and help prevent this error by reviewing the CloudFront documentation.
<BR clear="all">
<HR noshade size="1px">
<PRE>
Generated by cloudfront (CloudFront)
Request ID: Nic0QjzSvIPi684VvstpF1Lar8qpnfvvZy7DHAd51-aJeXUaAPRjDQ==
</PRE>
<ADDRESS>
</ADDRESS>
</BODY></HTML>
2022-06-30 12:07:47,738 - 23336 - hummingbot.connector.time_synchronizer - WARNING - Could not refresh server time. Check network connection.
2022-06-30 12:07:47,934 - 23336 - hummingbot.connector.exchange.binance.binance_api_order_book_data_source - ERROR - There was an error requesting exchange info (Error executing request GET /exchangeInfo. HTTP status is 403. Error: <!DOCTYPE HTML PUBLIC "-//W3C//DTD HTML 4.01 Transitional//EN" "http://www.w3.org/TR/html4/loose.dtd">
<HTML><HEAD><META HTTP-EQUIV="Content-Type" CONTENT="text/html; charset=iso-8859-1">
<TITLE>ERROR: The request could not be satisfied</TITLE>
</HEAD><BODY>
<H1>403 ERROR</H1>
<H2>The request could not be satisfied.</H2>
<HR noshade size="1px">
The Amazon CloudFront distribution is configured to block access from your country.
We can't connect to the server for this app or website at this time. There might be too much traffic or a configuration error. Try again later, or contact the app or website owner.
<BR clear="all">
If you provide content to customers through CloudFront, you can find steps to troubleshoot and help prevent this error by reviewing the CloudFront documentation.
<BR clear="all">
<HR noshade size="1px">
<PRE>
Generated by cloudfront (CloudFront)
Request ID: of_iIa-dRjSCmKejLVpxX6jUKo4voSaa3AKNoNZX6DdaIkyQwK4LSg==
</PRE>
<ADDRESS>
</ADDRESS>
</BODY></HTML>)
2022-06-30 12:07:48,565 - 23336 - hummingbot.connector.exchange.altmarkets.altmarkets_api_order_book_data_source - NETWORK - Error fetching data from https://v2.altmarkets.io/api/v2/peatio/public/markets. HTTP status is 403. Retrying in 7s. <!DOCTYPE html>
<html lang="en">
<head>
    <meta charset="utf-8" />
    <title>AltMarkets.io | Sche ... (truncated)
2022-06-30 12:08:00,296 - 23336 - hummingbot.connector.exchange.altmarkets.altmarkets_api_order_book_data_source - NETWORK - Error fetching data from https://v2.altmarkets.io/api/v2/peatio/public/markets. HTTP status is 403. Retrying in 31s. <!DOCTYPE html>
<html lang="en">
<head>
    <meta charset="utf-8" />
    <title>AltMarkets.io | Sche ... (truncated)
2022-06-30 12:08:32,570 - 23336 - hummingbot.connector.exchange.altmarkets.altmarkets_api_order_book_data_source - NETWORK - Error fetching data from https://v2.altmarkets.io/api/v2/peatio/public/markets. HTTP status is 403. Retrying in 277s. <!DOCTYPE html>
<html lang="en">
<head>
    <meta charset="utf-8" />
    <title>AltMarkets.io | Sche ... (truncated)
2022-06-30 12:09:57,024 - 23336 - hummingbot.core.utils.trading_pair_fetcher - ERROR - Connector probit_kr failed to retrieve its trading pairs. Trading pairs autocompletion won't work.
Traceback (most recent call last):
  File "/home/knight/miniconda3/envs/hummingbot/lib/python3.8/site-packages/aiohttp/connector.py", line 969, in _wrap_create_connection
    return await self._loop.create_connection(*args, **kwargs)  # type: ignore  # noqa
  File "/home/knight/miniconda3/envs/hummingbot/lib/python3.8/asyncio/base_events.py", line 1025, in create_connection
    raise exceptions[0]
  File "/home/knight/miniconda3/envs/hummingbot/lib/python3.8/asyncio/base_events.py", line 1010, in create_connection
    sock = await self._connect_sock(
  File "/home/knight/miniconda3/envs/hummingbot/lib/python3.8/asyncio/base_events.py", line 924, in _connect_sock
    await self.sock_connect(sock, address)
  File "/home/knight/miniconda3/envs/hummingbot/lib/python3.8/asyncio/selector_events.py", line 494, in sock_connect
    return await fut
  File "/home/knight/miniconda3/envs/hummingbot/lib/python3.8/asyncio/selector_events.py", line 526, in _sock_connect_cb
    raise OSError(err, f'Connect call failed {address}')
TimeoutError: [Errno 110] Connect call failed ('55.28.36.18', 443)

The above exception was the direct cause of the following exception:

Traceback (most recent call last):
  File "/mnt/e/Projects/hummingbot/hummingbot/hummingbot/core/utils/trading_pair_fetcher.py", line 74, in call_fetch_pairs
    self.trading_pairs[exchange_name] = await fetch_fn
  File "/mnt/e/Projects/hummingbot/hummingbot/hummingbot/connector/exchange/probit/probit_api_order_book_data_source.py", line 81, in fetch_trading_pairs
    async with client.get(f"{CONSTANTS.MARKETS_URL.format(domain)}") as response:
  File "/home/knight/miniconda3/envs/hummingbot/lib/python3.8/site-packages/aiohttp/client.py", line 1117, in __aenter__
    self._resp = await self._coro
  File "/home/knight/miniconda3/envs/hummingbot/lib/python3.8/site-packages/aiohttp/client.py", line 520, in _request
    conn = await self._connector.connect(
  File "/home/knight/miniconda3/envs/hummingbot/lib/python3.8/site-packages/aiohttp/connector.py", line 535, in connect
    proto = await self._create_connection(req, traces, timeout)
  File "/home/knight/miniconda3/envs/hummingbot/lib/python3.8/site-packages/aiohttp/connector.py", line 892, in _create_connection
    _, proto = await self._create_direct_connection(req, traces, timeout)
  File "/home/knight/miniconda3/envs/hummingbot/lib/python3.8/site-packages/aiohttp/connector.py", line 1051, in _create_direct_connection
    raise last_exc
  File "/home/knight/miniconda3/envs/hummingbot/lib/python3.8/site-packages/aiohttp/connector.py", line 1020, in _create_direct_connection
    transp, proto = await self._wrap_create_connection(
  File "/home/knight/miniconda3/envs/hummingbot/lib/python3.8/site-packages/aiohttp/connector.py", line 975, in _wrap_create_connection
    raise client_error(req.connection_key, exc) from exc
aiohttp.client_exceptions.ClientConnectorError: Cannot connect to host api.probit.kr:443 ssl:default [Connect call failed ('55.28.36.18', 443)]
2022-06-30 12:11:57,260 - 23381 - hummingbot.connector.exchange.altmarkets.altmarkets_api_order_book_data_source - NETWORK - Error fetching data from https://v2.altmarkets.io/api/v2/peatio/public/markets. HTTP status is 403. Retrying in 4s. <!DOCTYPE html>
<html lang="en">
<head>
    <meta charset="utf-8" />
    <title>AltMarkets.io | Sche ... (truncated)
2022-06-30 12:12:05,122 - 23381 - hummingbot.connector.time_synchronizer - NETWORK - Error getting server time.
Traceback (most recent call last):
  File "/mnt/e/Projects/hummingbot/hummingbot/hummingbot/connector/time_synchronizer.py", line 59, in update_server_time_offset_with_time_provider
    server_time_ms: float = await time_provider
  File "/mnt/e/Projects/hummingbot/hummingbot/hummingbot/connector/exchange/binance/binance_web_utils.py", line 127, in get_current_server_time
    response = await api_request(
  File "/mnt/e/Projects/hummingbot/hummingbot/hummingbot/connector/exchange/binance/binance_web_utils.py", line 115, in api_request
    raise IOError(f"Error executing request {method.name} {path}. "
OSError: Error executing request GET /time. HTTP status is 403. Error: <!DOCTYPE HTML PUBLIC "-//W3C//DTD HTML 4.01 Transitional//EN" "http://www.w3.org/TR/html4/loose.dtd">
<HTML><HEAD><META HTTP-EQUIV="Content-Type" CONTENT="text/html; charset=iso-8859-1">
<TITLE>ERROR: The request could not be satisfied</TITLE>
</HEAD><BODY>
<H1>403 ERROR</H1>
<H2>The request could not be satisfied.</H2>
<HR noshade size="1px">
The Amazon CloudFront distribution is configured to block access from your country.
We can't connect to the server for this app or website at this time. There might be too much traffic or a configuration error. Try again later, or contact the app or website owner.
<BR clear="all">
If you provide content to customers through CloudFront, you can find steps to troubleshoot and help prevent this error by reviewing the CloudFront documentation.
<BR clear="all">
<HR noshade size="1px">
<PRE>
Generated by cloudfront (CloudFront)
Request ID: nqB3YCL3CCXRQLx7N6yve1Uk6iImMRyzXZ8N7LnJJiLArvsJO-l3BA==
</PRE>
<ADDRESS>
</ADDRESS>
</BODY></HTML>
2022-06-30 12:12:05,128 - 23381 - hummingbot.connector.time_synchronizer - WARNING - Could not refresh server time. Check network connection.
2022-06-30 12:12:05,186 - 23381 - hummingbot.connector.exchange.altmarkets.altmarkets_api_order_book_data_source - NETWORK - Error fetching data from https://v2.altmarkets.io/api/v2/peatio/public/markets. HTTP status is 403. Retrying in 7s. <!DOCTYPE html>
<html lang="en">
<head>
    <meta charset="utf-8" />
    <title>AltMarkets.io | Sche ... (truncated)
2022-06-30 12:12:05,467 - 23381 - hummingbot.connector.exchange.binance.binance_api_order_book_data_source - ERROR - There was an error requesting exchange info (Error executing request GET /exchangeInfo. HTTP status is 403. Error: <!DOCTYPE HTML PUBLIC "-//W3C//DTD HTML 4.01 Transitional//EN" "http://www.w3.org/TR/html4/loose.dtd">
<HTML><HEAD><META HTTP-EQUIV="Content-Type" CONTENT="text/html; charset=iso-8859-1">
<TITLE>ERROR: The request could not be satisfied</TITLE>
</HEAD><BODY>
<H1>403 ERROR</H1>
<H2>The request could not be satisfied.</H2>
<HR noshade size="1px">
The Amazon CloudFront distribution is configured to block access from your country.
We can't connect to the server for this app or website at this time. There might be too much traffic or a configuration error. Try again later, or contact the app or website owner.
<BR clear="all">
If you provide content to customers through CloudFront, you can find steps to troubleshoot and help prevent this error by reviewing the CloudFront documentation.
<BR clear="all">
<HR noshade size="1px">
<PRE>
Generated by cloudfront (CloudFront)
Request ID: I7CFEcPCSMNXSeV87YbRFo-ntzmdI1pT1hN2FePxSAF07fPHB29wGw==
</PRE>
<ADDRESS>
</ADDRESS>
</BODY></HTML>)
2022-06-30 12:12:14,925 - 23381 - hummingbot.connector.exchange.altmarkets.altmarkets_api_order_book_data_source - NETWORK - Error fetching data from https://v2.altmarkets.io/api/v2/peatio/public/markets. HTTP status is 403. Retrying in 31s. <!DOCTYPE html>
<html lang="en">
<head>
    <meta charset="utf-8" />
    <title>AltMarkets.io | Sche ... (truncated)
2022-06-30 12:12:44,586 - 23426 - hummingbot.connector.exchange.altmarkets.altmarkets_api_order_book_data_source - NETWORK - Error fetching data from https://v2.altmarkets.io/api/v2/peatio/public/markets. HTTP status is 403. Retrying in 4s. <!DOCTYPE html>
<html lang="en">
<head>
    <meta charset="utf-8" />
    <title>AltMarkets.io | Sche ... (truncated)
2022-06-30 12:12:47,993 - 23426 - hummingbot.connector.time_synchronizer - NETWORK - Error getting server time.
Traceback (most recent call last):
  File "/mnt/e/Projects/hummingbot/hummingbot/hummingbot/connector/time_synchronizer.py", line 59, in update_server_time_offset_with_time_provider
    server_time_ms: float = await time_provider
  File "/mnt/e/Projects/hummingbot/hummingbot/hummingbot/connector/exchange/binance/binance_web_utils.py", line 127, in get_current_server_time
    response = await api_request(
  File "/mnt/e/Projects/hummingbot/hummingbot/hummingbot/connector/exchange/binance/binance_web_utils.py", line 115, in api_request
    raise IOError(f"Error executing request {method.name} {path}. "
OSError: Error executing request GET /time. HTTP status is 403. Error: <!DOCTYPE HTML PUBLIC "-//W3C//DTD HTML 4.01 Transitional//EN" "http://www.w3.org/TR/html4/loose.dtd">
<HTML><HEAD><META HTTP-EQUIV="Content-Type" CONTENT="text/html; charset=iso-8859-1">
<TITLE>ERROR: The request could not be satisfied</TITLE>
</HEAD><BODY>
<H1>403 ERROR</H1>
<H2>The request could not be satisfied.</H2>
<HR noshade size="1px">
The Amazon CloudFront distribution is configured to block access from your country.
We can't connect to the server for this app or website at this time. There might be too much traffic or a configuration error. Try again later, or contact the app or website owner.
<BR clear="all">
If you provide content to customers through CloudFront, you can find steps to troubleshoot and help prevent this error by reviewing the CloudFront documentation.
<BR clear="all">
<HR noshade size="1px">
<PRE>
Generated by cloudfront (CloudFront)
Request ID: uyC1RdPkqLPMsNySJt423v5ofUGWFnB0W6ytU2UQpk24qxWx-jQG9Q==
</PRE>
<ADDRESS>
</ADDRESS>
</BODY></HTML>
2022-06-30 12:12:48,030 - 23426 - hummingbot.connector.time_synchronizer - WARNING - Could not refresh server time. Check network connection.
2022-06-30 12:12:48,241 - 23426 - hummingbot.connector.exchange.binance.binance_api_order_book_data_source - ERROR - There was an error requesting exchange info (Error executing request GET /exchangeInfo. HTTP status is 403. Error: <!DOCTYPE HTML PUBLIC "-//W3C//DTD HTML 4.01 Transitional//EN" "http://www.w3.org/TR/html4/loose.dtd">
<HTML><HEAD><META HTTP-EQUIV="Content-Type" CONTENT="text/html; charset=iso-8859-1">
<TITLE>ERROR: The request could not be satisfied</TITLE>
</HEAD><BODY>
<H1>403 ERROR</H1>
<H2>The request could not be satisfied.</H2>
<HR noshade size="1px">
The Amazon CloudFront distribution is configured to block access from your country.
We can't connect to the server for this app or website at this time. There might be too much traffic or a configuration error. Try again later, or contact the app or website owner.
<BR clear="all">
If you provide content to customers through CloudFront, you can find steps to troubleshoot and help prevent this error by reviewing the CloudFront documentation.
<BR clear="all">
<HR noshade size="1px">
<PRE>
Generated by cloudfront (CloudFront)
Request ID: w3NrbFJoMuEvaEpfXhMzGEv2spIUp3qjVe_EYcQdBqIe1JVklI6HuQ==
</PRE>
<ADDRESS>
</ADDRESS>
</BODY></HTML>)
2022-06-30 12:12:49,885 - 23426 - hummingbot.connector.exchange.altmarkets.altmarkets_api_order_book_data_source - NETWORK - Error fetching data from https://v2.altmarkets.io/api/v2/peatio/public/markets. HTTP status is 403. Retrying in 7s. <!DOCTYPE html>
<html lang="en">
<head>
    <meta charset="utf-8" />
    <title>AltMarkets.io | Sche ... (truncated)
2022-06-30 12:12:58,091 - 23426 - hummingbot.connector.exchange.altmarkets.altmarkets_api_order_book_data_source - NETWORK - Error fetching data from https://v2.altmarkets.io/api/v2/peatio/public/markets. HTTP status is 403. Retrying in 31s. <!DOCTYPE html>
<html lang="en">
<head>
    <meta charset="utf-8" />
    <title>AltMarkets.io | Sche ... (truncated)
2022-06-30 12:13:22,027 - 23426 - hummingbot.core.utils.async_utils - ERROR - Unhandled error in background task: __init__() got an unexpected keyword argument 'dexfin_secret_key'
Traceback (most recent call last):
  File "/mnt/e/Projects/hummingbot/hummingbot/hummingbot/core/utils/async_utils.py", line 9, in safe_wrapper
    return await c
  File "/mnt/e/Projects/hummingbot/hummingbot/hummingbot/client/command/connect_command.py", line 76, in connect_exchange
    err_msg = await asyncio.wait_for(
  File "/home/knight/miniconda3/envs/hummingbot/lib/python3.8/asyncio/tasks.py", line 483, in wait_for
    return fut.result()
  File "/mnt/e/Projects/hummingbot/hummingbot/hummingbot/user/user_balances.py", line 55, in add_exchange
    market = UserBalances.connect_market(exchange, **api_details)
  File "/mnt/e/Projects/hummingbot/hummingbot/hummingbot/user/user_balances.py", line 23, in connect_market
    connector = connector_class(**init_params)
TypeError: __init__() got an unexpected keyword argument 'dexfin_secret_key'
2022-06-30 12:13:35,262 - 23426 - hummingbot.connector.exchange.altmarkets.altmarkets_api_order_book_data_source - NETWORK - Error fetching data from https://v2.altmarkets.io/api/v2/peatio/public/markets. HTTP status is 403. Retrying in 269s. <!DOCTYPE html>
<html lang="en">
<head>
    <meta charset="utf-8" />
    <title>AltMarkets.io | Sche ... (truncated)
2022-06-30 12:13:59,588 - 23470 - hummingbot.connector.exchange.altmarkets.altmarkets_api_order_book_data_source - NETWORK - Error fetching data from https://v2.altmarkets.io/api/v2/peatio/public/markets. HTTP status is 403. Retrying in 4s. <!DOCTYPE html>
<html lang="en">
<head>
    <meta charset="utf-8" />
    <title>AltMarkets.io | Sche ... (truncated)
2022-06-30 12:14:04,771 - 23470 - hummingbot.connector.time_synchronizer - NETWORK - Error getting server time.
Traceback (most recent call last):
  File "/mnt/e/Projects/hummingbot/hummingbot/hummingbot/connector/time_synchronizer.py", line 59, in update_server_time_offset_with_time_provider
    server_time_ms: float = await time_provider
  File "/mnt/e/Projects/hummingbot/hummingbot/hummingbot/connector/exchange/binance/binance_web_utils.py", line 127, in get_current_server_time
    response = await api_request(
  File "/mnt/e/Projects/hummingbot/hummingbot/hummingbot/connector/exchange/binance/binance_web_utils.py", line 115, in api_request
    raise IOError(f"Error executing request {method.name} {path}. "
OSError: Error executing request GET /time. HTTP status is 403. Error: <!DOCTYPE HTML PUBLIC "-//W3C//DTD HTML 4.01 Transitional//EN" "http://www.w3.org/TR/html4/loose.dtd">
<HTML><HEAD><META HTTP-EQUIV="Content-Type" CONTENT="text/html; charset=iso-8859-1">
<TITLE>ERROR: The request could not be satisfied</TITLE>
</HEAD><BODY>
<H1>403 ERROR</H1>
<H2>The request could not be satisfied.</H2>
<HR noshade size="1px">
The Amazon CloudFront distribution is configured to block access from your country.
We can't connect to the server for this app or website at this time. There might be too much traffic or a configuration error. Try again later, or contact the app or website owner.
<BR clear="all">
If you provide content to customers through CloudFront, you can find steps to troubleshoot and help prevent this error by reviewing the CloudFront documentation.
<BR clear="all">
<HR noshade size="1px">
<PRE>
Generated by cloudfront (CloudFront)
Request ID: LewQoDHq_TowskiTWvpGiavd9Nt3nr15o0HpPID0xVBZxshLO3xv4A==
</PRE>
<ADDRESS>
</ADDRESS>
</BODY></HTML>
2022-06-30 12:14:04,798 - 23470 - hummingbot.connector.time_synchronizer - WARNING - Could not refresh server time. Check network connection.
2022-06-30 12:14:04,943 - 23470 - hummingbot.connector.exchange.altmarkets.altmarkets_api_order_book_data_source - NETWORK - Error fetching data from https://v2.altmarkets.io/api/v2/peatio/public/markets. HTTP status is 403. Retrying in 7s. <!DOCTYPE html>
<html lang="en">
<head>
    <meta charset="utf-8" />
    <title>AltMarkets.io | Sche ... (truncated)
2022-06-30 12:14:05,018 - 23470 - hummingbot.connector.exchange.binance.binance_api_order_book_data_source - ERROR - There was an error requesting exchange info (Error executing request GET /exchangeInfo. HTTP status is 403. Error: <!DOCTYPE HTML PUBLIC "-//W3C//DTD HTML 4.01 Transitional//EN" "http://www.w3.org/TR/html4/loose.dtd">
<HTML><HEAD><META HTTP-EQUIV="Content-Type" CONTENT="text/html; charset=iso-8859-1">
<TITLE>ERROR: The request could not be satisfied</TITLE>
</HEAD><BODY>
<H1>403 ERROR</H1>
<H2>The request could not be satisfied.</H2>
<HR noshade size="1px">
The Amazon CloudFront distribution is configured to block access from your country.
We can't connect to the server for this app or website at this time. There might be too much traffic or a configuration error. Try again later, or contact the app or website owner.
<BR clear="all">
If you provide content to customers through CloudFront, you can find steps to troubleshoot and help prevent this error by reviewing the CloudFront documentation.
<BR clear="all">
<HR noshade size="1px">
<PRE>
Generated by cloudfront (CloudFront)
Request ID: tYOO9Y8vsybTJSWupvI0KsdK2lIQfhkwU7obJuit-PUaDFPdBZgdZQ==
</PRE>
<ADDRESS>
</ADDRESS>
</BODY></HTML>)
2022-06-30 12:14:13,334 - 23470 - hummingbot.connector.exchange.altmarkets.altmarkets_api_order_book_data_source - NETWORK - Error fetching data from https://v2.altmarkets.io/api/v2/peatio/public/markets. HTTP status is 403. Retrying in 32s. <!DOCTYPE html>
<html lang="en">
<head>
    <meta charset="utf-8" />
    <title>AltMarkets.io | Sche ... (truncated)
2022-06-30 12:14:31,861 - 23470 - root - ERROR - Error loading configs. Your config file may be corrupt. [Errno 2] No such file or directory: '/mnt/e/Projects/hummingbot/hummingbot/hummingbot/templates/conf_None_strategy_TEMPLATE.yml'
Traceback (most recent call last):
  File "/mnt/e/Projects/hummingbot/hummingbot/hummingbot/client/config/config_helpers.py", line 262, in load_yml_into_cm
    with open(template_file_path, "r") as template_fd:
FileNotFoundError: [Errno 2] No such file or directory: '/mnt/e/Projects/hummingbot/hummingbot/hummingbot/templates/conf_None_strategy_TEMPLATE.yml'
2022-06-30 12:14:46,958 - 23470 - hummingbot.connector.exchange.altmarkets.altmarkets_api_order_book_data_source - NETWORK - Error fetching data from https://v2.altmarkets.io/api/v2/peatio/public/markets. HTTP status is 403. Retrying in 282s. <!DOCTYPE html>
<html lang="en">
<head>
    <meta charset="utf-8" />
    <title>AltMarkets.io | Sche ... (truncated)
2022-06-30 12:15:04,850 - 23514 - hummingbot.connector.exchange.altmarkets.altmarkets_api_order_book_data_source - NETWORK - Error fetching data from https://v2.altmarkets.io/api/v2/peatio/public/markets. HTTP status is 403. Retrying in 4s. <!DOCTYPE html>
<html lang="en">
<head>
    <meta charset="utf-8" />
    <title>AltMarkets.io | Sche ... (truncated)
2022-06-30 12:15:10,571 - 23514 - hummingbot.connector.time_synchronizer - NETWORK - Error getting server time.
Traceback (most recent call last):
  File "/mnt/e/Projects/hummingbot/hummingbot/hummingbot/connector/time_synchronizer.py", line 59, in update_server_time_offset_with_time_provider
    server_time_ms: float = await time_provider
  File "/mnt/e/Projects/hummingbot/hummingbot/hummingbot/connector/exchange/binance/binance_web_utils.py", line 127, in get_current_server_time
    response = await api_request(
  File "/mnt/e/Projects/hummingbot/hummingbot/hummingbot/connector/exchange/binance/binance_web_utils.py", line 115, in api_request
    raise IOError(f"Error executing request {method.name} {path}. "
OSError: Error executing request GET /time. HTTP status is 403. Error: <!DOCTYPE HTML PUBLIC "-//W3C//DTD HTML 4.01 Transitional//EN" "http://www.w3.org/TR/html4/loose.dtd">
<HTML><HEAD><META HTTP-EQUIV="Content-Type" CONTENT="text/html; charset=iso-8859-1">
<TITLE>ERROR: The request could not be satisfied</TITLE>
</HEAD><BODY>
<H1>403 ERROR</H1>
<H2>The request could not be satisfied.</H2>
<HR noshade size="1px">
The Amazon CloudFront distribution is configured to block access from your country.
We can't connect to the server for this app or website at this time. There might be too much traffic or a configuration error. Try again later, or contact the app or website owner.
<BR clear="all">
If you provide content to customers through CloudFront, you can find steps to troubleshoot and help prevent this error by reviewing the CloudFront documentation.
<BR clear="all">
<HR noshade size="1px">
<PRE>
Generated by cloudfront (CloudFront)
Request ID: EGfEUf6utltIpp8qzZ1pC3ZYVy5aX-tsXTQPzBeRJS_w89xdGb9oBA==
</PRE>
<ADDRESS>
</ADDRESS>
</BODY></HTML>
2022-06-30 12:15:10,603 - 23514 - hummingbot.connector.time_synchronizer - WARNING - Could not refresh server time. Check network connection.
2022-06-30 12:15:10,731 - 23514 - hummingbot.connector.exchange.altmarkets.altmarkets_api_order_book_data_source - NETWORK - Error fetching data from https://v2.altmarkets.io/api/v2/peatio/public/markets. HTTP status is 403. Retrying in 8s. <!DOCTYPE html>
<html lang="en">
<head>
    <meta charset="utf-8" />
    <title>AltMarkets.io | Sche ... (truncated)
2022-06-30 12:15:10,847 - 23514 - hummingbot.connector.exchange.binance.binance_api_order_book_data_source - ERROR - There was an error requesting exchange info (Error executing request GET /exchangeInfo. HTTP status is 403. Error: <!DOCTYPE HTML PUBLIC "-//W3C//DTD HTML 4.01 Transitional//EN" "http://www.w3.org/TR/html4/loose.dtd">
<HTML><HEAD><META HTTP-EQUIV="Content-Type" CONTENT="text/html; charset=iso-8859-1">
<TITLE>ERROR: The request could not be satisfied</TITLE>
</HEAD><BODY>
<H1>403 ERROR</H1>
<H2>The request could not be satisfied.</H2>
<HR noshade size="1px">
The Amazon CloudFront distribution is configured to block access from your country.
We can't connect to the server for this app or website at this time. There might be too much traffic or a configuration error. Try again later, or contact the app or website owner.
<BR clear="all">
If you provide content to customers through CloudFront, you can find steps to troubleshoot and help prevent this error by reviewing the CloudFront documentation.
<BR clear="all">
<HR noshade size="1px">
<PRE>
Generated by cloudfront (CloudFront)
Request ID: oIghRrNvc9ZUFkG8CKnO5LC6jNPyl03q5kSYJ5J9JN_Gp8CVKLhm-g==
</PRE>
<ADDRESS>
</ADDRESS>
</BODY></HTML>)
2022-06-30 12:15:19,249 - 23514 - hummingbot.connector.exchange.altmarkets.altmarkets_api_order_book_data_source - NETWORK - Error fetching data from https://v2.altmarkets.io/api/v2/peatio/public/markets. HTTP status is 403. Retrying in 30s. <!DOCTYPE html>
<html lang="en">
<head>
    <meta charset="utf-8" />
    <title>AltMarkets.io | Sche ... (truncated)
2022-06-30 12:15:50,413 - 23514 - root - ERROR - Error loading configs. Your config file may be corrupt. [Errno 2] No such file or directory: '/mnt/e/Projects/hummingbot/hummingbot/hummingbot/templates/conf_None_strategy_TEMPLATE.yml'
Traceback (most recent call last):
  File "/mnt/e/Projects/hummingbot/hummingbot/hummingbot/client/config/config_helpers.py", line 262, in load_yml_into_cm
    with open(template_file_path, "r") as template_fd:
FileNotFoundError: [Errno 2] No such file or directory: '/mnt/e/Projects/hummingbot/hummingbot/hummingbot/templates/conf_None_strategy_TEMPLATE.yml'
2022-06-30 12:15:50,683 - 23514 - hummingbot.connector.exchange.altmarkets.altmarkets_api_order_book_data_source - NETWORK - Error fetching data from https://v2.altmarkets.io/api/v2/peatio/public/markets. HTTP status is 403. Retrying in 267s. <!DOCTYPE html>
<html lang="en">
<head>
    <meta charset="utf-8" />
    <title>AltMarkets.io | Sche ... (truncated)
2022-06-30 12:16:07,093 - 23514 - root - ERROR - Error loading configs. Your config file may be corrupt. [Errno 2] No such file or directory: '/mnt/e/Projects/hummingbot/hummingbot/hummingbot/templates/conf_None_strategy_TEMPLATE.yml'
Traceback (most recent call last):
  File "/mnt/e/Projects/hummingbot/hummingbot/hummingbot/client/config/config_helpers.py", line 262, in load_yml_into_cm
    with open(template_file_path, "r") as template_fd:
FileNotFoundError: [Errno 2] No such file or directory: '/mnt/e/Projects/hummingbot/hummingbot/hummingbot/templates/conf_None_strategy_TEMPLATE.yml'
2022-06-30 12:16:19,645 - 23514 - root - ERROR - Error loading configs. Your config file may be corrupt. [Errno 2] No such file or directory: '/mnt/e/Projects/hummingbot/hummingbot/hummingbot/templates/conf_None_strategy_TEMPLATE.yml'
Traceback (most recent call last):
  File "/mnt/e/Projects/hummingbot/hummingbot/hummingbot/client/config/config_helpers.py", line 262, in load_yml_into_cm
    with open(template_file_path, "r") as template_fd:
FileNotFoundError: [Errno 2] No such file or directory: '/mnt/e/Projects/hummingbot/hummingbot/hummingbot/templates/conf_None_strategy_TEMPLATE.yml'
2022-06-30 12:17:02,099 - 23514 - hummingbot.client.ui.hummingbot_cli - ERROR - Unhandled error in prompt_toolkit: 
    Pyperclip could not find a copy/paste mechanism for your system.
    For more information, please visit https://pyperclip.readthedocs.io/en/latest/introduction.html#not-implemented-error 
Traceback (most recent call last):
  File "/home/knight/miniconda3/envs/hummingbot/lib/python3.8/asyncio/events.py", line 81, in _run
    self._context.run(self._callback, *self._args)
  File "/home/knight/miniconda3/envs/hummingbot/lib/python3.8/site-packages/prompt_toolkit/input/vt100.py", line 168, in callback_wrapper
    callback()
  File "/home/knight/miniconda3/envs/hummingbot/lib/python3.8/site-packages/prompt_toolkit/application/application.py", line 691, in read_from_input
    self.key_processor.process_keys()
  File "/home/knight/miniconda3/envs/hummingbot/lib/python3.8/site-packages/prompt_toolkit/key_binding/key_processor.py", line 274, in process_keys
    self._process_coroutine.send(key_press)
  File "/home/knight/miniconda3/envs/hummingbot/lib/python3.8/site-packages/prompt_toolkit/key_binding/key_processor.py", line 198, in _process
    self._call_handler(matches[-1], key_sequence=buffer[:i])
  File "/home/knight/miniconda3/envs/hummingbot/lib/python3.8/site-packages/prompt_toolkit/key_binding/key_processor.py", line 329, in _call_handler
    handler.call(event)
  File "/home/knight/miniconda3/envs/hummingbot/lib/python3.8/site-packages/prompt_toolkit/key_binding/key_bindings.py", line 102, in call
    result = self.handler(event)
  File "/mnt/e/Projects/hummingbot/hummingbot/hummingbot/client/ui/keybindings.py", line 68, in do_copy
    get_app().clipboard.set_data(data)
  File "/home/knight/miniconda3/envs/hummingbot/lib/python3.8/site-packages/prompt_toolkit/clipboard/pyperclip.py", line 25, in set_data
    pyperclip.copy(data.text)
  File "/home/knight/miniconda3/envs/hummingbot/lib/python3.8/site-packages/pyperclip/__init__.py", line 616, in lazy_load_stub_copy
    return copy(text)
  File "/home/knight/miniconda3/envs/hummingbot/lib/python3.8/site-packages/pyperclip/__init__.py", line 301, in __call__
    raise PyperclipException(EXCEPT_MSG)
pyperclip.PyperclipException: 
    Pyperclip could not find a copy/paste mechanism for your system.
    For more information, please visit https://pyperclip.readthedocs.io/en/latest/introduction.html#not-implemented-error 
2022-06-30 12:17:23,314 - 23558 - hummingbot.connector.exchange.altmarkets.altmarkets_api_order_book_data_source - NETWORK - Error fetching data from https://v2.altmarkets.io/api/v2/peatio/public/markets. HTTP status is 403. Retrying in 4s. <!DOCTYPE html>
<html lang="en">
<head>
    <meta charset="utf-8" />
    <title>AltMarkets.io | Sche ... (truncated)
2022-06-30 12:17:30,283 - 23558 - hummingbot.core.utils.trading_pair_fetcher - ERROR - Connector bitmart failed to retrieve its trading pairs. Trading pairs autocompletion won't work.
Traceback (most recent call last):
  File "/mnt/e/Projects/hummingbot/hummingbot/hummingbot/core/utils/trading_pair_fetcher.py", line 74, in call_fetch_pairs
    self.trading_pairs[exchange_name] = await fetch_fn
  File "/mnt/e/Projects/hummingbot/hummingbot/hummingbot/connector/exchange/bitmart/bitmart_api_order_book_data_source.py", line 89, in fetch_trading_pairs
    response = await rest_assistant.call(request=request, timeout=10)
  File "/mnt/e/Projects/hummingbot/hummingbot/hummingbot/core/web_assistant/rest_assistant.py", line 35, in call
    resp = await wait_for(self._connection.call(request), timeout)
  File "/home/knight/miniconda3/envs/hummingbot/lib/python3.8/asyncio/tasks.py", line 490, in wait_for
    raise exceptions.TimeoutError()
asyncio.exceptions.TimeoutError
2022-06-30 12:17:30,487 - 23558 - root - INFO - Error fetching data from https://api.gateio.ws/api/v4/spot/currency_pairs. HTTP status is None. Retrying in 4s.
2022-06-30 12:17:30,489 - 23558 - root - INFO - Error fetching data from https://api.gateio.ws/api/v4/spot/currency_pairs. HTTP status is None. Retrying in 4s.
2022-06-30 12:17:30,787 - 23558 - hummingbot.core.utils.trading_pair_fetcher - ERROR - Connector digifinex failed to retrieve its trading pairs. Trading pairs autocompletion won't work.
Traceback (most recent call last):
  File "/mnt/e/Projects/hummingbot/hummingbot/hummingbot/core/utils/trading_pair_fetcher.py", line 74, in call_fetch_pairs
    self.trading_pairs[exchange_name] = await fetch_fn
  File "/mnt/e/Projects/hummingbot/hummingbot/hummingbot/connector/exchange/digifinex/digifinex_api_order_book_data_source.py", line 57, in fetch_trading_pairs
    async with client.get(f"{constants.REST_URL}/ticker", timeout=10) as response:
  File "/home/knight/miniconda3/envs/hummingbot/lib/python3.8/site-packages/aiohttp/client.py", line 1117, in __aenter__
    self._resp = await self._coro
  File "/home/knight/miniconda3/envs/hummingbot/lib/python3.8/site-packages/aiohttp/client.py", line 544, in _request
    await resp.start(conn)
  File "/home/knight/miniconda3/envs/hummingbot/lib/python3.8/site-packages/aiohttp/client_reqrep.py", line 905, in start
    self._continue = None
  File "/home/knight/miniconda3/envs/hummingbot/lib/python3.8/site-packages/aiohttp/helpers.py", line 656, in __exit__
    raise asyncio.TimeoutError from None
asyncio.exceptions.TimeoutError
2022-06-30 12:17:30,832 - 23558 - hummingbot.core.utils.trading_pair_fetcher - ERROR - Connector wazirx failed to retrieve its trading pairs. Trading pairs autocompletion won't work.
Traceback (most recent call last):
  File "/mnt/e/Projects/hummingbot/hummingbot/hummingbot/core/utils/trading_pair_fetcher.py", line 74, in call_fetch_pairs
    self.trading_pairs[exchange_name] = await fetch_fn
  File "/mnt/e/Projects/hummingbot/hummingbot/hummingbot/connector/exchange/wazirx/wazirx_api_order_book_data_source.py", line 82, in fetch_trading_pairs
    async with client.get(f"{CONSTANTS.WAZIRX_API_BASE}/{CONSTANTS.GET_EXCHANGE_INFO}", timeout=10) as response:
  File "/home/knight/miniconda3/envs/hummingbot/lib/python3.8/site-packages/aiohttp/client.py", line 1117, in __aenter__
    self._resp = await self._coro
  File "/home/knight/miniconda3/envs/hummingbot/lib/python3.8/site-packages/aiohttp/client.py", line 619, in _request
    break
  File "/home/knight/miniconda3/envs/hummingbot/lib/python3.8/site-packages/aiohttp/helpers.py", line 656, in __exit__
    raise asyncio.TimeoutError from None
asyncio.exceptions.TimeoutError
2022-06-30 12:17:30,895 - 23558 - hummingbot.connector.derivative.binance_perpetual.binance_perpetual_api_order_book_data_source - ERROR - There was an error requesting exchange info ()
Traceback (most recent call last):
  File "/mnt/e/Projects/hummingbot/hummingbot/hummingbot/connector/derivative/binance_perpetual/binance_perpetual_api_order_book_data_source.py", line 143, in init_trading_pair_symbols
    data = await web_utils.api_request(
  File "/mnt/e/Projects/hummingbot/hummingbot/hummingbot/connector/derivative/binance_perpetual/binance_perpetual_web_utils.py", line 101, in api_request
    response = await rest_assistant.call(request=request, timeout=timeout)
  File "/mnt/e/Projects/hummingbot/hummingbot/hummingbot/core/web_assistant/rest_assistant.py", line 35, in call
    resp = await wait_for(self._connection.call(request), timeout)
  File "/home/knight/miniconda3/envs/hummingbot/lib/python3.8/asyncio/tasks.py", line 490, in wait_for
    raise exceptions.TimeoutError()
asyncio.exceptions.TimeoutError
2022-06-30 12:17:32,644 - 23558 - hummingbot.connector.time_synchronizer - NETWORK - Error getting server time.
Traceback (most recent call last):
  File "/mnt/e/Projects/hummingbot/hummingbot/hummingbot/connector/time_synchronizer.py", line 59, in update_server_time_offset_with_time_provider
    server_time_ms: float = await time_provider
  File "/mnt/e/Projects/hummingbot/hummingbot/hummingbot/connector/exchange/binance/binance_web_utils.py", line 127, in get_current_server_time
    response = await api_request(
  File "/mnt/e/Projects/hummingbot/hummingbot/hummingbot/connector/exchange/binance/binance_web_utils.py", line 115, in api_request
    raise IOError(f"Error executing request {method.name} {path}. "
OSError: Error executing request GET /time. HTTP status is 403. Error: <!DOCTYPE HTML PUBLIC "-//W3C//DTD HTML 4.01 Transitional//EN" "http://www.w3.org/TR/html4/loose.dtd">
<HTML><HEAD><META HTTP-EQUIV="Content-Type" CONTENT="text/html; charset=iso-8859-1">
<TITLE>ERROR: The request could not be satisfied</TITLE>
</HEAD><BODY>
<H1>403 ERROR</H1>
<H2>The request could not be satisfied.</H2>
<HR noshade size="1px">
The Amazon CloudFront distribution is configured to block access from your country.
We can't connect to the server for this app or website at this time. There might be too much traffic or a configuration error. Try again later, or contact the app or website owner.
<BR clear="all">
If you provide content to customers through CloudFront, you can find steps to troubleshoot and help prevent this error by reviewing the CloudFront documentation.
<BR clear="all">
<HR noshade size="1px">
<PRE>
Generated by cloudfront (CloudFront)
Request ID: WoBUbjVGsouWuwd4Yds67kwFbhWNovOGEzvp-Nwbw0ufj2eRy-IH0g==
</PRE>
<ADDRESS>
</ADDRESS>
</BODY></HTML>
2022-06-30 12:17:32,657 - 23558 - hummingbot.connector.time_synchronizer - WARNING - Could not refresh server time. Check network connection.
2022-06-30 12:17:32,854 - 23558 - hummingbot.connector.exchange.altmarkets.altmarkets_api_order_book_data_source - NETWORK - Error fetching data from https://v2.altmarkets.io/api/v2/peatio/public/markets. HTTP status is 403. Retrying in 7s. <!DOCTYPE html>
<html lang="en">
<head>
    <meta charset="utf-8" />
    <title>AltMarkets.io | Sche ... (truncated)
2022-06-30 12:17:32,940 - 23558 - hummingbot.connector.exchange.binance.binance_api_order_book_data_source - ERROR - There was an error requesting exchange info (Error executing request GET /exchangeInfo. HTTP status is 403. Error: <!DOCTYPE HTML PUBLIC "-//W3C//DTD HTML 4.01 Transitional//EN" "http://www.w3.org/TR/html4/loose.dtd">
<HTML><HEAD><META HTTP-EQUIV="Content-Type" CONTENT="text/html; charset=iso-8859-1">
<TITLE>ERROR: The request could not be satisfied</TITLE>
</HEAD><BODY>
<H1>403 ERROR</H1>
<H2>The request could not be satisfied.</H2>
<HR noshade size="1px">
The Amazon CloudFront distribution is configured to block access from your country.
We can't connect to the server for this app or website at this time. There might be too much traffic or a configuration error. Try again later, or contact the app or website owner.
<BR clear="all">
If you provide content to customers through CloudFront, you can find steps to troubleshoot and help prevent this error by reviewing the CloudFront documentation.
<BR clear="all">
<HR noshade size="1px">
<PRE>
Generated by cloudfront (CloudFront)
Request ID: eumP8yw6qyXGco_aVovan4CpuxfumAE9GQTTrs3GFFyWglP6SvkWiQ==
</PRE>
<ADDRESS>
</ADDRESS>
</BODY></HTML>)
2022-06-30 12:17:41,434 - 23558 - hummingbot.connector.exchange.altmarkets.altmarkets_api_order_book_data_source - NETWORK - Error fetching data from https://v2.altmarkets.io/api/v2/peatio/public/markets. HTTP status is 403. Retrying in 31s. <!DOCTYPE html>
<html lang="en">
<head>
    <meta charset="utf-8" />
    <title>AltMarkets.io | Sche ... (truncated)
2022-06-30 12:17:58,095 - 23558 - hummingbot.core.utils.async_utils - ERROR - Unhandled error in background task: __init__() got an unexpected keyword argument 'dexfin_secret_key'
Traceback (most recent call last):
  File "/mnt/e/Projects/hummingbot/hummingbot/hummingbot/core/utils/async_utils.py", line 9, in safe_wrapper
    return await c
  File "/mnt/e/Projects/hummingbot/hummingbot/hummingbot/client/command/connect_command.py", line 76, in connect_exchange
    err_msg = await asyncio.wait_for(
  File "/home/knight/miniconda3/envs/hummingbot/lib/python3.8/asyncio/tasks.py", line 483, in wait_for
    return fut.result()
  File "/mnt/e/Projects/hummingbot/hummingbot/hummingbot/user/user_balances.py", line 55, in add_exchange
    market = UserBalances.connect_market(exchange, **api_details)
  File "/mnt/e/Projects/hummingbot/hummingbot/hummingbot/user/user_balances.py", line 23, in connect_market
    connector = connector_class(**init_params)
TypeError: __init__() got an unexpected keyword argument 'dexfin_secret_key'
2022-06-30 12:18:13,561 - 23558 - hummingbot.connector.exchange.altmarkets.altmarkets_api_order_book_data_source - NETWORK - Error fetching data from https://v2.altmarkets.io/api/v2/peatio/public/markets. HTTP status is 403. Retrying in 277s. <!DOCTYPE html>
<html lang="en">
<head>
    <meta charset="utf-8" />
    <title>AltMarkets.io | Sche ... (truncated)
2022-06-30 12:19:40,705 - 23558 - hummingbot.core.utils.trading_pair_fetcher - ERROR - Connector probit_kr failed to retrieve its trading pairs. Trading pairs autocompletion won't work.
Traceback (most recent call last):
  File "/home/knight/miniconda3/envs/hummingbot/lib/python3.8/site-packages/aiohttp/connector.py", line 969, in _wrap_create_connection
    return await self._loop.create_connection(*args, **kwargs)  # type: ignore  # noqa
  File "/home/knight/miniconda3/envs/hummingbot/lib/python3.8/asyncio/base_events.py", line 1025, in create_connection
    raise exceptions[0]
  File "/home/knight/miniconda3/envs/hummingbot/lib/python3.8/asyncio/base_events.py", line 1010, in create_connection
    sock = await self._connect_sock(
  File "/home/knight/miniconda3/envs/hummingbot/lib/python3.8/asyncio/base_events.py", line 924, in _connect_sock
    await self.sock_connect(sock, address)
  File "/home/knight/miniconda3/envs/hummingbot/lib/python3.8/asyncio/selector_events.py", line 494, in sock_connect
    return await fut
  File "/home/knight/miniconda3/envs/hummingbot/lib/python3.8/asyncio/selector_events.py", line 526, in _sock_connect_cb
    raise OSError(err, f'Connect call failed {address}')
TimeoutError: [Errno 110] Connect call failed ('55.28.36.18', 443)

The above exception was the direct cause of the following exception:

Traceback (most recent call last):
  File "/mnt/e/Projects/hummingbot/hummingbot/hummingbot/core/utils/trading_pair_fetcher.py", line 74, in call_fetch_pairs
    self.trading_pairs[exchange_name] = await fetch_fn
  File "/mnt/e/Projects/hummingbot/hummingbot/hummingbot/connector/exchange/probit/probit_api_order_book_data_source.py", line 81, in fetch_trading_pairs
    async with client.get(f"{CONSTANTS.MARKETS_URL.format(domain)}") as response:
  File "/home/knight/miniconda3/envs/hummingbot/lib/python3.8/site-packages/aiohttp/client.py", line 1117, in __aenter__
    self._resp = await self._coro
  File "/home/knight/miniconda3/envs/hummingbot/lib/python3.8/site-packages/aiohttp/client.py", line 520, in _request
    conn = await self._connector.connect(
  File "/home/knight/miniconda3/envs/hummingbot/lib/python3.8/site-packages/aiohttp/connector.py", line 535, in connect
    proto = await self._create_connection(req, traces, timeout)
  File "/home/knight/miniconda3/envs/hummingbot/lib/python3.8/site-packages/aiohttp/connector.py", line 892, in _create_connection
    _, proto = await self._create_direct_connection(req, traces, timeout)
  File "/home/knight/miniconda3/envs/hummingbot/lib/python3.8/site-packages/aiohttp/connector.py", line 1051, in _create_direct_connection
    raise last_exc
  File "/home/knight/miniconda3/envs/hummingbot/lib/python3.8/site-packages/aiohttp/connector.py", line 1020, in _create_direct_connection
    transp, proto = await self._wrap_create_connection(
  File "/home/knight/miniconda3/envs/hummingbot/lib/python3.8/site-packages/aiohttp/connector.py", line 975, in _wrap_create_connection
    raise client_error(req.connection_key, exc) from exc
aiohttp.client_exceptions.ClientConnectorError: Cannot connect to host api.probit.kr:443 ssl:default [Connect call failed ('55.28.36.18', 443)]
2022-06-30 12:26:54,866 - 24781 - hummingbot.connector.exchange.altmarkets.altmarkets_api_order_book_data_source - NETWORK - Error fetching data from https://v2.altmarkets.io/api/v2/peatio/public/markets. HTTP status is 403. Retrying in 4s. <!DOCTYPE html>
<html lang="en">
<head>
    <meta charset="utf-8" />
    <title>AltMarkets.io | Sche ... (truncated)
2022-06-30 12:27:05,104 - 24781 - hummingbot.core.utils.trading_pair_fetcher - ERROR - Connector digifinex failed to retrieve its trading pairs. Trading pairs autocompletion won't work.
Traceback (most recent call last):
  File "/mnt/e/Projects/hummingbot/hummingbot/hummingbot/core/utils/trading_pair_fetcher.py", line 74, in call_fetch_pairs
    self.trading_pairs[exchange_name] = await fetch_fn
  File "/mnt/e/Projects/hummingbot/hummingbot/hummingbot/connector/exchange/digifinex/digifinex_api_order_book_data_source.py", line 57, in fetch_trading_pairs
    async with client.get(f"{constants.REST_URL}/ticker", timeout=10) as response:
  File "/home/knight/miniconda3/envs/hummingbot/lib/python3.8/site-packages/aiohttp/client.py", line 1117, in __aenter__
    self._resp = await self._coro
  File "/home/knight/miniconda3/envs/hummingbot/lib/python3.8/site-packages/aiohttp/client.py", line 544, in _request
    await resp.start(conn)
  File "/home/knight/miniconda3/envs/hummingbot/lib/python3.8/site-packages/aiohttp/client_reqrep.py", line 905, in start
    self._continue = None
  File "/home/knight/miniconda3/envs/hummingbot/lib/python3.8/site-packages/aiohttp/helpers.py", line 656, in __exit__
    raise asyncio.TimeoutError from None
asyncio.exceptions.TimeoutError
2022-06-30 12:27:05,151 - 24781 - hummingbot.core.utils.trading_pair_fetcher - ERROR - Connector k2 failed to retrieve its trading pairs. Trading pairs autocompletion won't work.
Traceback (most recent call last):
  File "/mnt/e/Projects/hummingbot/hummingbot/hummingbot/core/utils/trading_pair_fetcher.py", line 74, in call_fetch_pairs
    self.trading_pairs[exchange_name] = await fetch_fn
  File "/mnt/e/Projects/hummingbot/hummingbot/hummingbot/connector/exchange/k2/k2_api_order_book_data_source.py", line 62, in fetch_trading_pairs
    async with client.get(f"{constants.REST_URL}{constants.GET_TRADING_PAIRS}",
  File "/home/knight/miniconda3/envs/hummingbot/lib/python3.8/site-packages/aiohttp/client.py", line 1117, in __aenter__
    self._resp = await self._coro
  File "/home/knight/miniconda3/envs/hummingbot/lib/python3.8/site-packages/aiohttp/client.py", line 619, in _request
    break
  File "/home/knight/miniconda3/envs/hummingbot/lib/python3.8/site-packages/aiohttp/helpers.py", line 656, in __exit__
    raise asyncio.TimeoutError from None
asyncio.exceptions.TimeoutError
2022-06-30 12:27:05,171 - 24781 - hummingbot.core.utils.trading_pair_fetcher - ERROR - Connector wazirx failed to retrieve its trading pairs. Trading pairs autocompletion won't work.
Traceback (most recent call last):
  File "/mnt/e/Projects/hummingbot/hummingbot/hummingbot/core/utils/trading_pair_fetcher.py", line 74, in call_fetch_pairs
    self.trading_pairs[exchange_name] = await fetch_fn
  File "/mnt/e/Projects/hummingbot/hummingbot/hummingbot/connector/exchange/wazirx/wazirx_api_order_book_data_source.py", line 82, in fetch_trading_pairs
    async with client.get(f"{CONSTANTS.WAZIRX_API_BASE}/{CONSTANTS.GET_EXCHANGE_INFO}", timeout=10) as response:
  File "/home/knight/miniconda3/envs/hummingbot/lib/python3.8/site-packages/aiohttp/client.py", line 1117, in __aenter__
    self._resp = await self._coro
  File "/home/knight/miniconda3/envs/hummingbot/lib/python3.8/site-packages/aiohttp/client.py", line 619, in _request
    break
  File "/home/knight/miniconda3/envs/hummingbot/lib/python3.8/site-packages/aiohttp/helpers.py", line 656, in __exit__
    raise asyncio.TimeoutError from None
asyncio.exceptions.TimeoutError
2022-06-30 12:27:05,178 - 24781 - hummingbot.core.utils.trading_pair_fetcher - ERROR - Connector bitmart failed to retrieve its trading pairs. Trading pairs autocompletion won't work.
Traceback (most recent call last):
  File "/mnt/e/Projects/hummingbot/hummingbot/hummingbot/core/utils/trading_pair_fetcher.py", line 74, in call_fetch_pairs
    self.trading_pairs[exchange_name] = await fetch_fn
  File "/mnt/e/Projects/hummingbot/hummingbot/hummingbot/connector/exchange/bitmart/bitmart_api_order_book_data_source.py", line 89, in fetch_trading_pairs
    response = await rest_assistant.call(request=request, timeout=10)
  File "/mnt/e/Projects/hummingbot/hummingbot/hummingbot/core/web_assistant/rest_assistant.py", line 35, in call
    resp = await wait_for(self._connection.call(request), timeout)
  File "/home/knight/miniconda3/envs/hummingbot/lib/python3.8/asyncio/tasks.py", line 490, in wait_for
    raise exceptions.TimeoutError()
asyncio.exceptions.TimeoutError
2022-06-30 12:27:05,204 - 24781 - root - INFO - Error fetching data from https://api.gateio.ws/api/v4/spot/currency_pairs. HTTP status is None. Retrying in 4s.
2022-06-30 12:27:05,205 - 24781 - root - INFO - Error fetching data from https://api.gateio.ws/api/v4/spot/currency_pairs. HTTP status is None. Retrying in 4s.
2022-06-30 12:27:05,205 - 24781 - hummingbot.connector.derivative.binance_perpetual.binance_perpetual_api_order_book_data_source - ERROR - There was an error requesting exchange info ()
Traceback (most recent call last):
  File "/mnt/e/Projects/hummingbot/hummingbot/hummingbot/connector/derivative/binance_perpetual/binance_perpetual_api_order_book_data_source.py", line 143, in init_trading_pair_symbols
    data = await web_utils.api_request(
  File "/mnt/e/Projects/hummingbot/hummingbot/hummingbot/connector/derivative/binance_perpetual/binance_perpetual_web_utils.py", line 101, in api_request
    response = await rest_assistant.call(request=request, timeout=timeout)
  File "/mnt/e/Projects/hummingbot/hummingbot/hummingbot/core/web_assistant/rest_assistant.py", line 35, in call
    resp = await wait_for(self._connection.call(request), timeout)
  File "/home/knight/miniconda3/envs/hummingbot/lib/python3.8/asyncio/tasks.py", line 490, in wait_for
    raise exceptions.TimeoutError()
asyncio.exceptions.TimeoutError
2022-06-30 12:27:06,653 - 24781 - hummingbot.connector.time_synchronizer - NETWORK - Error getting server time.
Traceback (most recent call last):
  File "/mnt/e/Projects/hummingbot/hummingbot/hummingbot/connector/time_synchronizer.py", line 59, in update_server_time_offset_with_time_provider
    server_time_ms: float = await time_provider
  File "/mnt/e/Projects/hummingbot/hummingbot/hummingbot/connector/exchange/binance/binance_web_utils.py", line 127, in get_current_server_time
    response = await api_request(
  File "/mnt/e/Projects/hummingbot/hummingbot/hummingbot/connector/exchange/binance/binance_web_utils.py", line 115, in api_request
    raise IOError(f"Error executing request {method.name} {path}. "
OSError: Error executing request GET /time. HTTP status is 403. Error: <!DOCTYPE HTML PUBLIC "-//W3C//DTD HTML 4.01 Transitional//EN" "http://www.w3.org/TR/html4/loose.dtd">
<HTML><HEAD><META HTTP-EQUIV="Content-Type" CONTENT="text/html; charset=iso-8859-1">
<TITLE>ERROR: The request could not be satisfied</TITLE>
</HEAD><BODY>
<H1>403 ERROR</H1>
<H2>The request could not be satisfied.</H2>
<HR noshade size="1px">
The Amazon CloudFront distribution is configured to block access from your country.
We can't connect to the server for this app or website at this time. There might be too much traffic or a configuration error. Try again later, or contact the app or website owner.
<BR clear="all">
If you provide content to customers through CloudFront, you can find steps to troubleshoot and help prevent this error by reviewing the CloudFront documentation.
<BR clear="all">
<HR noshade size="1px">
<PRE>
Generated by cloudfront (CloudFront)
Request ID: B9CuSgpLVp9t6q6x8QNg-MPVngzG71BvL9xVAaY-7g0ht10ksh7E1A==
</PRE>
<ADDRESS>
</ADDRESS>
</BODY></HTML>
2022-06-30 12:27:06,687 - 24781 - hummingbot.connector.time_synchronizer - WARNING - Could not refresh server time. Check network connection.
2022-06-30 12:27:06,934 - 24781 - hummingbot.connector.exchange.binance.binance_api_order_book_data_source - ERROR - There was an error requesting exchange info (Error executing request GET /exchangeInfo. HTTP status is 403. Error: <!DOCTYPE HTML PUBLIC "-//W3C//DTD HTML 4.01 Transitional//EN" "http://www.w3.org/TR/html4/loose.dtd">
<HTML><HEAD><META HTTP-EQUIV="Content-Type" CONTENT="text/html; charset=iso-8859-1">
<TITLE>ERROR: The request could not be satisfied</TITLE>
</HEAD><BODY>
<H1>403 ERROR</H1>
<H2>The request could not be satisfied.</H2>
<HR noshade size="1px">
The Amazon CloudFront distribution is configured to block access from your country.
We can't connect to the server for this app or website at this time. There might be too much traffic or a configuration error. Try again later, or contact the app or website owner.
<BR clear="all">
If you provide content to customers through CloudFront, you can find steps to troubleshoot and help prevent this error by reviewing the CloudFront documentation.
<BR clear="all">
<HR noshade size="1px">
<PRE>
Generated by cloudfront (CloudFront)
Request ID: lCGsxwSVfI7MfHn2t3TGzpVXN1yhuPFk3Op7SqnKv2qfqOZ2jx4Hmw==
</PRE>
<ADDRESS>
</ADDRESS>
</BODY></HTML>)
2022-06-30 12:27:07,206 - 24781 - hummingbot.connector.exchange.altmarkets.altmarkets_api_order_book_data_source - NETWORK - Error fetching data from https://v2.altmarkets.io/api/v2/peatio/public/markets. HTTP status is 403. Retrying in 7s. <!DOCTYPE html>
<html lang="en">
<head>
    <meta charset="utf-8" />
    <title>AltMarkets.io | Sche ... (truncated)
2022-06-30 12:27:16,670 - 24781 - hummingbot.connector.exchange.altmarkets.altmarkets_api_order_book_data_source - NETWORK - Error fetching data from https://v2.altmarkets.io/api/v2/peatio/public/markets. HTTP status is 403. Retrying in 32s. <!DOCTYPE html>
<html lang="en">
<head>
    <meta charset="utf-8" />
    <title>AltMarkets.io | Sche ... (truncated)
2022-06-30 12:27:49,955 - 24781 - hummingbot.connector.exchange.altmarkets.altmarkets_api_order_book_data_source - NETWORK - Error fetching data from https://v2.altmarkets.io/api/v2/peatio/public/markets. HTTP status is 403. Retrying in 269s. <!DOCTYPE html>
<html lang="en">
<head>
    <meta charset="utf-8" />
    <title>AltMarkets.io | Sche ... (truncated)
2022-06-30 12:29:19,265 - 24781 - hummingbot.core.utils.trading_pair_fetcher - ERROR - Connector probit_kr failed to retrieve its trading pairs. Trading pairs autocompletion won't work.
Traceback (most recent call last):
  File "/home/knight/miniconda3/envs/hummingbot/lib/python3.8/site-packages/aiohttp/connector.py", line 969, in _wrap_create_connection
    return await self._loop.create_connection(*args, **kwargs)  # type: ignore  # noqa
  File "/home/knight/miniconda3/envs/hummingbot/lib/python3.8/asyncio/base_events.py", line 1025, in create_connection
    raise exceptions[0]
  File "/home/knight/miniconda3/envs/hummingbot/lib/python3.8/asyncio/base_events.py", line 1010, in create_connection
    sock = await self._connect_sock(
  File "/home/knight/miniconda3/envs/hummingbot/lib/python3.8/asyncio/base_events.py", line 924, in _connect_sock
    await self.sock_connect(sock, address)
  File "/home/knight/miniconda3/envs/hummingbot/lib/python3.8/asyncio/selector_events.py", line 494, in sock_connect
    return await fut
  File "/home/knight/miniconda3/envs/hummingbot/lib/python3.8/asyncio/selector_events.py", line 526, in _sock_connect_cb
    raise OSError(err, f'Connect call failed {address}')
TimeoutError: [Errno 110] Connect call failed ('55.28.36.18', 443)

The above exception was the direct cause of the following exception:

Traceback (most recent call last):
  File "/mnt/e/Projects/hummingbot/hummingbot/hummingbot/core/utils/trading_pair_fetcher.py", line 74, in call_fetch_pairs
    self.trading_pairs[exchange_name] = await fetch_fn
  File "/mnt/e/Projects/hummingbot/hummingbot/hummingbot/connector/exchange/probit/probit_api_order_book_data_source.py", line 81, in fetch_trading_pairs
    async with client.get(f"{CONSTANTS.MARKETS_URL.format(domain)}") as response:
  File "/home/knight/miniconda3/envs/hummingbot/lib/python3.8/site-packages/aiohttp/client.py", line 1117, in __aenter__
    self._resp = await self._coro
  File "/home/knight/miniconda3/envs/hummingbot/lib/python3.8/site-packages/aiohttp/client.py", line 520, in _request
    conn = await self._connector.connect(
  File "/home/knight/miniconda3/envs/hummingbot/lib/python3.8/site-packages/aiohttp/connector.py", line 535, in connect
    proto = await self._create_connection(req, traces, timeout)
  File "/home/knight/miniconda3/envs/hummingbot/lib/python3.8/site-packages/aiohttp/connector.py", line 892, in _create_connection
    _, proto = await self._create_direct_connection(req, traces, timeout)
  File "/home/knight/miniconda3/envs/hummingbot/lib/python3.8/site-packages/aiohttp/connector.py", line 1051, in _create_direct_connection
    raise last_exc
  File "/home/knight/miniconda3/envs/hummingbot/lib/python3.8/site-packages/aiohttp/connector.py", line 1020, in _create_direct_connection
    transp, proto = await self._wrap_create_connection(
  File "/home/knight/miniconda3/envs/hummingbot/lib/python3.8/site-packages/aiohttp/connector.py", line 975, in _wrap_create_connection
    raise client_error(req.connection_key, exc) from exc
aiohttp.client_exceptions.ClientConnectorError: Cannot connect to host api.probit.kr:443 ssl:default [Connect call failed ('55.28.36.18', 443)]
2022-06-30 12:49:17,570 - 25534 - hummingbot.connector.exchange.altmarkets.altmarkets_api_order_book_data_source - NETWORK - Error fetching data from https://v2.altmarkets.io/api/v2/peatio/public/markets. HTTP status is 403. Retrying in 4s. <!DOCTYPE html>
<html lang="en">
<head>
    <meta charset="utf-8" />
    <title>AltMarkets.io | Sche ... (truncated)
2022-06-30 12:49:23,147 - 25534 - hummingbot.core.utils.trading_pair_fetcher - ERROR - Connector bitmart failed to retrieve its trading pairs. Trading pairs autocompletion won't work.
Traceback (most recent call last):
  File "/mnt/e/Projects/hummingbot/hummingbot/hummingbot/core/utils/trading_pair_fetcher.py", line 74, in call_fetch_pairs
    self.trading_pairs[exchange_name] = await fetch_fn
  File "/mnt/e/Projects/hummingbot/hummingbot/hummingbot/connector/exchange/bitmart/bitmart_api_order_book_data_source.py", line 89, in fetch_trading_pairs
    response = await rest_assistant.call(request=request, timeout=10)
  File "/mnt/e/Projects/hummingbot/hummingbot/hummingbot/core/web_assistant/rest_assistant.py", line 35, in call
    resp = await wait_for(self._connection.call(request), timeout)
  File "/home/knight/miniconda3/envs/hummingbot/lib/python3.8/asyncio/tasks.py", line 490, in wait_for
    raise exceptions.TimeoutError()
asyncio.exceptions.TimeoutError
2022-06-30 12:49:23,400 - 25534 - root - INFO - Error fetching data from https://api.gateio.ws/api/v4/spot/currency_pairs. HTTP status is None. Retrying in 4s.
2022-06-30 12:49:23,402 - 25534 - root - INFO - Error fetching data from https://api.gateio.ws/api/v4/spot/currency_pairs. HTTP status is None. Retrying in 4s.
2022-06-30 12:49:23,786 - 25534 - hummingbot.core.utils.trading_pair_fetcher - ERROR - Connector k2 failed to retrieve its trading pairs. Trading pairs autocompletion won't work.
Traceback (most recent call last):
  File "/mnt/e/Projects/hummingbot/hummingbot/hummingbot/core/utils/trading_pair_fetcher.py", line 74, in call_fetch_pairs
    self.trading_pairs[exchange_name] = await fetch_fn
  File "/mnt/e/Projects/hummingbot/hummingbot/hummingbot/connector/exchange/k2/k2_api_order_book_data_source.py", line 62, in fetch_trading_pairs
    async with client.get(f"{constants.REST_URL}{constants.GET_TRADING_PAIRS}",
  File "/home/knight/miniconda3/envs/hummingbot/lib/python3.8/site-packages/aiohttp/client.py", line 1117, in __aenter__
    self._resp = await self._coro
  File "/home/knight/miniconda3/envs/hummingbot/lib/python3.8/site-packages/aiohttp/client.py", line 619, in _request
    break
  File "/home/knight/miniconda3/envs/hummingbot/lib/python3.8/site-packages/aiohttp/helpers.py", line 656, in __exit__
    raise asyncio.TimeoutError from None
asyncio.exceptions.TimeoutError
2022-06-30 12:49:23,851 - 25534 - hummingbot.core.utils.trading_pair_fetcher - ERROR - Connector crypto_com failed to retrieve its trading pairs. Trading pairs autocompletion won't work.
Traceback (most recent call last):
  File "/mnt/e/Projects/hummingbot/hummingbot/hummingbot/core/utils/trading_pair_fetcher.py", line 74, in call_fetch_pairs
    self.trading_pairs[exchange_name] = await fetch_fn
  File "/mnt/e/Projects/hummingbot/hummingbot/hummingbot/connector/exchange/crypto_com/crypto_com_api_order_book_data_source.py", line 85, in fetch_trading_pairs
    async with client.get(url=url, timeout=10) as response:
  File "/home/knight/miniconda3/envs/hummingbot/lib/python3.8/site-packages/aiohttp/client.py", line 1117, in __aenter__
    self._resp = await self._coro
  File "/home/knight/miniconda3/envs/hummingbot/lib/python3.8/site-packages/aiohttp/client.py", line 619, in _request
    break
  File "/home/knight/miniconda3/envs/hummingbot/lib/python3.8/site-packages/aiohttp/helpers.py", line 656, in __exit__
    raise asyncio.TimeoutError from None
asyncio.exceptions.TimeoutError
2022-06-30 12:49:23,962 - 25534 - hummingbot.core.utils.trading_pair_fetcher - ERROR - Connector wazirx failed to retrieve its trading pairs. Trading pairs autocompletion won't work.
Traceback (most recent call last):
  File "/mnt/e/Projects/hummingbot/hummingbot/hummingbot/core/utils/trading_pair_fetcher.py", line 74, in call_fetch_pairs
    self.trading_pairs[exchange_name] = await fetch_fn
  File "/mnt/e/Projects/hummingbot/hummingbot/hummingbot/connector/exchange/wazirx/wazirx_api_order_book_data_source.py", line 82, in fetch_trading_pairs
    async with client.get(f"{CONSTANTS.WAZIRX_API_BASE}/{CONSTANTS.GET_EXCHANGE_INFO}", timeout=10) as response:
  File "/home/knight/miniconda3/envs/hummingbot/lib/python3.8/site-packages/aiohttp/client.py", line 1117, in __aenter__
    self._resp = await self._coro
  File "/home/knight/miniconda3/envs/hummingbot/lib/python3.8/site-packages/aiohttp/client.py", line 619, in _request
    break
  File "/home/knight/miniconda3/envs/hummingbot/lib/python3.8/site-packages/aiohttp/helpers.py", line 656, in __exit__
    raise asyncio.TimeoutError from None
asyncio.exceptions.TimeoutError
2022-06-30 12:49:26,433 - 25534 - hummingbot.connector.derivative.binance_perpetual.binance_perpetual_api_order_book_data_source - ERROR - There was an error requesting exchange info ()
Traceback (most recent call last):
  File "/mnt/e/Projects/hummingbot/hummingbot/hummingbot/connector/derivative/binance_perpetual/binance_perpetual_api_order_book_data_source.py", line 143, in init_trading_pair_symbols
    data = await web_utils.api_request(
  File "/mnt/e/Projects/hummingbot/hummingbot/hummingbot/connector/derivative/binance_perpetual/binance_perpetual_web_utils.py", line 101, in api_request
    response = await rest_assistant.call(request=request, timeout=timeout)
  File "/mnt/e/Projects/hummingbot/hummingbot/hummingbot/core/web_assistant/rest_assistant.py", line 35, in call
    resp = await wait_for(self._connection.call(request), timeout)
  File "/home/knight/miniconda3/envs/hummingbot/lib/python3.8/asyncio/tasks.py", line 490, in wait_for
    raise exceptions.TimeoutError()
asyncio.exceptions.TimeoutError
2022-06-30 12:49:31,333 - 25534 - hummingbot.connector.exchange.altmarkets.altmarkets_api_order_book_data_source - NETWORK - Error fetching data from https://v2.altmarkets.io/api/v2/peatio/public/markets. HTTP status is 403. Retrying in 7s. <!DOCTYPE html>
<html lang="en">
<head>
    <meta charset="utf-8" />
    <title>AltMarkets.io | Sche ... (truncated)
2022-06-30 12:49:31,693 - 25534 - hummingbot.connector.time_synchronizer - NETWORK - Error getting server time.
Traceback (most recent call last):
  File "/mnt/e/Projects/hummingbot/hummingbot/hummingbot/connector/time_synchronizer.py", line 59, in update_server_time_offset_with_time_provider
    server_time_ms: float = await time_provider
  File "/mnt/e/Projects/hummingbot/hummingbot/hummingbot/connector/exchange/binance/binance_web_utils.py", line 127, in get_current_server_time
    response = await api_request(
  File "/mnt/e/Projects/hummingbot/hummingbot/hummingbot/connector/exchange/binance/binance_web_utils.py", line 115, in api_request
    raise IOError(f"Error executing request {method.name} {path}. "
OSError: Error executing request GET /time. HTTP status is 403. Error: <!DOCTYPE HTML PUBLIC "-//W3C//DTD HTML 4.01 Transitional//EN" "http://www.w3.org/TR/html4/loose.dtd">
<HTML><HEAD><META HTTP-EQUIV="Content-Type" CONTENT="text/html; charset=iso-8859-1">
<TITLE>ERROR: The request could not be satisfied</TITLE>
</HEAD><BODY>
<H1>403 ERROR</H1>
<H2>The request could not be satisfied.</H2>
<HR noshade size="1px">
The Amazon CloudFront distribution is configured to block access from your country.
We can't connect to the server for this app or website at this time. There might be too much traffic or a configuration error. Try again later, or contact the app or website owner.
<BR clear="all">
If you provide content to customers through CloudFront, you can find steps to troubleshoot and help prevent this error by reviewing the CloudFront documentation.
<BR clear="all">
<HR noshade size="1px">
<PRE>
Generated by cloudfront (CloudFront)
Request ID: yOLi_bGnXT4ZfBdagtCoTa-l0GzYUJPxy0crkK7MtV8BBJ06Ms9k7Q==
</PRE>
<ADDRESS>
</ADDRESS>
</BODY></HTML>
2022-06-30 12:49:31,719 - 25534 - hummingbot.connector.time_synchronizer - WARNING - Could not refresh server time. Check network connection.
2022-06-30 12:49:33,027 - 25534 - hummingbot.connector.exchange.binance.binance_api_order_book_data_source - ERROR - There was an error requesting exchange info (Error executing request GET /exchangeInfo. HTTP status is 403. Error: <!DOCTYPE HTML PUBLIC "-//W3C//DTD HTML 4.01 Transitional//EN" "http://www.w3.org/TR/html4/loose.dtd">
<HTML><HEAD><META HTTP-EQUIV="Content-Type" CONTENT="text/html; charset=iso-8859-1">
<TITLE>ERROR: The request could not be satisfied</TITLE>
</HEAD><BODY>
<H1>403 ERROR</H1>
<H2>The request could not be satisfied.</H2>
<HR noshade size="1px">
The Amazon CloudFront distribution is configured to block access from your country.
We can't connect to the server for this app or website at this time. There might be too much traffic or a configuration error. Try again later, or contact the app or website owner.
<BR clear="all">
If you provide content to customers through CloudFront, you can find steps to troubleshoot and help prevent this error by reviewing the CloudFront documentation.
<BR clear="all">
<HR noshade size="1px">
<PRE>
Generated by cloudfront (CloudFront)
Request ID: UrxUfJSyJVWqusj9lLdZDKzF2Zte5ggrco-quV1lIDQ5hO1Jo6bHyg==
</PRE>
<ADDRESS>
</ADDRESS>
</BODY></HTML>)
2022-06-30 12:49:39,808 - 25534 - hummingbot.connector.exchange.altmarkets.altmarkets_api_order_book_data_source - NETWORK - Error fetching data from https://v2.altmarkets.io/api/v2/peatio/public/markets. HTTP status is 403. Retrying in 30s. <!DOCTYPE html>
<html lang="en">
<head>
    <meta charset="utf-8" />
    <title>AltMarkets.io | Sche ... (truncated)
2022-06-30 12:50:11,266 - 25534 - hummingbot.connector.exchange.altmarkets.altmarkets_api_order_book_data_source - NETWORK - Error fetching data from https://v2.altmarkets.io/api/v2/peatio/public/markets. HTTP status is 403. Retrying in 272s. <!DOCTYPE html>
<html lang="en">
<head>
    <meta charset="utf-8" />
    <title>AltMarkets.io | Sche ... (truncated)
2022-06-30 12:50:34,503 - 25534 - hummingbot.core.rate_oracle.rate_oracle - ERROR - Unexpected error while retrieving rates from Binance. Check the log file for more info.
2022-06-30 12:51:40,704 - 25534 - hummingbot.core.utils.trading_pair_fetcher - ERROR - Connector probit_kr failed to retrieve its trading pairs. Trading pairs autocompletion won't work.
Traceback (most recent call last):
  File "/home/knight/miniconda3/envs/hummingbot/lib/python3.8/site-packages/aiohttp/connector.py", line 969, in _wrap_create_connection
    return await self._loop.create_connection(*args, **kwargs)  # type: ignore  # noqa
  File "/home/knight/miniconda3/envs/hummingbot/lib/python3.8/asyncio/base_events.py", line 1025, in create_connection
    raise exceptions[0]
  File "/home/knight/miniconda3/envs/hummingbot/lib/python3.8/asyncio/base_events.py", line 1010, in create_connection
    sock = await self._connect_sock(
  File "/home/knight/miniconda3/envs/hummingbot/lib/python3.8/asyncio/base_events.py", line 924, in _connect_sock
    await self.sock_connect(sock, address)
  File "/home/knight/miniconda3/envs/hummingbot/lib/python3.8/asyncio/selector_events.py", line 494, in sock_connect
    return await fut
  File "/home/knight/miniconda3/envs/hummingbot/lib/python3.8/asyncio/selector_events.py", line 526, in _sock_connect_cb
    raise OSError(err, f'Connect call failed {address}')
TimeoutError: [Errno 110] Connect call failed ('55.28.36.18', 443)

The above exception was the direct cause of the following exception:

Traceback (most recent call last):
  File "/mnt/e/Projects/hummingbot/hummingbot/hummingbot/core/utils/trading_pair_fetcher.py", line 74, in call_fetch_pairs
    self.trading_pairs[exchange_name] = await fetch_fn
  File "/mnt/e/Projects/hummingbot/hummingbot/hummingbot/connector/exchange/probit/probit_api_order_book_data_source.py", line 81, in fetch_trading_pairs
    async with client.get(f"{CONSTANTS.MARKETS_URL.format(domain)}") as response:
  File "/home/knight/miniconda3/envs/hummingbot/lib/python3.8/site-packages/aiohttp/client.py", line 1117, in __aenter__
    self._resp = await self._coro
  File "/home/knight/miniconda3/envs/hummingbot/lib/python3.8/site-packages/aiohttp/client.py", line 520, in _request
    conn = await self._connector.connect(
  File "/home/knight/miniconda3/envs/hummingbot/lib/python3.8/site-packages/aiohttp/connector.py", line 535, in connect
    proto = await self._create_connection(req, traces, timeout)
  File "/home/knight/miniconda3/envs/hummingbot/lib/python3.8/site-packages/aiohttp/connector.py", line 892, in _create_connection
    _, proto = await self._create_direct_connection(req, traces, timeout)
  File "/home/knight/miniconda3/envs/hummingbot/lib/python3.8/site-packages/aiohttp/connector.py", line 1051, in _create_direct_connection
    raise last_exc
  File "/home/knight/miniconda3/envs/hummingbot/lib/python3.8/site-packages/aiohttp/connector.py", line 1020, in _create_direct_connection
    transp, proto = await self._wrap_create_connection(
  File "/home/knight/miniconda3/envs/hummingbot/lib/python3.8/site-packages/aiohttp/connector.py", line 975, in _wrap_create_connection
    raise client_error(req.connection_key, exc) from exc
aiohttp.client_exceptions.ClientConnectorError: Cannot connect to host api.probit.kr:443 ssl:default [Connect call failed ('55.28.36.18', 443)]
2022-06-30 13:04:12,480 - 26478 - hummingbot.core.utils.trading_pair_fetcher - ERROR - Connector bitmart failed to retrieve its trading pairs. Trading pairs autocompletion won't work.
Traceback (most recent call last):
  File "/mnt/e/Projects/hummingbot/hummingbot/hummingbot/core/utils/trading_pair_fetcher.py", line 74, in call_fetch_pairs
    self.trading_pairs[exchange_name] = await fetch_fn
  File "/mnt/e/Projects/hummingbot/hummingbot/hummingbot/connector/exchange/bitmart/bitmart_api_order_book_data_source.py", line 89, in fetch_trading_pairs
    response = await rest_assistant.call(request=request, timeout=10)
  File "/mnt/e/Projects/hummingbot/hummingbot/hummingbot/core/web_assistant/rest_assistant.py", line 35, in call
    resp = await wait_for(self._connection.call(request), timeout)
  File "/home/knight/miniconda3/envs/hummingbot/lib/python3.8/asyncio/tasks.py", line 490, in wait_for
    raise exceptions.TimeoutError()
asyncio.exceptions.TimeoutError
2022-06-30 13:04:12,643 - 26478 - root - INFO - Error fetching data from https://api.gateio.ws/api/v4/spot/currency_pairs. HTTP status is None. Retrying in 4s.
2022-06-30 13:04:12,643 - 26478 - root - INFO - Error fetching data from https://api.gateio.ws/api/v4/spot/currency_pairs. HTTP status is None. Retrying in 4s.
2022-06-30 13:04:12,789 - 26478 - hummingbot.core.utils.trading_pair_fetcher - ERROR - Connector wazirx failed to retrieve its trading pairs. Trading pairs autocompletion won't work.
Traceback (most recent call last):
  File "/mnt/e/Projects/hummingbot/hummingbot/hummingbot/core/utils/trading_pair_fetcher.py", line 74, in call_fetch_pairs
    self.trading_pairs[exchange_name] = await fetch_fn
  File "/mnt/e/Projects/hummingbot/hummingbot/hummingbot/connector/exchange/wazirx/wazirx_api_order_book_data_source.py", line 82, in fetch_trading_pairs
    async with client.get(f"{CONSTANTS.WAZIRX_API_BASE}/{CONSTANTS.GET_EXCHANGE_INFO}", timeout=10) as response:
  File "/home/knight/miniconda3/envs/hummingbot/lib/python3.8/site-packages/aiohttp/client.py", line 1117, in __aenter__
    self._resp = await self._coro
  File "/home/knight/miniconda3/envs/hummingbot/lib/python3.8/site-packages/aiohttp/client.py", line 619, in _request
    break
  File "/home/knight/miniconda3/envs/hummingbot/lib/python3.8/site-packages/aiohttp/helpers.py", line 656, in __exit__
    raise asyncio.TimeoutError from None
asyncio.exceptions.TimeoutError
2022-06-30 13:04:16,596 - 26478 - hummingbot.connector.time_synchronizer - NETWORK - Error getting server time.
Traceback (most recent call last):
  File "/mnt/e/Projects/hummingbot/hummingbot/hummingbot/connector/time_synchronizer.py", line 59, in update_server_time_offset_with_time_provider
    server_time_ms: float = await time_provider
  File "/mnt/e/Projects/hummingbot/hummingbot/hummingbot/connector/exchange/binance/binance_web_utils.py", line 127, in get_current_server_time
    response = await api_request(
  File "/mnt/e/Projects/hummingbot/hummingbot/hummingbot/connector/exchange/binance/binance_web_utils.py", line 115, in api_request
    raise IOError(f"Error executing request {method.name} {path}. "
OSError: Error executing request GET /time. HTTP status is 403. Error: <!DOCTYPE HTML PUBLIC "-//W3C//DTD HTML 4.01 Transitional//EN" "http://www.w3.org/TR/html4/loose.dtd">
<HTML><HEAD><META HTTP-EQUIV="Content-Type" CONTENT="text/html; charset=iso-8859-1">
<TITLE>ERROR: The request could not be satisfied</TITLE>
</HEAD><BODY>
<H1>403 ERROR</H1>
<H2>The request could not be satisfied.</H2>
<HR noshade size="1px">
The Amazon CloudFront distribution is configured to block access from your country.
We can't connect to the server for this app or website at this time. There might be too much traffic or a configuration error. Try again later, or contact the app or website owner.
<BR clear="all">
If you provide content to customers through CloudFront, you can find steps to troubleshoot and help prevent this error by reviewing the CloudFront documentation.
<BR clear="all">
<HR noshade size="1px">
<PRE>
Generated by cloudfront (CloudFront)
Request ID: fhpKwK9By_xyzxi9HrlZ08QSoN8DtcaCebWKzFSgKynszCGcMdUaXA==
</PRE>
<ADDRESS>
</ADDRESS>
</BODY></HTML>
2022-06-30 13:04:16,748 - 26478 - hummingbot.connector.time_synchronizer - WARNING - Could not refresh server time. Check network connection.
2022-06-30 13:04:16,957 - 26478 - hummingbot.connector.exchange.binance.binance_api_order_book_data_source - ERROR - There was an error requesting exchange info (Error executing request GET /exchangeInfo. HTTP status is 403. Error: <!DOCTYPE HTML PUBLIC "-//W3C//DTD HTML 4.01 Transitional//EN" "http://www.w3.org/TR/html4/loose.dtd">
<HTML><HEAD><META HTTP-EQUIV="Content-Type" CONTENT="text/html; charset=iso-8859-1">
<TITLE>ERROR: The request could not be satisfied</TITLE>
</HEAD><BODY>
<H1>403 ERROR</H1>
<H2>The request could not be satisfied.</H2>
<HR noshade size="1px">
The Amazon CloudFront distribution is configured to block access from your country.
We can't connect to the server for this app or website at this time. There might be too much traffic or a configuration error. Try again later, or contact the app or website owner.
<BR clear="all">
If you provide content to customers through CloudFront, you can find steps to troubleshoot and help prevent this error by reviewing the CloudFront documentation.
<BR clear="all">
<HR noshade size="1px">
<PRE>
Generated by cloudfront (CloudFront)
Request ID: 8837PvKZnCSCfV6H-ue1D6UxbZ-PXF2xxJ6xswOQDNnTWzGjBHQ5Tw==
</PRE>
<ADDRESS>
</ADDRESS>
</BODY></HTML>)
2022-06-30 13:04:19,177 - 26478 - hummingbot.connector.exchange.altmarkets.altmarkets_api_order_book_data_source - NETWORK - Error fetching data from https://v2.altmarkets.io/api/v2/peatio/public/markets. HTTP status is 403. Retrying in 7s. <!DOCTYPE html>
<html lang="en">
<head>
    <meta charset="utf-8" />
    <title>AltMarkets.io | Sche ... (truncated)
2022-06-30 13:04:27,626 - 26478 - hummingbot.connector.exchange.altmarkets.altmarkets_api_order_book_data_source - NETWORK - Error fetching data from https://v2.altmarkets.io/api/v2/peatio/public/markets. HTTP status is 403. Retrying in 32s. <!DOCTYPE html>
<html lang="en">
<head>
    <meta charset="utf-8" />
    <title>AltMarkets.io | Sche ... (truncated)
2022-06-30 13:04:42,338 - 26478 - hummingbot.core.rate_oracle.rate_oracle - ERROR - Unexpected error while retrieving rates from Binance. Check the log file for more info.
2022-06-30 13:05:00,752 - 26478 - hummingbot.connector.exchange.altmarkets.altmarkets_api_order_book_data_source - NETWORK - Error fetching data from https://v2.altmarkets.io/api/v2/peatio/public/markets. HTTP status is 403. Retrying in 272s. <!DOCTYPE html>
<html lang="en">
<head>
    <meta charset="utf-8" />
    <title>AltMarkets.io | Sche ... (truncated)
2022-06-30 13:06:26,465 - 26478 - hummingbot.core.utils.trading_pair_fetcher - ERROR - Connector probit_kr failed to retrieve its trading pairs. Trading pairs autocompletion won't work.
Traceback (most recent call last):
  File "/home/knight/miniconda3/envs/hummingbot/lib/python3.8/site-packages/aiohttp/connector.py", line 969, in _wrap_create_connection
    return await self._loop.create_connection(*args, **kwargs)  # type: ignore  # noqa
  File "/home/knight/miniconda3/envs/hummingbot/lib/python3.8/asyncio/base_events.py", line 1025, in create_connection
    raise exceptions[0]
  File "/home/knight/miniconda3/envs/hummingbot/lib/python3.8/asyncio/base_events.py", line 1010, in create_connection
    sock = await self._connect_sock(
  File "/home/knight/miniconda3/envs/hummingbot/lib/python3.8/asyncio/base_events.py", line 924, in _connect_sock
    await self.sock_connect(sock, address)
  File "/home/knight/miniconda3/envs/hummingbot/lib/python3.8/asyncio/selector_events.py", line 494, in sock_connect
    return await fut
  File "/home/knight/miniconda3/envs/hummingbot/lib/python3.8/asyncio/selector_events.py", line 526, in _sock_connect_cb
    raise OSError(err, f'Connect call failed {address}')
TimeoutError: [Errno 110] Connect call failed ('55.28.36.18', 443)

The above exception was the direct cause of the following exception:

Traceback (most recent call last):
  File "/mnt/e/Projects/hummingbot/hummingbot/hummingbot/core/utils/trading_pair_fetcher.py", line 74, in call_fetch_pairs
    self.trading_pairs[exchange_name] = await fetch_fn
  File "/mnt/e/Projects/hummingbot/hummingbot/hummingbot/connector/exchange/probit/probit_api_order_book_data_source.py", line 81, in fetch_trading_pairs
    async with client.get(f"{CONSTANTS.MARKETS_URL.format(domain)}") as response:
  File "/home/knight/miniconda3/envs/hummingbot/lib/python3.8/site-packages/aiohttp/client.py", line 1117, in __aenter__
    self._resp = await self._coro
  File "/home/knight/miniconda3/envs/hummingbot/lib/python3.8/site-packages/aiohttp/client.py", line 520, in _request
    conn = await self._connector.connect(
  File "/home/knight/miniconda3/envs/hummingbot/lib/python3.8/site-packages/aiohttp/connector.py", line 535, in connect
    proto = await self._create_connection(req, traces, timeout)
  File "/home/knight/miniconda3/envs/hummingbot/lib/python3.8/site-packages/aiohttp/connector.py", line 892, in _create_connection
    _, proto = await self._create_direct_connection(req, traces, timeout)
  File "/home/knight/miniconda3/envs/hummingbot/lib/python3.8/site-packages/aiohttp/connector.py", line 1051, in _create_direct_connection
    raise last_exc
  File "/home/knight/miniconda3/envs/hummingbot/lib/python3.8/site-packages/aiohttp/connector.py", line 1020, in _create_direct_connection
    transp, proto = await self._wrap_create_connection(
  File "/home/knight/miniconda3/envs/hummingbot/lib/python3.8/site-packages/aiohttp/connector.py", line 975, in _wrap_create_connection
    raise client_error(req.connection_key, exc) from exc
aiohttp.client_exceptions.ClientConnectorError: Cannot connect to host api.probit.kr:443 ssl:default [Connect call failed ('55.28.36.18', 443)]
2022-06-30 13:19:22,047 - 27041 - hummingbot.connector.exchange.altmarkets.altmarkets_api_order_book_data_source - NETWORK - Error fetching data from https://v2.altmarkets.io/api/v2/peatio/public/markets. HTTP status is 403. Retrying in 4s. <!DOCTYPE html>
<html lang="en">
<head>
    <meta charset="utf-8" />
    <title>AltMarkets.io | Sche ... (truncated)
2022-06-30 13:19:25,143 - 27041 - hummingbot.core.utils.trading_pair_fetcher - ERROR - Connector bitmart failed to retrieve its trading pairs. Trading pairs autocompletion won't work.
Traceback (most recent call last):
  File "/mnt/e/Projects/hummingbot/hummingbot/hummingbot/core/utils/trading_pair_fetcher.py", line 74, in call_fetch_pairs
    self.trading_pairs[exchange_name] = await fetch_fn
  File "/mnt/e/Projects/hummingbot/hummingbot/hummingbot/connector/exchange/bitmart/bitmart_api_order_book_data_source.py", line 89, in fetch_trading_pairs
    response = await rest_assistant.call(request=request, timeout=10)
  File "/mnt/e/Projects/hummingbot/hummingbot/hummingbot/core/web_assistant/rest_assistant.py", line 35, in call
    resp = await wait_for(self._connection.call(request), timeout)
  File "/home/knight/miniconda3/envs/hummingbot/lib/python3.8/asyncio/tasks.py", line 490, in wait_for
    raise exceptions.TimeoutError()
asyncio.exceptions.TimeoutError
2022-06-30 13:19:25,181 - 27041 - root - INFO - Error fetching data from https://api.gateio.ws/api/v4/spot/currency_pairs. HTTP status is None. Retrying in 4s.
2022-06-30 13:19:25,182 - 27041 - root - INFO - Error fetching data from https://api.gateio.ws/api/v4/spot/currency_pairs. HTTP status is None. Retrying in 4s.
2022-06-30 13:19:25,784 - 27041 - hummingbot.core.utils.trading_pair_fetcher - ERROR - Connector k2 failed to retrieve its trading pairs. Trading pairs autocompletion won't work.
Traceback (most recent call last):
  File "/mnt/e/Projects/hummingbot/hummingbot/hummingbot/core/utils/trading_pair_fetcher.py", line 74, in call_fetch_pairs
    self.trading_pairs[exchange_name] = await fetch_fn
  File "/mnt/e/Projects/hummingbot/hummingbot/hummingbot/connector/exchange/k2/k2_api_order_book_data_source.py", line 62, in fetch_trading_pairs
    async with client.get(f"{constants.REST_URL}{constants.GET_TRADING_PAIRS}",
  File "/home/knight/miniconda3/envs/hummingbot/lib/python3.8/site-packages/aiohttp/client.py", line 1117, in __aenter__
    self._resp = await self._coro
  File "/home/knight/miniconda3/envs/hummingbot/lib/python3.8/site-packages/aiohttp/client.py", line 619, in _request
    break
  File "/home/knight/miniconda3/envs/hummingbot/lib/python3.8/site-packages/aiohttp/helpers.py", line 656, in __exit__
    raise asyncio.TimeoutError from None
asyncio.exceptions.TimeoutError
2022-06-30 13:19:25,797 - 27041 - hummingbot.core.utils.trading_pair_fetcher - ERROR - Connector wazirx failed to retrieve its trading pairs. Trading pairs autocompletion won't work.
Traceback (most recent call last):
  File "/mnt/e/Projects/hummingbot/hummingbot/hummingbot/core/utils/trading_pair_fetcher.py", line 74, in call_fetch_pairs
    self.trading_pairs[exchange_name] = await fetch_fn
  File "/mnt/e/Projects/hummingbot/hummingbot/hummingbot/connector/exchange/wazirx/wazirx_api_order_book_data_source.py", line 82, in fetch_trading_pairs
    async with client.get(f"{CONSTANTS.WAZIRX_API_BASE}/{CONSTANTS.GET_EXCHANGE_INFO}", timeout=10) as response:
  File "/home/knight/miniconda3/envs/hummingbot/lib/python3.8/site-packages/aiohttp/client.py", line 1117, in __aenter__
    self._resp = await self._coro
  File "/home/knight/miniconda3/envs/hummingbot/lib/python3.8/site-packages/aiohttp/client.py", line 619, in _request
    break
  File "/home/knight/miniconda3/envs/hummingbot/lib/python3.8/site-packages/aiohttp/helpers.py", line 656, in __exit__
    raise asyncio.TimeoutError from None
asyncio.exceptions.TimeoutError
2022-06-30 13:19:27,922 - 27041 - hummingbot.connector.derivative.binance_perpetual.binance_perpetual_api_order_book_data_source - ERROR - There was an error requesting exchange info ()
Traceback (most recent call last):
  File "/mnt/e/Projects/hummingbot/hummingbot/hummingbot/connector/derivative/binance_perpetual/binance_perpetual_api_order_book_data_source.py", line 143, in init_trading_pair_symbols
    data = await web_utils.api_request(
  File "/mnt/e/Projects/hummingbot/hummingbot/hummingbot/connector/derivative/binance_perpetual/binance_perpetual_web_utils.py", line 101, in api_request
    response = await rest_assistant.call(request=request, timeout=timeout)
  File "/mnt/e/Projects/hummingbot/hummingbot/hummingbot/core/web_assistant/rest_assistant.py", line 35, in call
    resp = await wait_for(self._connection.call(request), timeout)
  File "/home/knight/miniconda3/envs/hummingbot/lib/python3.8/asyncio/tasks.py", line 490, in wait_for
    raise exceptions.TimeoutError()
asyncio.exceptions.TimeoutError
2022-06-30 13:19:33,664 - 27041 - root - INFO - Error fetching data from https://api.gateio.ws/api/v4/spot/currency_pairs. HTTP status is None. Retrying in 7s.
2022-06-30 13:19:36,784 - 27041 - hummingbot.connector.exchange.altmarkets.altmarkets_api_order_book_data_source - NETWORK - Error fetching data from https://v2.altmarkets.io/api/v2/peatio/public/markets. HTTP status is None. Retrying in 7s. 
2022-06-30 13:19:40,816 - 27041 - hummingbot.connector.time_synchronizer - NETWORK - Error getting server time.
Traceback (most recent call last):
  File "/mnt/e/Projects/hummingbot/hummingbot/hummingbot/connector/time_synchronizer.py", line 59, in update_server_time_offset_with_time_provider
    server_time_ms: float = await time_provider
  File "/mnt/e/Projects/hummingbot/hummingbot/hummingbot/connector/exchange/binance/binance_web_utils.py", line 127, in get_current_server_time
    response = await api_request(
  File "/mnt/e/Projects/hummingbot/hummingbot/hummingbot/connector/exchange/binance/binance_web_utils.py", line 115, in api_request
    raise IOError(f"Error executing request {method.name} {path}. "
OSError: Error executing request GET /time. HTTP status is 403. Error: <!DOCTYPE HTML PUBLIC "-//W3C//DTD HTML 4.01 Transitional//EN" "http://www.w3.org/TR/html4/loose.dtd">
<HTML><HEAD><META HTTP-EQUIV="Content-Type" CONTENT="text/html; charset=iso-8859-1">
<TITLE>ERROR: The request could not be satisfied</TITLE>
</HEAD><BODY>
<H1>403 ERROR</H1>
<H2>The request could not be satisfied.</H2>
<HR noshade size="1px">
The Amazon CloudFront distribution is configured to block access from your country.
We can't connect to the server for this app or website at this time. There might be too much traffic or a configuration error. Try again later, or contact the app or website owner.
<BR clear="all">
If you provide content to customers through CloudFront, you can find steps to troubleshoot and help prevent this error by reviewing the CloudFront documentation.
<BR clear="all">
<HR noshade size="1px">
<PRE>
Generated by cloudfront (CloudFront)
Request ID: EjCmhz2NNsar106RnJ1-yLGFaX7w63WOFJ7S3LXYlYexI0uNAYnRRQ==
</PRE>
<ADDRESS>
</ADDRESS>
</BODY></HTML>
2022-06-30 13:19:40,977 - 27041 - hummingbot.connector.time_synchronizer - WARNING - Could not refresh server time. Check network connection.
2022-06-30 13:19:41,274 - 27041 - hummingbot.connector.exchange.binance.binance_api_order_book_data_source - ERROR - There was an error requesting exchange info (Error executing request GET /exchangeInfo. HTTP status is 403. Error: <!DOCTYPE HTML PUBLIC "-//W3C//DTD HTML 4.01 Transitional//EN" "http://www.w3.org/TR/html4/loose.dtd">
<HTML><HEAD><META HTTP-EQUIV="Content-Type" CONTENT="text/html; charset=iso-8859-1">
<TITLE>ERROR: The request could not be satisfied</TITLE>
</HEAD><BODY>
<H1>403 ERROR</H1>
<H2>The request could not be satisfied.</H2>
<HR noshade size="1px">
The Amazon CloudFront distribution is configured to block access from your country.
We can't connect to the server for this app or website at this time. There might be too much traffic or a configuration error. Try again later, or contact the app or website owner.
<BR clear="all">
If you provide content to customers through CloudFront, you can find steps to troubleshoot and help prevent this error by reviewing the CloudFront documentation.
<BR clear="all">
<HR noshade size="1px">
<PRE>
Generated by cloudfront (CloudFront)
Request ID: l-OU23HMeFSqQmfqDTvtUG0AYoBFsoIu_X_mNF1XWOTp2NS6OKIOXA==
</PRE>
<ADDRESS>
</ADDRESS>
</BODY></HTML>)
2022-06-30 13:19:45,321 - 27041 - hummingbot.connector.exchange.altmarkets.altmarkets_api_order_book_data_source - NETWORK - Error fetching data from https://v2.altmarkets.io/api/v2/peatio/public/markets. HTTP status is 403. Retrying in 33s. <!DOCTYPE html>
<html lang="en">
<head>
    <meta charset="utf-8" />
    <title>AltMarkets.io | Sche ... (truncated)
2022-06-30 13:21:00,300 - 27108 - hummingbot.connector.exchange.altmarkets.altmarkets_api_order_book_data_source - NETWORK - Error fetching data from https://v2.altmarkets.io/api/v2/peatio/public/markets. HTTP status is 403. Retrying in 4s. <!DOCTYPE html>
<html lang="en">
<head>
    <meta charset="utf-8" />
    <title>AltMarkets.io | Sche ... (truncated)
2022-06-30 13:21:07,472 - 27108 - hummingbot.core.utils.trading_pair_fetcher - ERROR - Connector bitmart failed to retrieve its trading pairs. Trading pairs autocompletion won't work.
Traceback (most recent call last):
  File "/mnt/e/Projects/hummingbot/hummingbot/hummingbot/core/utils/trading_pair_fetcher.py", line 74, in call_fetch_pairs
    self.trading_pairs[exchange_name] = await fetch_fn
  File "/mnt/e/Projects/hummingbot/hummingbot/hummingbot/connector/exchange/bitmart/bitmart_api_order_book_data_source.py", line 89, in fetch_trading_pairs
    response = await rest_assistant.call(request=request, timeout=10)
  File "/mnt/e/Projects/hummingbot/hummingbot/hummingbot/core/web_assistant/rest_assistant.py", line 35, in call
    resp = await wait_for(self._connection.call(request), timeout)
  File "/home/knight/miniconda3/envs/hummingbot/lib/python3.8/asyncio/tasks.py", line 490, in wait_for
    raise exceptions.TimeoutError()
asyncio.exceptions.TimeoutError
2022-06-30 13:21:07,483 - 27108 - root - INFO - Error fetching data from https://api.gateio.ws/api/v4/spot/currency_pairs. HTTP status is None. Retrying in 4s.
2022-06-30 13:21:07,483 - 27108 - root - INFO - Error fetching data from https://api.gateio.ws/api/v4/spot/currency_pairs. HTTP status is None. Retrying in 4s.
2022-06-30 13:21:07,785 - 27108 - hummingbot.core.utils.trading_pair_fetcher - ERROR - Connector wazirx failed to retrieve its trading pairs. Trading pairs autocompletion won't work.
Traceback (most recent call last):
  File "/mnt/e/Projects/hummingbot/hummingbot/hummingbot/core/utils/trading_pair_fetcher.py", line 74, in call_fetch_pairs
    self.trading_pairs[exchange_name] = await fetch_fn
  File "/mnt/e/Projects/hummingbot/hummingbot/hummingbot/connector/exchange/wazirx/wazirx_api_order_book_data_source.py", line 82, in fetch_trading_pairs
    async with client.get(f"{CONSTANTS.WAZIRX_API_BASE}/{CONSTANTS.GET_EXCHANGE_INFO}", timeout=10) as response:
  File "/home/knight/miniconda3/envs/hummingbot/lib/python3.8/site-packages/aiohttp/client.py", line 1117, in __aenter__
    self._resp = await self._coro
  File "/home/knight/miniconda3/envs/hummingbot/lib/python3.8/site-packages/aiohttp/client.py", line 619, in _request
    break
  File "/home/knight/miniconda3/envs/hummingbot/lib/python3.8/site-packages/aiohttp/helpers.py", line 656, in __exit__
    raise asyncio.TimeoutError from None
asyncio.exceptions.TimeoutError
2022-06-30 13:21:09,970 - 27108 - hummingbot.connector.time_synchronizer - NETWORK - Error getting server time.
Traceback (most recent call last):
  File "/mnt/e/Projects/hummingbot/hummingbot/hummingbot/connector/time_synchronizer.py", line 59, in update_server_time_offset_with_time_provider
    server_time_ms: float = await time_provider
  File "/mnt/e/Projects/hummingbot/hummingbot/hummingbot/connector/exchange/binance/binance_web_utils.py", line 127, in get_current_server_time
    response = await api_request(
  File "/mnt/e/Projects/hummingbot/hummingbot/hummingbot/connector/exchange/binance/binance_web_utils.py", line 115, in api_request
    raise IOError(f"Error executing request {method.name} {path}. "
OSError: Error executing request GET /time. HTTP status is 403. Error: <!DOCTYPE HTML PUBLIC "-//W3C//DTD HTML 4.01 Transitional//EN" "http://www.w3.org/TR/html4/loose.dtd">
<HTML><HEAD><META HTTP-EQUIV="Content-Type" CONTENT="text/html; charset=iso-8859-1">
<TITLE>ERROR: The request could not be satisfied</TITLE>
</HEAD><BODY>
<H1>403 ERROR</H1>
<H2>The request could not be satisfied.</H2>
<HR noshade size="1px">
The Amazon CloudFront distribution is configured to block access from your country.
We can't connect to the server for this app or website at this time. There might be too much traffic or a configuration error. Try again later, or contact the app or website owner.
<BR clear="all">
If you provide content to customers through CloudFront, you can find steps to troubleshoot and help prevent this error by reviewing the CloudFront documentation.
<BR clear="all">
<HR noshade size="1px">
<PRE>
Generated by cloudfront (CloudFront)
Request ID: 95UuUifM2OcQH_LG9mPp06jmygmbKHtSCPqZ8y5KT46EkuYaZLQU2g==
</PRE>
<ADDRESS>
</ADDRESS>
</BODY></HTML>
2022-06-30 13:21:09,977 - 27108 - hummingbot.connector.time_synchronizer - WARNING - Could not refresh server time. Check network connection.
2022-06-30 13:21:10,016 - 27108 - hummingbot.connector.exchange.altmarkets.altmarkets_api_order_book_data_source - NETWORK - Error fetching data from https://v2.altmarkets.io/api/v2/peatio/public/markets. HTTP status is 403. Retrying in 7s. <!DOCTYPE html>
<html lang="en">
<head>
    <meta charset="utf-8" />
    <title>AltMarkets.io | Sche ... (truncated)
2022-06-30 13:21:10,176 - 27108 - hummingbot.connector.exchange.binance.binance_api_order_book_data_source - ERROR - There was an error requesting exchange info (Error executing request GET /exchangeInfo. HTTP status is 403. Error: <!DOCTYPE HTML PUBLIC "-//W3C//DTD HTML 4.01 Transitional//EN" "http://www.w3.org/TR/html4/loose.dtd">
<HTML><HEAD><META HTTP-EQUIV="Content-Type" CONTENT="text/html; charset=iso-8859-1">
<TITLE>ERROR: The request could not be satisfied</TITLE>
</HEAD><BODY>
<H1>403 ERROR</H1>
<H2>The request could not be satisfied.</H2>
<HR noshade size="1px">
The Amazon CloudFront distribution is configured to block access from your country.
We can't connect to the server for this app or website at this time. There might be too much traffic or a configuration error. Try again later, or contact the app or website owner.
<BR clear="all">
If you provide content to customers through CloudFront, you can find steps to troubleshoot and help prevent this error by reviewing the CloudFront documentation.
<BR clear="all">
<HR noshade size="1px">
<PRE>
Generated by cloudfront (CloudFront)
Request ID: 0ZNb2ul1XcgYuSSJqBgEh3q4X6WPoqsDUjeqevLS9LeNjyoEvaBuRQ==
</PRE>
<ADDRESS>
</ADDRESS>
</BODY></HTML>)
2022-06-30 13:21:19,004 - 27108 - hummingbot.connector.exchange.altmarkets.altmarkets_api_order_book_data_source - NETWORK - Error fetching data from https://v2.altmarkets.io/api/v2/peatio/public/markets. HTTP status is 403. Retrying in 30s. <!DOCTYPE html>
<html lang="en">
<head>
    <meta charset="utf-8" />
    <title>AltMarkets.io | Sche ... (truncated)
2022-06-30 13:21:37,653 - 27108 - hummingbot.core.rate_oracle.rate_oracle - ERROR - Unexpected error while retrieving rates from Binance. Check the log file for more info.
2022-06-30 13:21:51,061 - 27108 - hummingbot.connector.exchange.altmarkets.altmarkets_api_order_book_data_source - NETWORK - Error fetching data from https://v2.altmarkets.io/api/v2/peatio/public/markets. HTTP status is 403. Retrying in 272s. <!DOCTYPE html>
<html lang="en">
<head>
    <meta charset="utf-8" />
    <title>AltMarkets.io | Sche ... (truncated)
2022-06-30 14:02:21,219 - 29130 - hummingbot.connector.exchange.altmarkets.altmarkets_api_order_book_data_source - NETWORK - Error fetching data from https://v2.altmarkets.io/api/v2/peatio/public/markets. HTTP status is 403. Retrying in 4s. <!DOCTYPE html>
<html lang="en">
<head>
    <meta charset="utf-8" />
    <title>AltMarkets.io | Sche ... (truncated)
2022-06-30 14:02:30,602 - 29130 - hummingbot.core.utils.trading_pair_fetcher - ERROR - Connector k2 failed to retrieve its trading pairs. Trading pairs autocompletion won't work.
Traceback (most recent call last):
  File "/mnt/e/Projects/hummingbot/hummingbot/hummingbot/core/utils/trading_pair_fetcher.py", line 74, in call_fetch_pairs
    self.trading_pairs[exchange_name] = await fetch_fn
  File "/mnt/e/Projects/hummingbot/hummingbot/hummingbot/connector/exchange/k2/k2_api_order_book_data_source.py", line 62, in fetch_trading_pairs
    async with client.get(f"{constants.REST_URL}{constants.GET_TRADING_PAIRS}",
  File "/home/knight/miniconda3/envs/hummingbot/lib/python3.8/site-packages/aiohttp/client.py", line 1117, in __aenter__
    self._resp = await self._coro
  File "/home/knight/miniconda3/envs/hummingbot/lib/python3.8/site-packages/aiohttp/client.py", line 619, in _request
    break
  File "/home/knight/miniconda3/envs/hummingbot/lib/python3.8/site-packages/aiohttp/helpers.py", line 656, in __exit__
    raise asyncio.TimeoutError from None
asyncio.exceptions.TimeoutError
2022-06-30 14:02:30,641 - 29130 - hummingbot.core.utils.trading_pair_fetcher - ERROR - Connector wazirx failed to retrieve its trading pairs. Trading pairs autocompletion won't work.
Traceback (most recent call last):
  File "/mnt/e/Projects/hummingbot/hummingbot/hummingbot/core/utils/trading_pair_fetcher.py", line 74, in call_fetch_pairs
    self.trading_pairs[exchange_name] = await fetch_fn
  File "/mnt/e/Projects/hummingbot/hummingbot/hummingbot/connector/exchange/wazirx/wazirx_api_order_book_data_source.py", line 82, in fetch_trading_pairs
    async with client.get(f"{CONSTANTS.WAZIRX_API_BASE}/{CONSTANTS.GET_EXCHANGE_INFO}", timeout=10) as response:
  File "/home/knight/miniconda3/envs/hummingbot/lib/python3.8/site-packages/aiohttp/client.py", line 1117, in __aenter__
    self._resp = await self._coro
  File "/home/knight/miniconda3/envs/hummingbot/lib/python3.8/site-packages/aiohttp/client.py", line 619, in _request
    break
  File "/home/knight/miniconda3/envs/hummingbot/lib/python3.8/site-packages/aiohttp/helpers.py", line 656, in __exit__
    raise asyncio.TimeoutError from None
asyncio.exceptions.TimeoutError
2022-06-30 14:02:30,676 - 29130 - hummingbot.core.utils.trading_pair_fetcher - ERROR - Connector bitmart failed to retrieve its trading pairs. Trading pairs autocompletion won't work.
Traceback (most recent call last):
  File "/mnt/e/Projects/hummingbot/hummingbot/hummingbot/core/utils/trading_pair_fetcher.py", line 74, in call_fetch_pairs
    self.trading_pairs[exchange_name] = await fetch_fn
  File "/mnt/e/Projects/hummingbot/hummingbot/hummingbot/connector/exchange/bitmart/bitmart_api_order_book_data_source.py", line 89, in fetch_trading_pairs
    response = await rest_assistant.call(request=request, timeout=10)
  File "/mnt/e/Projects/hummingbot/hummingbot/hummingbot/core/web_assistant/rest_assistant.py", line 35, in call
    resp = await wait_for(self._connection.call(request), timeout)
  File "/home/knight/miniconda3/envs/hummingbot/lib/python3.8/asyncio/tasks.py", line 490, in wait_for
    raise exceptions.TimeoutError()
asyncio.exceptions.TimeoutError
2022-06-30 14:02:30,698 - 29130 - root - INFO - Error fetching data from https://api.gateio.ws/api/v4/spot/currency_pairs. HTTP status is None. Retrying in 4s.
2022-06-30 14:02:30,698 - 29130 - root - INFO - Error fetching data from https://api.gateio.ws/api/v4/spot/currency_pairs. HTTP status is None. Retrying in 4s.
2022-06-30 14:02:30,699 - 29130 - hummingbot.connector.derivative.binance_perpetual.binance_perpetual_api_order_book_data_source - ERROR - There was an error requesting exchange info ()
Traceback (most recent call last):
  File "/mnt/e/Projects/hummingbot/hummingbot/hummingbot/connector/derivative/binance_perpetual/binance_perpetual_api_order_book_data_source.py", line 143, in init_trading_pair_symbols
    data = await web_utils.api_request(
  File "/mnt/e/Projects/hummingbot/hummingbot/hummingbot/connector/derivative/binance_perpetual/binance_perpetual_web_utils.py", line 101, in api_request
    response = await rest_assistant.call(request=request, timeout=timeout)
  File "/mnt/e/Projects/hummingbot/hummingbot/hummingbot/core/web_assistant/rest_assistant.py", line 35, in call
    resp = await wait_for(self._connection.call(request), timeout)
  File "/home/knight/miniconda3/envs/hummingbot/lib/python3.8/asyncio/tasks.py", line 490, in wait_for
    raise exceptions.TimeoutError()
asyncio.exceptions.TimeoutError
2022-06-30 14:02:31,804 - 29130 - hummingbot.connector.time_synchronizer - NETWORK - Error getting server time.
Traceback (most recent call last):
  File "/mnt/e/Projects/hummingbot/hummingbot/hummingbot/connector/time_synchronizer.py", line 59, in update_server_time_offset_with_time_provider
    server_time_ms: float = await time_provider
  File "/mnt/e/Projects/hummingbot/hummingbot/hummingbot/connector/exchange/binance/binance_web_utils.py", line 127, in get_current_server_time
    response = await api_request(
  File "/mnt/e/Projects/hummingbot/hummingbot/hummingbot/connector/exchange/binance/binance_web_utils.py", line 115, in api_request
    raise IOError(f"Error executing request {method.name} {path}. "
OSError: Error executing request GET /time. HTTP status is 403. Error: <!DOCTYPE HTML PUBLIC "-//W3C//DTD HTML 4.01 Transitional//EN" "http://www.w3.org/TR/html4/loose.dtd">
<HTML><HEAD><META HTTP-EQUIV="Content-Type" CONTENT="text/html; charset=iso-8859-1">
<TITLE>ERROR: The request could not be satisfied</TITLE>
</HEAD><BODY>
<H1>403 ERROR</H1>
<H2>The request could not be satisfied.</H2>
<HR noshade size="1px">
The Amazon CloudFront distribution is configured to block access from your country.
We can't connect to the server for this app or website at this time. There might be too much traffic or a configuration error. Try again later, or contact the app or website owner.
<BR clear="all">
If you provide content to customers through CloudFront, you can find steps to troubleshoot and help prevent this error by reviewing the CloudFront documentation.
<BR clear="all">
<HR noshade size="1px">
<PRE>
Generated by cloudfront (CloudFront)
Request ID: FbGnMSMEZchmqXlqxjzGydQZcuPVLGTKrYKIYosSN2gGEX6RT3bqYA==
</PRE>
<ADDRESS>
</ADDRESS>
</BODY></HTML>
2022-06-30 14:02:31,820 - 29130 - hummingbot.connector.time_synchronizer - WARNING - Could not refresh server time. Check network connection.
2022-06-30 14:02:32,229 - 29130 - hummingbot.connector.exchange.altmarkets.altmarkets_api_order_book_data_source - NETWORK - Error fetching data from https://v2.altmarkets.io/api/v2/peatio/public/markets. HTTP status is 403. Retrying in 7s. <!DOCTYPE html>
<html lang="en">
<head>
    <meta charset="utf-8" />
    <title>AltMarkets.io | Sche ... (truncated)
2022-06-30 14:02:33,091 - 29130 - hummingbot.connector.exchange.binance.binance_api_order_book_data_source - ERROR - There was an error requesting exchange info (Error executing request GET /exchangeInfo. HTTP status is 403. Error: <!DOCTYPE HTML PUBLIC "-//W3C//DTD HTML 4.01 Transitional//EN" "http://www.w3.org/TR/html4/loose.dtd">
<HTML><HEAD><META HTTP-EQUIV="Content-Type" CONTENT="text/html; charset=iso-8859-1">
<TITLE>ERROR: The request could not be satisfied</TITLE>
</HEAD><BODY>
<H1>403 ERROR</H1>
<H2>The request could not be satisfied.</H2>
<HR noshade size="1px">
The Amazon CloudFront distribution is configured to block access from your country.
We can't connect to the server for this app or website at this time. There might be too much traffic or a configuration error. Try again later, or contact the app or website owner.
<BR clear="all">
If you provide content to customers through CloudFront, you can find steps to troubleshoot and help prevent this error by reviewing the CloudFront documentation.
<BR clear="all">
<HR noshade size="1px">
<PRE>
Generated by cloudfront (CloudFront)
Request ID: Iqy67tGljkaRbAOGByty4KHaT09fuCFuASebSubEep4JQmgMZUGCXw==
</PRE>
<ADDRESS>
</ADDRESS>
</BODY></HTML>)
2022-06-30 14:02:41,414 - 29130 - hummingbot.connector.exchange.altmarkets.altmarkets_api_order_book_data_source - NETWORK - Error fetching data from https://v2.altmarkets.io/api/v2/peatio/public/markets. HTTP status is 403. Retrying in 31s. <!DOCTYPE html>
<html lang="en">
<head>
    <meta charset="utf-8" />
    <title>AltMarkets.io | Sche ... (truncated)
2022-06-30 14:03:14,700 - 29130 - hummingbot.connector.exchange.altmarkets.altmarkets_api_order_book_data_source - NETWORK - Error fetching data from https://v2.altmarkets.io/api/v2/peatio/public/markets. HTTP status is 403. Retrying in 285s. <!DOCTYPE html>
<html lang="en">
<head>
    <meta charset="utf-8" />
    <title>AltMarkets.io | Sche ... (truncated)
2022-06-30 14:03:20,204 - 29130 - hummingbot.client.ui.hummingbot_cli - ERROR - Unhandled error in prompt_toolkit: 
    Pyperclip could not find a copy/paste mechanism for your system.
    For more information, please visit https://pyperclip.readthedocs.io/en/latest/introduction.html#not-implemented-error 
Traceback (most recent call last):
  File "/home/knight/miniconda3/envs/hummingbot/lib/python3.8/asyncio/events.py", line 81, in _run
    self._context.run(self._callback, *self._args)
  File "/home/knight/miniconda3/envs/hummingbot/lib/python3.8/site-packages/prompt_toolkit/input/vt100.py", line 168, in callback_wrapper
    callback()
  File "/home/knight/miniconda3/envs/hummingbot/lib/python3.8/site-packages/prompt_toolkit/application/application.py", line 691, in read_from_input
    self.key_processor.process_keys()
  File "/home/knight/miniconda3/envs/hummingbot/lib/python3.8/site-packages/prompt_toolkit/key_binding/key_processor.py", line 274, in process_keys
    self._process_coroutine.send(key_press)
  File "/home/knight/miniconda3/envs/hummingbot/lib/python3.8/site-packages/prompt_toolkit/key_binding/key_processor.py", line 198, in _process
    self._call_handler(matches[-1], key_sequence=buffer[:i])
  File "/home/knight/miniconda3/envs/hummingbot/lib/python3.8/site-packages/prompt_toolkit/key_binding/key_processor.py", line 329, in _call_handler
    handler.call(event)
  File "/home/knight/miniconda3/envs/hummingbot/lib/python3.8/site-packages/prompt_toolkit/key_binding/key_bindings.py", line 102, in call
    result = self.handler(event)
  File "/mnt/e/Projects/hummingbot/hummingbot/hummingbot/client/ui/keybindings.py", line 68, in do_copy
    get_app().clipboard.set_data(data)
  File "/home/knight/miniconda3/envs/hummingbot/lib/python3.8/site-packages/prompt_toolkit/clipboard/pyperclip.py", line 25, in set_data
    pyperclip.copy(data.text)
  File "/home/knight/miniconda3/envs/hummingbot/lib/python3.8/site-packages/pyperclip/__init__.py", line 616, in lazy_load_stub_copy
    return copy(text)
  File "/home/knight/miniconda3/envs/hummingbot/lib/python3.8/site-packages/pyperclip/__init__.py", line 301, in __call__
    raise PyperclipException(EXCEPT_MSG)
pyperclip.PyperclipException: 
    Pyperclip could not find a copy/paste mechanism for your system.
    For more information, please visit https://pyperclip.readthedocs.io/en/latest/introduction.html#not-implemented-error 
2022-06-30 14:03:49,335 - 29130 - hummingbot.core.rate_oracle.rate_oracle - ERROR - Unexpected error while retrieving rates from Binance. Check the log file for more info.
2022-06-30 14:04:43,425 - 29130 - hummingbot.core.utils.trading_pair_fetcher - ERROR - Connector probit_kr failed to retrieve its trading pairs. Trading pairs autocompletion won't work.
Traceback (most recent call last):
  File "/home/knight/miniconda3/envs/hummingbot/lib/python3.8/site-packages/aiohttp/connector.py", line 969, in _wrap_create_connection
    return await self._loop.create_connection(*args, **kwargs)  # type: ignore  # noqa
  File "/home/knight/miniconda3/envs/hummingbot/lib/python3.8/asyncio/base_events.py", line 1025, in create_connection
    raise exceptions[0]
  File "/home/knight/miniconda3/envs/hummingbot/lib/python3.8/asyncio/base_events.py", line 1010, in create_connection
    sock = await self._connect_sock(
  File "/home/knight/miniconda3/envs/hummingbot/lib/python3.8/asyncio/base_events.py", line 924, in _connect_sock
    await self.sock_connect(sock, address)
  File "/home/knight/miniconda3/envs/hummingbot/lib/python3.8/asyncio/selector_events.py", line 494, in sock_connect
    return await fut
  File "/home/knight/miniconda3/envs/hummingbot/lib/python3.8/asyncio/selector_events.py", line 526, in _sock_connect_cb
    raise OSError(err, f'Connect call failed {address}')
TimeoutError: [Errno 110] Connect call failed ('55.28.36.18', 443)

The above exception was the direct cause of the following exception:

Traceback (most recent call last):
  File "/mnt/e/Projects/hummingbot/hummingbot/hummingbot/core/utils/trading_pair_fetcher.py", line 74, in call_fetch_pairs
    self.trading_pairs[exchange_name] = await fetch_fn
  File "/mnt/e/Projects/hummingbot/hummingbot/hummingbot/connector/exchange/probit/probit_api_order_book_data_source.py", line 81, in fetch_trading_pairs
    async with client.get(f"{CONSTANTS.MARKETS_URL.format(domain)}") as response:
  File "/home/knight/miniconda3/envs/hummingbot/lib/python3.8/site-packages/aiohttp/client.py", line 1117, in __aenter__
    self._resp = await self._coro
  File "/home/knight/miniconda3/envs/hummingbot/lib/python3.8/site-packages/aiohttp/client.py", line 520, in _request
    conn = await self._connector.connect(
  File "/home/knight/miniconda3/envs/hummingbot/lib/python3.8/site-packages/aiohttp/connector.py", line 535, in connect
    proto = await self._create_connection(req, traces, timeout)
  File "/home/knight/miniconda3/envs/hummingbot/lib/python3.8/site-packages/aiohttp/connector.py", line 892, in _create_connection
    _, proto = await self._create_direct_connection(req, traces, timeout)
  File "/home/knight/miniconda3/envs/hummingbot/lib/python3.8/site-packages/aiohttp/connector.py", line 1051, in _create_direct_connection
    raise last_exc
  File "/home/knight/miniconda3/envs/hummingbot/lib/python3.8/site-packages/aiohttp/connector.py", line 1020, in _create_direct_connection
    transp, proto = await self._wrap_create_connection(
  File "/home/knight/miniconda3/envs/hummingbot/lib/python3.8/site-packages/aiohttp/connector.py", line 975, in _wrap_create_connection
    raise client_error(req.connection_key, exc) from exc
aiohttp.client_exceptions.ClientConnectorError: Cannot connect to host api.probit.kr:443 ssl:default [Connect call failed ('55.28.36.18', 443)]
2022-06-30 16:57:56,300 - 29130 - hummingbot.core.rate_oracle.rate_oracle - ERROR - Unexpected error while retrieving rates from Binance. Check the log file for more info.
