2022-06-28 10:49:58,089 - 4847 - hummingbot.connector.exchange.altmarkets.altmarkets_api_order_book_data_source - NETWORK - Error fetching data from https://v2.altmarkets.io/api/v2/peatio/public/markets. HTTP status is 403. Retrying in 4s. <!DOCTYPE html>
<html lang="en">
<head>
    <meta charset="utf-8" />
    <title>AltMarkets.io | Sche ... (truncated)
2022-06-28 10:50:05,135 - 4847 - hummingbot.core.utils.trading_pair_fetcher - ERROR - Connector bitmart failed to retrieve its trading pairs. Trading pairs autocompletion won't work.
Traceback (most recent call last):
  File "/mnt/e/Projects/hummingbot/hummingbot/hummingbot/core/utils/trading_pair_fetcher.py", line 74, in call_fetch_pairs
    self.trading_pairs[exchange_name] = await fetch_fn
  File "/mnt/e/Projects/hummingbot/hummingbot/hummingbot/connector/exchange/bitmart/bitmart_api_order_book_data_source.py", line 89, in fetch_trading_pairs
    response = await rest_assistant.call(request=request, timeout=10)
  File "/mnt/e/Projects/hummingbot/hummingbot/hummingbot/core/web_assistant/rest_assistant.py", line 35, in call
    resp = await wait_for(self._connection.call(request), timeout)
  File "/home/knight/miniconda3/envs/hummingbot/lib/python3.8/asyncio/tasks.py", line 490, in wait_for
    raise exceptions.TimeoutError()
asyncio.exceptions.TimeoutError
2022-06-28 10:50:05,229 - 4847 - root - INFO - Error fetching data from https://api.gateio.ws/api/v4/spot/currency_pairs. HTTP status is None. Retrying in 4s.
2022-06-28 10:50:05,230 - 4847 - root - INFO - Error fetching data from https://api.gateio.ws/api/v4/spot/currency_pairs. HTTP status is None. Retrying in 4s.
2022-06-28 10:50:06,107 - 4847 - hummingbot.connector.derivative.binance_perpetual.binance_perpetual_api_order_book_data_source - ERROR - There was an error requesting exchange info ()
Traceback (most recent call last):
  File "/mnt/e/Projects/hummingbot/hummingbot/hummingbot/connector/derivative/binance_perpetual/binance_perpetual_api_order_book_data_source.py", line 143, in init_trading_pair_symbols
    data = await web_utils.api_request(
  File "/mnt/e/Projects/hummingbot/hummingbot/hummingbot/connector/derivative/binance_perpetual/binance_perpetual_web_utils.py", line 101, in api_request
    response = await rest_assistant.call(request=request, timeout=timeout)
  File "/mnt/e/Projects/hummingbot/hummingbot/hummingbot/core/web_assistant/rest_assistant.py", line 35, in call
    resp = await wait_for(self._connection.call(request), timeout)
  File "/home/knight/miniconda3/envs/hummingbot/lib/python3.8/asyncio/tasks.py", line 490, in wait_for
    raise exceptions.TimeoutError()
asyncio.exceptions.TimeoutError
2022-06-28 10:50:06,137 - 4847 - hummingbot.core.utils.trading_pair_fetcher - ERROR - Connector wazirx failed to retrieve its trading pairs. Trading pairs autocompletion won't work.
Traceback (most recent call last):
  File "/mnt/e/Projects/hummingbot/hummingbot/hummingbot/core/utils/trading_pair_fetcher.py", line 74, in call_fetch_pairs
    self.trading_pairs[exchange_name] = await fetch_fn
  File "/mnt/e/Projects/hummingbot/hummingbot/hummingbot/connector/exchange/wazirx/wazirx_api_order_book_data_source.py", line 82, in fetch_trading_pairs
    async with client.get(f"{CONSTANTS.WAZIRX_API_BASE}/{CONSTANTS.GET_EXCHANGE_INFO}", timeout=10) as response:
  File "/home/knight/miniconda3/envs/hummingbot/lib/python3.8/site-packages/aiohttp/client.py", line 1117, in __aenter__
    self._resp = await self._coro
  File "/home/knight/miniconda3/envs/hummingbot/lib/python3.8/site-packages/aiohttp/client.py", line 619, in _request
    break
  File "/home/knight/miniconda3/envs/hummingbot/lib/python3.8/site-packages/aiohttp/helpers.py", line 656, in __exit__
    raise asyncio.TimeoutError from None
asyncio.exceptions.TimeoutError
2022-06-28 10:50:07,848 - 4847 - hummingbot.connector.exchange.altmarkets.altmarkets_api_order_book_data_source - NETWORK - Error fetching data from https://v2.altmarkets.io/api/v2/peatio/public/markets. HTTP status is 403. Retrying in 7s. <!DOCTYPE html>
<html lang="en">
<head>
    <meta charset="utf-8" />
    <title>AltMarkets.io | Sche ... (truncated)
2022-06-28 10:50:08,837 - 4847 - hummingbot.connector.time_synchronizer - NETWORK - Error getting server time.
Traceback (most recent call last):
  File "/mnt/e/Projects/hummingbot/hummingbot/hummingbot/connector/time_synchronizer.py", line 59, in update_server_time_offset_with_time_provider
    server_time_ms: float = await time_provider
  File "/mnt/e/Projects/hummingbot/hummingbot/hummingbot/connector/exchange/binance/binance_web_utils.py", line 127, in get_current_server_time
    response = await api_request(
  File "/mnt/e/Projects/hummingbot/hummingbot/hummingbot/connector/exchange/binance/binance_web_utils.py", line 115, in api_request
    raise IOError(f"Error executing request {method.name} {path}. "
OSError: Error executing request GET /time. HTTP status is 403. Error: <!DOCTYPE HTML PUBLIC "-//W3C//DTD HTML 4.01 Transitional//EN" "http://www.w3.org/TR/html4/loose.dtd">
<HTML><HEAD><META HTTP-EQUIV="Content-Type" CONTENT="text/html; charset=iso-8859-1">
<TITLE>ERROR: The request could not be satisfied</TITLE>
</HEAD><BODY>
<H1>403 ERROR</H1>
<H2>The request could not be satisfied.</H2>
<HR noshade size="1px">
The Amazon CloudFront distribution is configured to block access from your country.
We can't connect to the server for this app or website at this time. There might be too much traffic or a configuration error. Try again later, or contact the app or website owner.
<BR clear="all">
If you provide content to customers through CloudFront, you can find steps to troubleshoot and help prevent this error by reviewing the CloudFront documentation.
<BR clear="all">
<HR noshade size="1px">
<PRE>
Generated by cloudfront (CloudFront)
Request ID: nnskoGDmB-mz0zuFY9rmVTYetdK0RTLZ45xnz0ANW6LGvzdY5bvU5Q==
</PRE>
<ADDRESS>
</ADDRESS>
</BODY></HTML>
2022-06-28 10:50:08,868 - 4847 - hummingbot.connector.time_synchronizer - WARNING - Could not refresh server time. Check network connection.
2022-06-28 10:50:09,236 - 4847 - hummingbot.connector.exchange.binance.binance_api_order_book_data_source - ERROR - There was an error requesting exchange info (Error executing request GET /exchangeInfo. HTTP status is 403. Error: <!DOCTYPE HTML PUBLIC "-//W3C//DTD HTML 4.01 Transitional//EN" "http://www.w3.org/TR/html4/loose.dtd">
<HTML><HEAD><META HTTP-EQUIV="Content-Type" CONTENT="text/html; charset=iso-8859-1">
<TITLE>ERROR: The request could not be satisfied</TITLE>
</HEAD><BODY>
<H1>403 ERROR</H1>
<H2>The request could not be satisfied.</H2>
<HR noshade size="1px">
The Amazon CloudFront distribution is configured to block access from your country.
We can't connect to the server for this app or website at this time. There might be too much traffic or a configuration error. Try again later, or contact the app or website owner.
<BR clear="all">
If you provide content to customers through CloudFront, you can find steps to troubleshoot and help prevent this error by reviewing the CloudFront documentation.
<BR clear="all">
<HR noshade size="1px">
<PRE>
Generated by cloudfront (CloudFront)
Request ID: xFTsjWYR79Gre0LsD3N7jFyl6U8MCLkF3T4LH4r0Ib5x9IW7HAfwug==
</PRE>
<ADDRESS>
</ADDRESS>
</BODY></HTML>)
2022-06-28 10:50:16,277 - 4847 - hummingbot.connector.exchange.altmarkets.altmarkets_api_order_book_data_source - NETWORK - Error fetching data from https://v2.altmarkets.io/api/v2/peatio/public/markets. HTTP status is 403. Retrying in 31s. <!DOCTYPE html>
<html lang="en">
<head>
    <meta charset="utf-8" />
    <title>AltMarkets.io | Sche ... (truncated)
2022-06-28 10:50:48,073 - 4847 - hummingbot.connector.exchange.altmarkets.altmarkets_api_order_book_data_source - NETWORK - Error fetching data from https://v2.altmarkets.io/api/v2/peatio/public/markets. HTTP status is 403. Retrying in 269s. <!DOCTYPE html>
<html lang="en">
<head>
    <meta charset="utf-8" />
    <title>AltMarkets.io | Sche ... (truncated)
2022-06-28 10:52:16,875 - 4847 - hummingbot.core.utils.trading_pair_fetcher - ERROR - Connector probit_kr failed to retrieve its trading pairs. Trading pairs autocompletion won't work.
Traceback (most recent call last):
  File "/home/knight/miniconda3/envs/hummingbot/lib/python3.8/site-packages/aiohttp/connector.py", line 969, in _wrap_create_connection
    return await self._loop.create_connection(*args, **kwargs)  # type: ignore  # noqa
  File "/home/knight/miniconda3/envs/hummingbot/lib/python3.8/asyncio/base_events.py", line 1025, in create_connection
    raise exceptions[0]
  File "/home/knight/miniconda3/envs/hummingbot/lib/python3.8/asyncio/base_events.py", line 1010, in create_connection
    sock = await self._connect_sock(
  File "/home/knight/miniconda3/envs/hummingbot/lib/python3.8/asyncio/base_events.py", line 924, in _connect_sock
    await self.sock_connect(sock, address)
  File "/home/knight/miniconda3/envs/hummingbot/lib/python3.8/asyncio/selector_events.py", line 494, in sock_connect
    return await fut
  File "/home/knight/miniconda3/envs/hummingbot/lib/python3.8/asyncio/selector_events.py", line 526, in _sock_connect_cb
    raise OSError(err, f'Connect call failed {address}')
TimeoutError: [Errno 110] Connect call failed ('55.28.36.18', 443)

The above exception was the direct cause of the following exception:

Traceback (most recent call last):
  File "/mnt/e/Projects/hummingbot/hummingbot/hummingbot/core/utils/trading_pair_fetcher.py", line 74, in call_fetch_pairs
    self.trading_pairs[exchange_name] = await fetch_fn
  File "/mnt/e/Projects/hummingbot/hummingbot/hummingbot/connector/exchange/probit/probit_api_order_book_data_source.py", line 81, in fetch_trading_pairs
    async with client.get(f"{CONSTANTS.MARKETS_URL.format(domain)}") as response:
  File "/home/knight/miniconda3/envs/hummingbot/lib/python3.8/site-packages/aiohttp/client.py", line 1117, in __aenter__
    self._resp = await self._coro
  File "/home/knight/miniconda3/envs/hummingbot/lib/python3.8/site-packages/aiohttp/client.py", line 520, in _request
    conn = await self._connector.connect(
  File "/home/knight/miniconda3/envs/hummingbot/lib/python3.8/site-packages/aiohttp/connector.py", line 535, in connect
    proto = await self._create_connection(req, traces, timeout)
  File "/home/knight/miniconda3/envs/hummingbot/lib/python3.8/site-packages/aiohttp/connector.py", line 892, in _create_connection
    _, proto = await self._create_direct_connection(req, traces, timeout)
  File "/home/knight/miniconda3/envs/hummingbot/lib/python3.8/site-packages/aiohttp/connector.py", line 1051, in _create_direct_connection
    raise last_exc
  File "/home/knight/miniconda3/envs/hummingbot/lib/python3.8/site-packages/aiohttp/connector.py", line 1020, in _create_direct_connection
    transp, proto = await self._wrap_create_connection(
  File "/home/knight/miniconda3/envs/hummingbot/lib/python3.8/site-packages/aiohttp/connector.py", line 975, in _wrap_create_connection
    raise client_error(req.connection_key, exc) from exc
aiohttp.client_exceptions.ClientConnectorError: Cannot connect to host api.probit.kr:443 ssl:default [Connect call failed ('55.28.36.18', 443)]
2022-06-28 11:36:36,699 - 277 - hummingbot.connector.exchange.altmarkets.altmarkets_api_order_book_data_source - NETWORK - Error fetching data from https://v2.altmarkets.io/api/v2/peatio/public/markets. HTTP status is 403. Retrying in 4s. <!DOCTYPE html>
<html lang="en">
<head>
    <meta charset="utf-8" />
    <title>AltMarkets.io | Sche ... (truncated)
2022-06-28 11:36:43,777 - 277 - hummingbot.core.utils.trading_pair_fetcher - ERROR - Connector bitmart failed to retrieve its trading pairs. Trading pairs autocompletion won't work.
Traceback (most recent call last):
  File "/mnt/e/Projects/hummingbot/hummingbot/hummingbot/core/utils/trading_pair_fetcher.py", line 74, in call_fetch_pairs
    self.trading_pairs[exchange_name] = await fetch_fn
  File "/mnt/e/Projects/hummingbot/hummingbot/hummingbot/connector/exchange/bitmart/bitmart_api_order_book_data_source.py", line 89, in fetch_trading_pairs
    response = await rest_assistant.call(request=request, timeout=10)
  File "/mnt/e/Projects/hummingbot/hummingbot/hummingbot/core/web_assistant/rest_assistant.py", line 35, in call
    resp = await wait_for(self._connection.call(request), timeout)
  File "/home/knight/miniconda3/envs/hummingbot/lib/python3.8/asyncio/tasks.py", line 490, in wait_for
    raise exceptions.TimeoutError()
asyncio.exceptions.TimeoutError
2022-06-28 11:36:43,877 - 277 - root - INFO - Error fetching data from https://api.gateio.ws/api/v4/spot/currency_pairs. HTTP status is None. Retrying in 4s.
2022-06-28 11:36:43,878 - 277 - root - INFO - Error fetching data from https://api.gateio.ws/api/v4/spot/currency_pairs. HTTP status is None. Retrying in 4s.
2022-06-28 11:36:44,230 - 277 - hummingbot.core.utils.trading_pair_fetcher - ERROR - Connector k2 failed to retrieve its trading pairs. Trading pairs autocompletion won't work.
Traceback (most recent call last):
  File "/mnt/e/Projects/hummingbot/hummingbot/hummingbot/core/utils/trading_pair_fetcher.py", line 74, in call_fetch_pairs
    self.trading_pairs[exchange_name] = await fetch_fn
  File "/mnt/e/Projects/hummingbot/hummingbot/hummingbot/connector/exchange/k2/k2_api_order_book_data_source.py", line 62, in fetch_trading_pairs
    async with client.get(f"{constants.REST_URL}{constants.GET_TRADING_PAIRS}",
  File "/home/knight/miniconda3/envs/hummingbot/lib/python3.8/site-packages/aiohttp/client.py", line 1117, in __aenter__
    self._resp = await self._coro
  File "/home/knight/miniconda3/envs/hummingbot/lib/python3.8/site-packages/aiohttp/client.py", line 619, in _request
    break
  File "/home/knight/miniconda3/envs/hummingbot/lib/python3.8/site-packages/aiohttp/helpers.py", line 656, in __exit__
    raise asyncio.TimeoutError from None
asyncio.exceptions.TimeoutError
2022-06-28 11:36:44,290 - 277 - hummingbot.core.utils.trading_pair_fetcher - ERROR - Connector wazirx failed to retrieve its trading pairs. Trading pairs autocompletion won't work.
Traceback (most recent call last):
  File "/mnt/e/Projects/hummingbot/hummingbot/hummingbot/core/utils/trading_pair_fetcher.py", line 74, in call_fetch_pairs
    self.trading_pairs[exchange_name] = await fetch_fn
  File "/mnt/e/Projects/hummingbot/hummingbot/hummingbot/connector/exchange/wazirx/wazirx_api_order_book_data_source.py", line 82, in fetch_trading_pairs
    async with client.get(f"{CONSTANTS.WAZIRX_API_BASE}/{CONSTANTS.GET_EXCHANGE_INFO}", timeout=10) as response:
  File "/home/knight/miniconda3/envs/hummingbot/lib/python3.8/site-packages/aiohttp/client.py", line 1117, in __aenter__
    self._resp = await self._coro
  File "/home/knight/miniconda3/envs/hummingbot/lib/python3.8/site-packages/aiohttp/client.py", line 619, in _request
    break
  File "/home/knight/miniconda3/envs/hummingbot/lib/python3.8/site-packages/aiohttp/helpers.py", line 656, in __exit__
    raise asyncio.TimeoutError from None
asyncio.exceptions.TimeoutError
2022-06-28 11:36:44,343 - 277 - hummingbot.connector.derivative.binance_perpetual.binance_perpetual_api_order_book_data_source - ERROR - There was an error requesting exchange info ()
Traceback (most recent call last):
  File "/mnt/e/Projects/hummingbot/hummingbot/hummingbot/connector/derivative/binance_perpetual/binance_perpetual_api_order_book_data_source.py", line 143, in init_trading_pair_symbols
    data = await web_utils.api_request(
  File "/mnt/e/Projects/hummingbot/hummingbot/hummingbot/connector/derivative/binance_perpetual/binance_perpetual_web_utils.py", line 101, in api_request
    response = await rest_assistant.call(request=request, timeout=timeout)
  File "/mnt/e/Projects/hummingbot/hummingbot/hummingbot/core/web_assistant/rest_assistant.py", line 35, in call
    resp = await wait_for(self._connection.call(request), timeout)
  File "/home/knight/miniconda3/envs/hummingbot/lib/python3.8/asyncio/tasks.py", line 490, in wait_for
    raise exceptions.TimeoutError()
asyncio.exceptions.TimeoutError
2022-06-28 11:36:46,897 - 277 - hummingbot.connector.time_synchronizer - NETWORK - Error getting server time.
Traceback (most recent call last):
  File "/mnt/e/Projects/hummingbot/hummingbot/hummingbot/connector/time_synchronizer.py", line 59, in update_server_time_offset_with_time_provider
    server_time_ms: float = await time_provider
  File "/mnt/e/Projects/hummingbot/hummingbot/hummingbot/connector/exchange/binance/binance_web_utils.py", line 127, in get_current_server_time
    response = await api_request(
  File "/mnt/e/Projects/hummingbot/hummingbot/hummingbot/connector/exchange/binance/binance_web_utils.py", line 115, in api_request
    raise IOError(f"Error executing request {method.name} {path}. "
OSError: Error executing request GET /time. HTTP status is 403. Error: <!DOCTYPE HTML PUBLIC "-//W3C//DTD HTML 4.01 Transitional//EN" "http://www.w3.org/TR/html4/loose.dtd">
<HTML><HEAD><META HTTP-EQUIV="Content-Type" CONTENT="text/html; charset=iso-8859-1">
<TITLE>ERROR: The request could not be satisfied</TITLE>
</HEAD><BODY>
<H1>403 ERROR</H1>
<H2>The request could not be satisfied.</H2>
<HR noshade size="1px">
The Amazon CloudFront distribution is configured to block access from your country.
We can't connect to the server for this app or website at this time. There might be too much traffic or a configuration error. Try again later, or contact the app or website owner.
<BR clear="all">
If you provide content to customers through CloudFront, you can find steps to troubleshoot and help prevent this error by reviewing the CloudFront documentation.
<BR clear="all">
<HR noshade size="1px">
<PRE>
Generated by cloudfront (CloudFront)
Request ID: l9y7JQz5VF7WndgT1_XIzwBH8kMSMUoN3f5s2iTjEkaYZ4dsS71L4g==
</PRE>
<ADDRESS>
</ADDRESS>
</BODY></HTML>
2022-06-28 11:36:47,018 - 277 - hummingbot.connector.time_synchronizer - WARNING - Could not refresh server time. Check network connection.
2022-06-28 11:36:47,210 - 277 - hummingbot.connector.exchange.binance.binance_api_order_book_data_source - ERROR - There was an error requesting exchange info (Error executing request GET /exchangeInfo. HTTP status is 403. Error: <!DOCTYPE HTML PUBLIC "-//W3C//DTD HTML 4.01 Transitional//EN" "http://www.w3.org/TR/html4/loose.dtd">
<HTML><HEAD><META HTTP-EQUIV="Content-Type" CONTENT="text/html; charset=iso-8859-1">
<TITLE>ERROR: The request could not be satisfied</TITLE>
</HEAD><BODY>
<H1>403 ERROR</H1>
<H2>The request could not be satisfied.</H2>
<HR noshade size="1px">
The Amazon CloudFront distribution is configured to block access from your country.
We can't connect to the server for this app or website at this time. There might be too much traffic or a configuration error. Try again later, or contact the app or website owner.
<BR clear="all">
If you provide content to customers through CloudFront, you can find steps to troubleshoot and help prevent this error by reviewing the CloudFront documentation.
<BR clear="all">
<HR noshade size="1px">
<PRE>
Generated by cloudfront (CloudFront)
Request ID: HwA4O-ENB7Kzbgbe5XTjEkC3_2c3rXxIjp172bLCEz7Wekqpt6P9xg==
</PRE>
<ADDRESS>
</ADDRESS>
</BODY></HTML>)
2022-06-28 11:36:47,434 - 277 - hummingbot.connector.exchange.altmarkets.altmarkets_api_order_book_data_source - NETWORK - Error fetching data from https://v2.altmarkets.io/api/v2/peatio/public/markets. HTTP status is 403. Retrying in 7s. <!DOCTYPE html>
<html lang="en">
<head>
    <meta charset="utf-8" />
    <title>AltMarkets.io | Sche ... (truncated)
2022-06-28 16:34:28,521 - 4757 - hummingbot.core.utils.trading_pair_fetcher - ERROR - Connector bitmart failed to retrieve its trading pairs. Trading pairs autocompletion won't work.
Traceback (most recent call last):
  File "/mnt/e/Projects/hummingbot/hummingbot/hummingbot/core/utils/trading_pair_fetcher.py", line 74, in call_fetch_pairs
    self.trading_pairs[exchange_name] = await fetch_fn
  File "/mnt/e/Projects/hummingbot/hummingbot/hummingbot/connector/exchange/bitmart/bitmart_api_order_book_data_source.py", line 89, in fetch_trading_pairs
    response = await rest_assistant.call(request=request, timeout=10)
  File "/mnt/e/Projects/hummingbot/hummingbot/hummingbot/core/web_assistant/rest_assistant.py", line 35, in call
    resp = await wait_for(self._connection.call(request), timeout)
  File "/home/knight/miniconda3/envs/hummingbot/lib/python3.8/asyncio/tasks.py", line 490, in wait_for
    raise exceptions.TimeoutError()
asyncio.exceptions.TimeoutError
2022-06-28 16:34:28,585 - 4757 - root - INFO - Error fetching data from https://api.gateio.ws/api/v4/spot/currency_pairs. HTTP status is None. Retrying in 4s.
2022-06-28 16:34:28,585 - 4757 - root - INFO - Error fetching data from https://api.gateio.ws/api/v4/spot/currency_pairs. HTTP status is None. Retrying in 4s.
2022-06-28 16:34:29,232 - 4757 - hummingbot.core.utils.trading_pair_fetcher - ERROR - Connector k2 failed to retrieve its trading pairs. Trading pairs autocompletion won't work.
Traceback (most recent call last):
  File "/mnt/e/Projects/hummingbot/hummingbot/hummingbot/core/utils/trading_pair_fetcher.py", line 74, in call_fetch_pairs
    self.trading_pairs[exchange_name] = await fetch_fn
  File "/mnt/e/Projects/hummingbot/hummingbot/hummingbot/connector/exchange/k2/k2_api_order_book_data_source.py", line 62, in fetch_trading_pairs
    async with client.get(f"{constants.REST_URL}{constants.GET_TRADING_PAIRS}",
  File "/home/knight/miniconda3/envs/hummingbot/lib/python3.8/site-packages/aiohttp/client.py", line 1117, in __aenter__
    self._resp = await self._coro
  File "/home/knight/miniconda3/envs/hummingbot/lib/python3.8/site-packages/aiohttp/client.py", line 619, in _request
    break
  File "/home/knight/miniconda3/envs/hummingbot/lib/python3.8/site-packages/aiohttp/helpers.py", line 656, in __exit__
    raise asyncio.TimeoutError from None
asyncio.exceptions.TimeoutError
2022-06-28 16:34:29,283 - 4757 - hummingbot.core.utils.trading_pair_fetcher - ERROR - Connector wazirx failed to retrieve its trading pairs. Trading pairs autocompletion won't work.
Traceback (most recent call last):
  File "/mnt/e/Projects/hummingbot/hummingbot/hummingbot/core/utils/trading_pair_fetcher.py", line 74, in call_fetch_pairs
    self.trading_pairs[exchange_name] = await fetch_fn
  File "/mnt/e/Projects/hummingbot/hummingbot/hummingbot/connector/exchange/wazirx/wazirx_api_order_book_data_source.py", line 82, in fetch_trading_pairs
    async with client.get(f"{CONSTANTS.WAZIRX_API_BASE}/{CONSTANTS.GET_EXCHANGE_INFO}", timeout=10) as response:
  File "/home/knight/miniconda3/envs/hummingbot/lib/python3.8/site-packages/aiohttp/client.py", line 1117, in __aenter__
    self._resp = await self._coro
  File "/home/knight/miniconda3/envs/hummingbot/lib/python3.8/site-packages/aiohttp/client.py", line 619, in _request
    break
  File "/home/knight/miniconda3/envs/hummingbot/lib/python3.8/site-packages/aiohttp/helpers.py", line 656, in __exit__
    raise asyncio.TimeoutError from None
asyncio.exceptions.TimeoutError
2022-06-28 16:34:29,674 - 4757 - hummingbot.connector.derivative.binance_perpetual.binance_perpetual_api_order_book_data_source - ERROR - There was an error requesting exchange info ()
Traceback (most recent call last):
  File "/mnt/e/Projects/hummingbot/hummingbot/hummingbot/connector/derivative/binance_perpetual/binance_perpetual_api_order_book_data_source.py", line 143, in init_trading_pair_symbols
    data = await web_utils.api_request(
  File "/mnt/e/Projects/hummingbot/hummingbot/hummingbot/connector/derivative/binance_perpetual/binance_perpetual_web_utils.py", line 101, in api_request
    response = await rest_assistant.call(request=request, timeout=timeout)
  File "/mnt/e/Projects/hummingbot/hummingbot/hummingbot/core/web_assistant/rest_assistant.py", line 35, in call
    resp = await wait_for(self._connection.call(request), timeout)
  File "/home/knight/miniconda3/envs/hummingbot/lib/python3.8/asyncio/tasks.py", line 490, in wait_for
    raise exceptions.TimeoutError()
asyncio.exceptions.TimeoutError
2022-06-28 16:34:35,951 - 4757 - hummingbot.connector.time_synchronizer - NETWORK - Error getting server time.
Traceback (most recent call last):
  File "/mnt/e/Projects/hummingbot/hummingbot/hummingbot/connector/time_synchronizer.py", line 59, in update_server_time_offset_with_time_provider
    server_time_ms: float = await time_provider
  File "/mnt/e/Projects/hummingbot/hummingbot/hummingbot/connector/exchange/binance/binance_web_utils.py", line 127, in get_current_server_time
    response = await api_request(
  File "/mnt/e/Projects/hummingbot/hummingbot/hummingbot/connector/exchange/binance/binance_web_utils.py", line 115, in api_request
    raise IOError(f"Error executing request {method.name} {path}. "
OSError: Error executing request GET /time. HTTP status is 403. Error: <!DOCTYPE HTML PUBLIC "-//W3C//DTD HTML 4.01 Transitional//EN" "http://www.w3.org/TR/html4/loose.dtd">
<HTML><HEAD><META HTTP-EQUIV="Content-Type" CONTENT="text/html; charset=iso-8859-1">
<TITLE>ERROR: The request could not be satisfied</TITLE>
</HEAD><BODY>
<H1>403 ERROR</H1>
<H2>The request could not be satisfied.</H2>
<HR noshade size="1px">
The Amazon CloudFront distribution is configured to block access from your country.
We can't connect to the server for this app or website at this time. There might be too much traffic or a configuration error. Try again later, or contact the app or website owner.
<BR clear="all">
If you provide content to customers through CloudFront, you can find steps to troubleshoot and help prevent this error by reviewing the CloudFront documentation.
<BR clear="all">
<HR noshade size="1px">
<PRE>
Generated by cloudfront (CloudFront)
Request ID: 0kb9gyAfnQUAdJYwv2CBo5wiEJfbdK9zOcVsUQ3Pd15t0Q_ogyChyQ==
</PRE>
<ADDRESS>
</ADDRESS>
</BODY></HTML>
2022-06-28 16:34:36,145 - 4757 - hummingbot.connector.time_synchronizer - WARNING - Could not refresh server time. Check network connection.
2022-06-28 16:34:36,306 - 4757 - hummingbot.connector.exchange.altmarkets.altmarkets_api_order_book_data_source - NETWORK - Error fetching data from https://v2.altmarkets.io/api/v2/peatio/public/markets. HTTP status is 403. Retrying in 8s. <!DOCTYPE html>
<html lang="en">
<head>
    <meta charset="utf-8" />
    <title>AltMarkets.io | Sche ... (truncated)
2022-06-28 16:34:36,392 - 4757 - hummingbot.connector.exchange.binance.binance_api_order_book_data_source - ERROR - There was an error requesting exchange info (Error executing request GET /exchangeInfo. HTTP status is 403. Error: <!DOCTYPE HTML PUBLIC "-//W3C//DTD HTML 4.01 Transitional//EN" "http://www.w3.org/TR/html4/loose.dtd">
<HTML><HEAD><META HTTP-EQUIV="Content-Type" CONTENT="text/html; charset=iso-8859-1">
<TITLE>ERROR: The request could not be satisfied</TITLE>
</HEAD><BODY>
<H1>403 ERROR</H1>
<H2>The request could not be satisfied.</H2>
<HR noshade size="1px">
The Amazon CloudFront distribution is configured to block access from your country.
We can't connect to the server for this app or website at this time. There might be too much traffic or a configuration error. Try again later, or contact the app or website owner.
<BR clear="all">
If you provide content to customers through CloudFront, you can find steps to troubleshoot and help prevent this error by reviewing the CloudFront documentation.
<BR clear="all">
<HR noshade size="1px">
<PRE>
Generated by cloudfront (CloudFront)
Request ID: AoWlas6it1u6BUSC4vOqSxPqsNEGQtn79q2ydvN8cHYnGPzXG_JgNg==
</PRE>
<ADDRESS>
</ADDRESS>
</BODY></HTML>)
2022-06-28 16:34:52,824 - 4757 - hummingbot.connector.exchange.altmarkets.altmarkets_api_order_book_data_source - NETWORK - Error fetching data from https://v2.altmarkets.io/api/v2/peatio/public/markets. HTTP status is 403. Retrying in 32s. <!DOCTYPE html>
<html lang="en">
<head>
    <meta charset="utf-8" />
    <title>AltMarkets.io | Sche ... (truncated)
2022-06-28 16:35:27,047 - 4757 - hummingbot.connector.exchange.altmarkets.altmarkets_api_order_book_data_source - NETWORK - Error fetching data from https://v2.altmarkets.io/api/v2/peatio/public/markets. HTTP status is 403. Retrying in 282s. <!DOCTYPE html>
<html lang="en">
<head>
    <meta charset="utf-8" />
    <title>AltMarkets.io | Sche ... (truncated)
2022-06-28 16:36:45,066 - 4757 - hummingbot.core.utils.trading_pair_fetcher - ERROR - Connector probit_kr failed to retrieve its trading pairs. Trading pairs autocompletion won't work.
Traceback (most recent call last):
  File "/home/knight/miniconda3/envs/hummingbot/lib/python3.8/site-packages/aiohttp/connector.py", line 969, in _wrap_create_connection
    return await self._loop.create_connection(*args, **kwargs)  # type: ignore  # noqa
  File "/home/knight/miniconda3/envs/hummingbot/lib/python3.8/asyncio/base_events.py", line 1025, in create_connection
    raise exceptions[0]
  File "/home/knight/miniconda3/envs/hummingbot/lib/python3.8/asyncio/base_events.py", line 1010, in create_connection
    sock = await self._connect_sock(
  File "/home/knight/miniconda3/envs/hummingbot/lib/python3.8/asyncio/base_events.py", line 924, in _connect_sock
    await self.sock_connect(sock, address)
  File "/home/knight/miniconda3/envs/hummingbot/lib/python3.8/asyncio/selector_events.py", line 494, in sock_connect
    return await fut
  File "/home/knight/miniconda3/envs/hummingbot/lib/python3.8/asyncio/selector_events.py", line 526, in _sock_connect_cb
    raise OSError(err, f'Connect call failed {address}')
TimeoutError: [Errno 110] Connect call failed ('55.28.36.18', 443)

The above exception was the direct cause of the following exception:

Traceback (most recent call last):
  File "/mnt/e/Projects/hummingbot/hummingbot/hummingbot/core/utils/trading_pair_fetcher.py", line 74, in call_fetch_pairs
    self.trading_pairs[exchange_name] = await fetch_fn
  File "/mnt/e/Projects/hummingbot/hummingbot/hummingbot/connector/exchange/probit/probit_api_order_book_data_source.py", line 81, in fetch_trading_pairs
    async with client.get(f"{CONSTANTS.MARKETS_URL.format(domain)}") as response:
  File "/home/knight/miniconda3/envs/hummingbot/lib/python3.8/site-packages/aiohttp/client.py", line 1117, in __aenter__
    self._resp = await self._coro
  File "/home/knight/miniconda3/envs/hummingbot/lib/python3.8/site-packages/aiohttp/client.py", line 520, in _request
    conn = await self._connector.connect(
  File "/home/knight/miniconda3/envs/hummingbot/lib/python3.8/site-packages/aiohttp/connector.py", line 535, in connect
    proto = await self._create_connection(req, traces, timeout)
  File "/home/knight/miniconda3/envs/hummingbot/lib/python3.8/site-packages/aiohttp/connector.py", line 892, in _create_connection
    _, proto = await self._create_direct_connection(req, traces, timeout)
  File "/home/knight/miniconda3/envs/hummingbot/lib/python3.8/site-packages/aiohttp/connector.py", line 1051, in _create_direct_connection
    raise last_exc
  File "/home/knight/miniconda3/envs/hummingbot/lib/python3.8/site-packages/aiohttp/connector.py", line 1020, in _create_direct_connection
    transp, proto = await self._wrap_create_connection(
  File "/home/knight/miniconda3/envs/hummingbot/lib/python3.8/site-packages/aiohttp/connector.py", line 975, in _wrap_create_connection
    raise client_error(req.connection_key, exc) from exc
aiohttp.client_exceptions.ClientConnectorError: Cannot connect to host api.probit.kr:443 ssl:default [Connect call failed ('55.28.36.18', 443)]
2022-06-28 16:53:16,169 - 5894 - hummingbot.connector.exchange.altmarkets.altmarkets_api_order_book_data_source - NETWORK - Error fetching data from https://v2.altmarkets.io/api/v2/peatio/public/markets. HTTP status is 403. Retrying in 4s. <!DOCTYPE html>
<html lang="en">
<head>
    <meta charset="utf-8" />
    <title>AltMarkets.io | Sche ... (truncated)
2022-06-28 16:53:22,142 - 5894 - hummingbot.core.utils.trading_pair_fetcher - ERROR - Connector bitmart failed to retrieve its trading pairs. Trading pairs autocompletion won't work.
Traceback (most recent call last):
  File "/mnt/e/Projects/hummingbot/hummingbot/hummingbot/core/utils/trading_pair_fetcher.py", line 74, in call_fetch_pairs
    self.trading_pairs[exchange_name] = await fetch_fn
  File "/mnt/e/Projects/hummingbot/hummingbot/hummingbot/connector/exchange/bitmart/bitmart_api_order_book_data_source.py", line 89, in fetch_trading_pairs
    response = await rest_assistant.call(request=request, timeout=10)
  File "/mnt/e/Projects/hummingbot/hummingbot/hummingbot/core/web_assistant/rest_assistant.py", line 35, in call
    resp = await wait_for(self._connection.call(request), timeout)
  File "/home/knight/miniconda3/envs/hummingbot/lib/python3.8/asyncio/tasks.py", line 490, in wait_for
    raise exceptions.TimeoutError()
asyncio.exceptions.TimeoutError
2022-06-28 16:53:22,701 - 5894 - hummingbot.core.utils.trading_pair_fetcher - ERROR - Connector k2 failed to retrieve its trading pairs. Trading pairs autocompletion won't work.
Traceback (most recent call last):
  File "/mnt/e/Projects/hummingbot/hummingbot/hummingbot/core/utils/trading_pair_fetcher.py", line 74, in call_fetch_pairs
    self.trading_pairs[exchange_name] = await fetch_fn
  File "/mnt/e/Projects/hummingbot/hummingbot/hummingbot/connector/exchange/k2/k2_api_order_book_data_source.py", line 62, in fetch_trading_pairs
    async with client.get(f"{constants.REST_URL}{constants.GET_TRADING_PAIRS}",
  File "/home/knight/miniconda3/envs/hummingbot/lib/python3.8/site-packages/aiohttp/client.py", line 1117, in __aenter__
    self._resp = await self._coro
  File "/home/knight/miniconda3/envs/hummingbot/lib/python3.8/site-packages/aiohttp/client.py", line 619, in _request
    break
  File "/home/knight/miniconda3/envs/hummingbot/lib/python3.8/site-packages/aiohttp/helpers.py", line 656, in __exit__
    raise asyncio.TimeoutError from None
asyncio.exceptions.TimeoutError
2022-06-28 16:53:22,718 - 5894 - hummingbot.core.utils.trading_pair_fetcher - ERROR - Connector wazirx failed to retrieve its trading pairs. Trading pairs autocompletion won't work.
Traceback (most recent call last):
  File "/mnt/e/Projects/hummingbot/hummingbot/hummingbot/core/utils/trading_pair_fetcher.py", line 74, in call_fetch_pairs
    self.trading_pairs[exchange_name] = await fetch_fn
  File "/mnt/e/Projects/hummingbot/hummingbot/hummingbot/connector/exchange/wazirx/wazirx_api_order_book_data_source.py", line 82, in fetch_trading_pairs
    async with client.get(f"{CONSTANTS.WAZIRX_API_BASE}/{CONSTANTS.GET_EXCHANGE_INFO}", timeout=10) as response:
  File "/home/knight/miniconda3/envs/hummingbot/lib/python3.8/site-packages/aiohttp/client.py", line 1117, in __aenter__
    self._resp = await self._coro
  File "/home/knight/miniconda3/envs/hummingbot/lib/python3.8/site-packages/aiohttp/client.py", line 619, in _request
    break
  File "/home/knight/miniconda3/envs/hummingbot/lib/python3.8/site-packages/aiohttp/helpers.py", line 656, in __exit__
    raise asyncio.TimeoutError from None
asyncio.exceptions.TimeoutError
2022-06-28 16:53:22,744 - 5894 - root - INFO - Error fetching data from https://api.gateio.ws/api/v4/spot/currency_pairs. HTTP status is None. Retrying in 4s.
2022-06-28 16:53:22,745 - 5894 - root - INFO - Error fetching data from https://api.gateio.ws/api/v4/spot/currency_pairs. HTTP status is None. Retrying in 4s.
2022-06-28 16:53:23,261 - 5894 - hummingbot.connector.derivative.binance_perpetual.binance_perpetual_api_order_book_data_source - ERROR - There was an error requesting exchange info ()
Traceback (most recent call last):
  File "/mnt/e/Projects/hummingbot/hummingbot/hummingbot/connector/derivative/binance_perpetual/binance_perpetual_api_order_book_data_source.py", line 143, in init_trading_pair_symbols
    data = await web_utils.api_request(
  File "/mnt/e/Projects/hummingbot/hummingbot/hummingbot/connector/derivative/binance_perpetual/binance_perpetual_web_utils.py", line 101, in api_request
    response = await rest_assistant.call(request=request, timeout=timeout)
  File "/mnt/e/Projects/hummingbot/hummingbot/hummingbot/core/web_assistant/rest_assistant.py", line 35, in call
    resp = await wait_for(self._connection.call(request), timeout)
  File "/home/knight/miniconda3/envs/hummingbot/lib/python3.8/asyncio/tasks.py", line 490, in wait_for
    raise exceptions.TimeoutError()
asyncio.exceptions.TimeoutError
2022-06-28 16:53:30,249 - 5894 - hummingbot.connector.exchange.altmarkets.altmarkets_api_order_book_data_source - NETWORK - Error fetching data from https://v2.altmarkets.io/api/v2/peatio/public/markets. HTTP status is 403. Retrying in 7s. <!DOCTYPE html>
<html lang="en">
<head>
    <meta charset="utf-8" />
    <title>AltMarkets.io | Sche ... (truncated)
2022-06-28 16:53:31,456 - 5894 - hummingbot.connector.time_synchronizer - NETWORK - Error getting server time.
Traceback (most recent call last):
  File "/mnt/e/Projects/hummingbot/hummingbot/hummingbot/connector/time_synchronizer.py", line 59, in update_server_time_offset_with_time_provider
    server_time_ms: float = await time_provider
  File "/mnt/e/Projects/hummingbot/hummingbot/hummingbot/connector/exchange/binance/binance_web_utils.py", line 127, in get_current_server_time
    response = await api_request(
  File "/mnt/e/Projects/hummingbot/hummingbot/hummingbot/connector/exchange/binance/binance_web_utils.py", line 115, in api_request
    raise IOError(f"Error executing request {method.name} {path}. "
OSError: Error executing request GET /time. HTTP status is 403. Error: <!DOCTYPE HTML PUBLIC "-//W3C//DTD HTML 4.01 Transitional//EN" "http://www.w3.org/TR/html4/loose.dtd">
<HTML><HEAD><META HTTP-EQUIV="Content-Type" CONTENT="text/html; charset=iso-8859-1">
<TITLE>ERROR: The request could not be satisfied</TITLE>
</HEAD><BODY>
<H1>403 ERROR</H1>
<H2>The request could not be satisfied.</H2>
<HR noshade size="1px">
The Amazon CloudFront distribution is configured to block access from your country.
We can't connect to the server for this app or website at this time. There might be too much traffic or a configuration error. Try again later, or contact the app or website owner.
<BR clear="all">
If you provide content to customers through CloudFront, you can find steps to troubleshoot and help prevent this error by reviewing the CloudFront documentation.
<BR clear="all">
<HR noshade size="1px">
<PRE>
Generated by cloudfront (CloudFront)
Request ID: OJnKPAmIFmMK24MoWnhs4Reak53sZpaGzjb3kdDXSJ4iN8T1iH_jDA==
</PRE>
<ADDRESS>
</ADDRESS>
</BODY></HTML>
2022-06-28 16:53:31,508 - 5894 - hummingbot.connector.time_synchronizer - WARNING - Could not refresh server time. Check network connection.
2022-06-28 16:53:31,802 - 5894 - hummingbot.connector.exchange.binance.binance_api_order_book_data_source - ERROR - There was an error requesting exchange info (Error executing request GET /exchangeInfo. HTTP status is 403. Error: <!DOCTYPE HTML PUBLIC "-//W3C//DTD HTML 4.01 Transitional//EN" "http://www.w3.org/TR/html4/loose.dtd">
<HTML><HEAD><META HTTP-EQUIV="Content-Type" CONTENT="text/html; charset=iso-8859-1">
<TITLE>ERROR: The request could not be satisfied</TITLE>
</HEAD><BODY>
<H1>403 ERROR</H1>
<H2>The request could not be satisfied.</H2>
<HR noshade size="1px">
The Amazon CloudFront distribution is configured to block access from your country.
We can't connect to the server for this app or website at this time. There might be too much traffic or a configuration error. Try again later, or contact the app or website owner.
<BR clear="all">
If you provide content to customers through CloudFront, you can find steps to troubleshoot and help prevent this error by reviewing the CloudFront documentation.
<BR clear="all">
<HR noshade size="1px">
<PRE>
Generated by cloudfront (CloudFront)
Request ID: WVmRf9U2uKiLmhH1BEzgOWXhgpT_vq4izwZEMr4T-czXDg6T4MzyCA==
</PRE>
<ADDRESS>
</ADDRESS>
</BODY></HTML>)
2022-06-28 16:53:39,914 - 5894 - hummingbot.connector.exchange.altmarkets.altmarkets_api_order_book_data_source - NETWORK - Error fetching data from https://v2.altmarkets.io/api/v2/peatio/public/markets. HTTP status is 403. Retrying in 31s. <!DOCTYPE html>
<html lang="en">
<head>
    <meta charset="utf-8" />
    <title>AltMarkets.io | Sche ... (truncated)
2022-06-28 16:54:14,429 - 5894 - hummingbot.connector.exchange.altmarkets.altmarkets_api_order_book_data_source - NETWORK - Error fetching data from https://v2.altmarkets.io/api/v2/peatio/public/markets. HTTP status is 403. Retrying in 280s. <!DOCTYPE html>
<html lang="en">
<head>
    <meta charset="utf-8" />
    <title>AltMarkets.io | Sche ... (truncated)
2022-06-28 16:55:36,586 - 5894 - hummingbot.core.utils.trading_pair_fetcher - ERROR - Connector probit_kr failed to retrieve its trading pairs. Trading pairs autocompletion won't work.
Traceback (most recent call last):
  File "/home/knight/miniconda3/envs/hummingbot/lib/python3.8/site-packages/aiohttp/connector.py", line 969, in _wrap_create_connection
    return await self._loop.create_connection(*args, **kwargs)  # type: ignore  # noqa
  File "/home/knight/miniconda3/envs/hummingbot/lib/python3.8/asyncio/base_events.py", line 1025, in create_connection
    raise exceptions[0]
  File "/home/knight/miniconda3/envs/hummingbot/lib/python3.8/asyncio/base_events.py", line 1010, in create_connection
    sock = await self._connect_sock(
  File "/home/knight/miniconda3/envs/hummingbot/lib/python3.8/asyncio/base_events.py", line 924, in _connect_sock
    await self.sock_connect(sock, address)
  File "/home/knight/miniconda3/envs/hummingbot/lib/python3.8/asyncio/selector_events.py", line 494, in sock_connect
    return await fut
  File "/home/knight/miniconda3/envs/hummingbot/lib/python3.8/asyncio/selector_events.py", line 526, in _sock_connect_cb
    raise OSError(err, f'Connect call failed {address}')
TimeoutError: [Errno 110] Connect call failed ('55.28.36.18', 443)

The above exception was the direct cause of the following exception:

Traceback (most recent call last):
  File "/mnt/e/Projects/hummingbot/hummingbot/hummingbot/core/utils/trading_pair_fetcher.py", line 74, in call_fetch_pairs
    self.trading_pairs[exchange_name] = await fetch_fn
  File "/mnt/e/Projects/hummingbot/hummingbot/hummingbot/connector/exchange/probit/probit_api_order_book_data_source.py", line 81, in fetch_trading_pairs
    async with client.get(f"{CONSTANTS.MARKETS_URL.format(domain)}") as response:
  File "/home/knight/miniconda3/envs/hummingbot/lib/python3.8/site-packages/aiohttp/client.py", line 1117, in __aenter__
    self._resp = await self._coro
  File "/home/knight/miniconda3/envs/hummingbot/lib/python3.8/site-packages/aiohttp/client.py", line 520, in _request
    conn = await self._connector.connect(
  File "/home/knight/miniconda3/envs/hummingbot/lib/python3.8/site-packages/aiohttp/connector.py", line 535, in connect
    proto = await self._create_connection(req, traces, timeout)
  File "/home/knight/miniconda3/envs/hummingbot/lib/python3.8/site-packages/aiohttp/connector.py", line 892, in _create_connection
    _, proto = await self._create_direct_connection(req, traces, timeout)
  File "/home/knight/miniconda3/envs/hummingbot/lib/python3.8/site-packages/aiohttp/connector.py", line 1051, in _create_direct_connection
    raise last_exc
  File "/home/knight/miniconda3/envs/hummingbot/lib/python3.8/site-packages/aiohttp/connector.py", line 1020, in _create_direct_connection
    transp, proto = await self._wrap_create_connection(
  File "/home/knight/miniconda3/envs/hummingbot/lib/python3.8/site-packages/aiohttp/connector.py", line 975, in _wrap_create_connection
    raise client_error(req.connection_key, exc) from exc
aiohttp.client_exceptions.ClientConnectorError: Cannot connect to host api.probit.kr:443 ssl:default [Connect call failed ('55.28.36.18', 443)]
2022-06-28 17:03:38,492 - 6897 - hummingbot.connector.exchange.altmarkets.altmarkets_api_order_book_data_source - NETWORK - Error fetching data from https://v2.altmarkets.io/api/v2/peatio/public/markets. HTTP status is 403. Retrying in 4s. <!DOCTYPE html>
<html lang="en">
<head>
    <meta charset="utf-8" />
    <title>AltMarkets.io | Sche ... (truncated)
2022-06-28 17:03:47,665 - 6897 - hummingbot.core.utils.trading_pair_fetcher - ERROR - Connector digifinex failed to retrieve its trading pairs. Trading pairs autocompletion won't work.
Traceback (most recent call last):
  File "/mnt/e/Projects/hummingbot/hummingbot/hummingbot/core/utils/trading_pair_fetcher.py", line 74, in call_fetch_pairs
    self.trading_pairs[exchange_name] = await fetch_fn
  File "/mnt/e/Projects/hummingbot/hummingbot/hummingbot/connector/exchange/digifinex/digifinex_api_order_book_data_source.py", line 57, in fetch_trading_pairs
    async with client.get(f"{constants.REST_URL}/ticker", timeout=10) as response:
  File "/home/knight/miniconda3/envs/hummingbot/lib/python3.8/site-packages/aiohttp/client.py", line 1117, in __aenter__
    self._resp = await self._coro
  File "/home/knight/miniconda3/envs/hummingbot/lib/python3.8/site-packages/aiohttp/client.py", line 619, in _request
    break
  File "/home/knight/miniconda3/envs/hummingbot/lib/python3.8/site-packages/aiohttp/helpers.py", line 656, in __exit__
    raise asyncio.TimeoutError from None
asyncio.exceptions.TimeoutError
2022-06-28 17:03:47,937 - 6897 - hummingbot.core.utils.trading_pair_fetcher - ERROR - Connector crypto_com failed to retrieve its trading pairs. Trading pairs autocompletion won't work.
Traceback (most recent call last):
  File "/mnt/e/Projects/hummingbot/hummingbot/hummingbot/core/utils/trading_pair_fetcher.py", line 74, in call_fetch_pairs
    self.trading_pairs[exchange_name] = await fetch_fn
  File "/mnt/e/Projects/hummingbot/hummingbot/hummingbot/connector/exchange/crypto_com/crypto_com_api_order_book_data_source.py", line 85, in fetch_trading_pairs
    async with client.get(url=url, timeout=10) as response:
  File "/home/knight/miniconda3/envs/hummingbot/lib/python3.8/site-packages/aiohttp/client.py", line 1117, in __aenter__
    self._resp = await self._coro
  File "/home/knight/miniconda3/envs/hummingbot/lib/python3.8/site-packages/aiohttp/client.py", line 544, in _request
    await resp.start(conn)
  File "/home/knight/miniconda3/envs/hummingbot/lib/python3.8/site-packages/aiohttp/client_reqrep.py", line 905, in start
    self._continue = None
  File "/home/knight/miniconda3/envs/hummingbot/lib/python3.8/site-packages/aiohttp/helpers.py", line 656, in __exit__
    raise asyncio.TimeoutError from None
asyncio.exceptions.TimeoutError
2022-06-28 17:03:48,042 - 6897 - hummingbot.core.utils.trading_pair_fetcher - ERROR - Connector k2 failed to retrieve its trading pairs. Trading pairs autocompletion won't work.
Traceback (most recent call last):
  File "/mnt/e/Projects/hummingbot/hummingbot/hummingbot/core/utils/trading_pair_fetcher.py", line 74, in call_fetch_pairs
    self.trading_pairs[exchange_name] = await fetch_fn
  File "/mnt/e/Projects/hummingbot/hummingbot/hummingbot/connector/exchange/k2/k2_api_order_book_data_source.py", line 62, in fetch_trading_pairs
    async with client.get(f"{constants.REST_URL}{constants.GET_TRADING_PAIRS}",
  File "/home/knight/miniconda3/envs/hummingbot/lib/python3.8/site-packages/aiohttp/client.py", line 1117, in __aenter__
    self._resp = await self._coro
  File "/home/knight/miniconda3/envs/hummingbot/lib/python3.8/site-packages/aiohttp/client.py", line 619, in _request
    break
  File "/home/knight/miniconda3/envs/hummingbot/lib/python3.8/site-packages/aiohttp/helpers.py", line 656, in __exit__
    raise asyncio.TimeoutError from None
asyncio.exceptions.TimeoutError
2022-06-28 17:03:48,068 - 6897 - hummingbot.core.utils.trading_pair_fetcher - ERROR - Connector wazirx failed to retrieve its trading pairs. Trading pairs autocompletion won't work.
Traceback (most recent call last):
  File "/mnt/e/Projects/hummingbot/hummingbot/hummingbot/core/utils/trading_pair_fetcher.py", line 74, in call_fetch_pairs
    self.trading_pairs[exchange_name] = await fetch_fn
  File "/mnt/e/Projects/hummingbot/hummingbot/hummingbot/connector/exchange/wazirx/wazirx_api_order_book_data_source.py", line 82, in fetch_trading_pairs
    async with client.get(f"{CONSTANTS.WAZIRX_API_BASE}/{CONSTANTS.GET_EXCHANGE_INFO}", timeout=10) as response:
  File "/home/knight/miniconda3/envs/hummingbot/lib/python3.8/site-packages/aiohttp/client.py", line 1117, in __aenter__
    self._resp = await self._coro
  File "/home/knight/miniconda3/envs/hummingbot/lib/python3.8/site-packages/aiohttp/client.py", line 619, in _request
    break
  File "/home/knight/miniconda3/envs/hummingbot/lib/python3.8/site-packages/aiohttp/helpers.py", line 656, in __exit__
    raise asyncio.TimeoutError from None
asyncio.exceptions.TimeoutError
2022-06-28 17:03:48,086 - 6897 - hummingbot.core.utils.trading_pair_fetcher - ERROR - Connector bitmart failed to retrieve its trading pairs. Trading pairs autocompletion won't work.
Traceback (most recent call last):
  File "/mnt/e/Projects/hummingbot/hummingbot/hummingbot/core/utils/trading_pair_fetcher.py", line 74, in call_fetch_pairs
    self.trading_pairs[exchange_name] = await fetch_fn
  File "/mnt/e/Projects/hummingbot/hummingbot/hummingbot/connector/exchange/bitmart/bitmart_api_order_book_data_source.py", line 89, in fetch_trading_pairs
    response = await rest_assistant.call(request=request, timeout=10)
  File "/mnt/e/Projects/hummingbot/hummingbot/hummingbot/core/web_assistant/rest_assistant.py", line 35, in call
    resp = await wait_for(self._connection.call(request), timeout)
  File "/home/knight/miniconda3/envs/hummingbot/lib/python3.8/asyncio/tasks.py", line 490, in wait_for
    raise exceptions.TimeoutError()
asyncio.exceptions.TimeoutError
2022-06-28 17:03:48,116 - 6897 - root - INFO - Error fetching data from https://api.gateio.ws/api/v4/spot/currency_pairs. HTTP status is None. Retrying in 4s.
2022-06-28 17:03:48,116 - 6897 - root - INFO - Error fetching data from https://api.gateio.ws/api/v4/spot/currency_pairs. HTTP status is None. Retrying in 4s.
2022-06-28 17:03:48,117 - 6897 - hummingbot.connector.derivative.binance_perpetual.binance_perpetual_api_order_book_data_source - ERROR - There was an error requesting exchange info ()
Traceback (most recent call last):
  File "/mnt/e/Projects/hummingbot/hummingbot/hummingbot/connector/derivative/binance_perpetual/binance_perpetual_api_order_book_data_source.py", line 143, in init_trading_pair_symbols
    data = await web_utils.api_request(
  File "/mnt/e/Projects/hummingbot/hummingbot/hummingbot/connector/derivative/binance_perpetual/binance_perpetual_web_utils.py", line 101, in api_request
    response = await rest_assistant.call(request=request, timeout=timeout)
  File "/mnt/e/Projects/hummingbot/hummingbot/hummingbot/core/web_assistant/rest_assistant.py", line 35, in call
    resp = await wait_for(self._connection.call(request), timeout)
  File "/home/knight/miniconda3/envs/hummingbot/lib/python3.8/asyncio/tasks.py", line 490, in wait_for
    raise exceptions.TimeoutError()
asyncio.exceptions.TimeoutError
2022-06-28 17:03:51,280 - 6897 - hummingbot.connector.time_synchronizer - NETWORK - Error getting server time.
Traceback (most recent call last):
  File "/mnt/e/Projects/hummingbot/hummingbot/hummingbot/connector/time_synchronizer.py", line 59, in update_server_time_offset_with_time_provider
    server_time_ms: float = await time_provider
  File "/mnt/e/Projects/hummingbot/hummingbot/hummingbot/connector/exchange/binance/binance_web_utils.py", line 127, in get_current_server_time
    response = await api_request(
  File "/mnt/e/Projects/hummingbot/hummingbot/hummingbot/connector/exchange/binance/binance_web_utils.py", line 115, in api_request
    raise IOError(f"Error executing request {method.name} {path}. "
OSError: Error executing request GET /time. HTTP status is 403. Error: <!DOCTYPE HTML PUBLIC "-//W3C//DTD HTML 4.01 Transitional//EN" "http://www.w3.org/TR/html4/loose.dtd">
<HTML><HEAD><META HTTP-EQUIV="Content-Type" CONTENT="text/html; charset=iso-8859-1">
<TITLE>ERROR: The request could not be satisfied</TITLE>
</HEAD><BODY>
<H1>403 ERROR</H1>
<H2>The request could not be satisfied.</H2>
<HR noshade size="1px">
The Amazon CloudFront distribution is configured to block access from your country.
We can't connect to the server for this app or website at this time. There might be too much traffic or a configuration error. Try again later, or contact the app or website owner.
<BR clear="all">
If you provide content to customers through CloudFront, you can find steps to troubleshoot and help prevent this error by reviewing the CloudFront documentation.
<BR clear="all">
<HR noshade size="1px">
<PRE>
Generated by cloudfront (CloudFront)
Request ID: CVOjJJi8Bz_4oNZxedesgEqWRJi4rSAT_szHRHmlAD8Lfy5sFI6EEw==
</PRE>
<ADDRESS>
</ADDRESS>
</BODY></HTML>
2022-06-28 17:03:51,319 - 6897 - hummingbot.connector.time_synchronizer - WARNING - Could not refresh server time. Check network connection.
2022-06-28 17:03:51,577 - 6897 - hummingbot.connector.exchange.binance.binance_api_order_book_data_source - ERROR - There was an error requesting exchange info (Error executing request GET /exchangeInfo. HTTP status is 403. Error: <!DOCTYPE HTML PUBLIC "-//W3C//DTD HTML 4.01 Transitional//EN" "http://www.w3.org/TR/html4/loose.dtd">
<HTML><HEAD><META HTTP-EQUIV="Content-Type" CONTENT="text/html; charset=iso-8859-1">
<TITLE>ERROR: The request could not be satisfied</TITLE>
</HEAD><BODY>
<H1>403 ERROR</H1>
<H2>The request could not be satisfied.</H2>
<HR noshade size="1px">
The Amazon CloudFront distribution is configured to block access from your country.
We can't connect to the server for this app or website at this time. There might be too much traffic or a configuration error. Try again later, or contact the app or website owner.
<BR clear="all">
If you provide content to customers through CloudFront, you can find steps to troubleshoot and help prevent this error by reviewing the CloudFront documentation.
<BR clear="all">
<HR noshade size="1px">
<PRE>
Generated by cloudfront (CloudFront)
Request ID: EyIwGf0eud5_efDNJZl92lZFnRl0saXpZOT2PucuyDjAkPYoEGH0PQ==
</PRE>
<ADDRESS>
</ADDRESS>
</BODY></HTML>)
2022-06-28 17:03:52,963 - 6897 - hummingbot.connector.exchange.altmarkets.altmarkets_api_order_book_data_source - NETWORK - Error fetching data from https://v2.altmarkets.io/api/v2/peatio/public/markets. HTTP status is 403. Retrying in 7s. <!DOCTYPE html>
<html lang="en">
<head>
    <meta charset="utf-8" />
    <title>AltMarkets.io | Sche ... (truncated)
2022-06-28 17:04:09,398 - 6897 - hummingbot.connector.exchange.altmarkets.altmarkets_api_order_book_data_source - NETWORK - Error fetching data from https://v2.altmarkets.io/api/v2/peatio/public/markets. HTTP status is 403. Retrying in 31s. <!DOCTYPE html>
<html lang="en">
<head>
    <meta charset="utf-8" />
    <title>AltMarkets.io | Sche ... (truncated)
2022-06-28 17:04:43,100 - 6897 - hummingbot.connector.exchange.altmarkets.altmarkets_api_order_book_data_source - NETWORK - Error fetching data from https://v2.altmarkets.io/api/v2/peatio/public/markets. HTTP status is 403. Retrying in 277s. <!DOCTYPE html>
<html lang="en">
<head>
    <meta charset="utf-8" />
    <title>AltMarkets.io | Sche ... (truncated)
2022-06-28 17:06:01,227 - 6897 - hummingbot.core.utils.trading_pair_fetcher - ERROR - Connector probit_kr failed to retrieve its trading pairs. Trading pairs autocompletion won't work.
Traceback (most recent call last):
  File "/home/knight/miniconda3/envs/hummingbot/lib/python3.8/site-packages/aiohttp/connector.py", line 969, in _wrap_create_connection
    return await self._loop.create_connection(*args, **kwargs)  # type: ignore  # noqa
  File "/home/knight/miniconda3/envs/hummingbot/lib/python3.8/asyncio/base_events.py", line 1025, in create_connection
    raise exceptions[0]
  File "/home/knight/miniconda3/envs/hummingbot/lib/python3.8/asyncio/base_events.py", line 1010, in create_connection
    sock = await self._connect_sock(
  File "/home/knight/miniconda3/envs/hummingbot/lib/python3.8/asyncio/base_events.py", line 924, in _connect_sock
    await self.sock_connect(sock, address)
  File "/home/knight/miniconda3/envs/hummingbot/lib/python3.8/asyncio/selector_events.py", line 494, in sock_connect
    return await fut
  File "/home/knight/miniconda3/envs/hummingbot/lib/python3.8/asyncio/selector_events.py", line 526, in _sock_connect_cb
    raise OSError(err, f'Connect call failed {address}')
TimeoutError: [Errno 110] Connect call failed ('55.28.36.18', 443)

The above exception was the direct cause of the following exception:

Traceback (most recent call last):
  File "/mnt/e/Projects/hummingbot/hummingbot/hummingbot/core/utils/trading_pair_fetcher.py", line 74, in call_fetch_pairs
    self.trading_pairs[exchange_name] = await fetch_fn
  File "/mnt/e/Projects/hummingbot/hummingbot/hummingbot/connector/exchange/probit/probit_api_order_book_data_source.py", line 81, in fetch_trading_pairs
    async with client.get(f"{CONSTANTS.MARKETS_URL.format(domain)}") as response:
  File "/home/knight/miniconda3/envs/hummingbot/lib/python3.8/site-packages/aiohttp/client.py", line 1117, in __aenter__
    self._resp = await self._coro
  File "/home/knight/miniconda3/envs/hummingbot/lib/python3.8/site-packages/aiohttp/client.py", line 520, in _request
    conn = await self._connector.connect(
  File "/home/knight/miniconda3/envs/hummingbot/lib/python3.8/site-packages/aiohttp/connector.py", line 535, in connect
    proto = await self._create_connection(req, traces, timeout)
  File "/home/knight/miniconda3/envs/hummingbot/lib/python3.8/site-packages/aiohttp/connector.py", line 892, in _create_connection
    _, proto = await self._create_direct_connection(req, traces, timeout)
  File "/home/knight/miniconda3/envs/hummingbot/lib/python3.8/site-packages/aiohttp/connector.py", line 1051, in _create_direct_connection
    raise last_exc
  File "/home/knight/miniconda3/envs/hummingbot/lib/python3.8/site-packages/aiohttp/connector.py", line 1020, in _create_direct_connection
    transp, proto = await self._wrap_create_connection(
  File "/home/knight/miniconda3/envs/hummingbot/lib/python3.8/site-packages/aiohttp/connector.py", line 975, in _wrap_create_connection
    raise client_error(req.connection_key, exc) from exc
aiohttp.client_exceptions.ClientConnectorError: Cannot connect to host api.probit.kr:443 ssl:default [Connect call failed ('55.28.36.18', 443)]
2022-06-28 17:58:25,214 - 7844 - root - ERROR - Cannot find corresponding config to key dexfin_api_key in template.
2022-06-28 17:58:25,228 - 7844 - root - ERROR - Cannot find corresponding config to key dexfin_secret_key in template.
2022-06-28 17:58:33,860 - 7844 - hummingbot.connector.exchange.altmarkets.altmarkets_api_order_book_data_source - NETWORK - Error fetching data from https://v2.altmarkets.io/api/v2/peatio/public/markets. HTTP status is 403. Retrying in 4s. <!DOCTYPE html>
<html lang="en">
<head>
    <meta charset="utf-8" />
    <title>AltMarkets.io | Sche ... (truncated)
2022-06-28 17:58:37,111 - 7844 - hummingbot.core.utils.trading_pair_fetcher - ERROR - Connector bitmart failed to retrieve its trading pairs. Trading pairs autocompletion won't work.
Traceback (most recent call last):
  File "/mnt/e/Projects/hummingbot/hummingbot/hummingbot/core/utils/trading_pair_fetcher.py", line 74, in call_fetch_pairs
    self.trading_pairs[exchange_name] = await fetch_fn
  File "/mnt/e/Projects/hummingbot/hummingbot/hummingbot/connector/exchange/bitmart/bitmart_api_order_book_data_source.py", line 89, in fetch_trading_pairs
    response = await rest_assistant.call(request=request, timeout=10)
  File "/mnt/e/Projects/hummingbot/hummingbot/hummingbot/core/web_assistant/rest_assistant.py", line 35, in call
    resp = await wait_for(self._connection.call(request), timeout)
  File "/home/knight/miniconda3/envs/hummingbot/lib/python3.8/asyncio/tasks.py", line 490, in wait_for
    raise exceptions.TimeoutError()
asyncio.exceptions.TimeoutError
2022-06-28 17:58:37,184 - 7844 - hummingbot.core.utils.trading_pair_fetcher - ERROR - Connector digifinex failed to retrieve its trading pairs. Trading pairs autocompletion won't work.
Traceback (most recent call last):
  File "/home/knight/miniconda3/envs/hummingbot/lib/python3.8/site-packages/aiohttp/connector.py", line 999, in _create_direct_connection
    hosts = await asyncio.shield(host_resolved)
  File "/home/knight/miniconda3/envs/hummingbot/lib/python3.8/site-packages/aiohttp/connector.py", line 865, in _resolve_host
    addrs = await self._resolver.resolve(host, port, family=self._family)
  File "/home/knight/miniconda3/envs/hummingbot/lib/python3.8/site-packages/aiohttp/resolver.py", line 31, in resolve
    infos = await self._loop.getaddrinfo(
  File "/home/knight/miniconda3/envs/hummingbot/lib/python3.8/asyncio/base_events.py", line 825, in getaddrinfo
    return await self.run_in_executor(
  File "/home/knight/miniconda3/envs/hummingbot/lib/python3.8/concurrent/futures/thread.py", line 57, in run
    result = self.fn(*self.args, **self.kwargs)
  File "/home/knight/miniconda3/envs/hummingbot/lib/python3.8/socket.py", line 918, in getaddrinfo
    for res in _socket.getaddrinfo(host, port, family, type, proto, flags):
socket.gaierror: [Errno -3] Temporary failure in name resolution

The above exception was the direct cause of the following exception:

Traceback (most recent call last):
  File "/mnt/e/Projects/hummingbot/hummingbot/hummingbot/core/utils/trading_pair_fetcher.py", line 74, in call_fetch_pairs
    self.trading_pairs[exchange_name] = await fetch_fn
  File "/mnt/e/Projects/hummingbot/hummingbot/hummingbot/connector/exchange/digifinex/digifinex_api_order_book_data_source.py", line 57, in fetch_trading_pairs
    async with client.get(f"{constants.REST_URL}/ticker", timeout=10) as response:
  File "/home/knight/miniconda3/envs/hummingbot/lib/python3.8/site-packages/aiohttp/client.py", line 1117, in __aenter__
    self._resp = await self._coro
  File "/home/knight/miniconda3/envs/hummingbot/lib/python3.8/site-packages/aiohttp/client.py", line 520, in _request
    conn = await self._connector.connect(
  File "/home/knight/miniconda3/envs/hummingbot/lib/python3.8/site-packages/aiohttp/connector.py", line 535, in connect
    proto = await self._create_connection(req, traces, timeout)
  File "/home/knight/miniconda3/envs/hummingbot/lib/python3.8/site-packages/aiohttp/connector.py", line 892, in _create_connection
    _, proto = await self._create_direct_connection(req, traces, timeout)
  File "/home/knight/miniconda3/envs/hummingbot/lib/python3.8/site-packages/aiohttp/connector.py", line 1011, in _create_direct_connection
    raise ClientConnectorError(req.connection_key, exc) from exc
aiohttp.client_exceptions.ClientConnectorError: Cannot connect to host openapi.digifinex.com:443 ssl:default [Temporary failure in name resolution]
2022-06-28 17:58:37,236 - 7844 - root - INFO - Error fetching data from https://api.gateio.ws/api/v4/spot/currency_pairs. HTTP status is None. Retrying in 4s.
2022-06-28 17:58:37,237 - 7844 - root - INFO - Error fetching data from https://api.gateio.ws/api/v4/spot/currency_pairs. HTTP status is None. Retrying in 4s.
2022-06-28 17:58:37,238 - 7844 - hummingbot.core.utils.trading_pair_fetcher - ERROR - Connector k2 failed to retrieve its trading pairs. Trading pairs autocompletion won't work.
Traceback (most recent call last):
  File "/mnt/e/Projects/hummingbot/hummingbot/hummingbot/core/utils/trading_pair_fetcher.py", line 74, in call_fetch_pairs
    self.trading_pairs[exchange_name] = await fetch_fn
  File "/mnt/e/Projects/hummingbot/hummingbot/hummingbot/connector/exchange/k2/k2_api_order_book_data_source.py", line 62, in fetch_trading_pairs
    async with client.get(f"{constants.REST_URL}{constants.GET_TRADING_PAIRS}",
  File "/home/knight/miniconda3/envs/hummingbot/lib/python3.8/site-packages/aiohttp/client.py", line 1117, in __aenter__
    self._resp = await self._coro
  File "/home/knight/miniconda3/envs/hummingbot/lib/python3.8/site-packages/aiohttp/client.py", line 619, in _request
    break
  File "/home/knight/miniconda3/envs/hummingbot/lib/python3.8/site-packages/aiohttp/helpers.py", line 656, in __exit__
    raise asyncio.TimeoutError from None
asyncio.exceptions.TimeoutError
2022-06-28 17:58:37,264 - 7844 - hummingbot.core.utils.trading_pair_fetcher - ERROR - Connector crypto_com failed to retrieve its trading pairs. Trading pairs autocompletion won't work.
Traceback (most recent call last):
  File "/mnt/e/Projects/hummingbot/hummingbot/hummingbot/core/utils/trading_pair_fetcher.py", line 74, in call_fetch_pairs
    self.trading_pairs[exchange_name] = await fetch_fn
  File "/mnt/e/Projects/hummingbot/hummingbot/hummingbot/connector/exchange/crypto_com/crypto_com_api_order_book_data_source.py", line 85, in fetch_trading_pairs
    async with client.get(url=url, timeout=10) as response:
  File "/home/knight/miniconda3/envs/hummingbot/lib/python3.8/site-packages/aiohttp/client.py", line 1117, in __aenter__
    self._resp = await self._coro
  File "/home/knight/miniconda3/envs/hummingbot/lib/python3.8/site-packages/aiohttp/client.py", line 619, in _request
    break
  File "/home/knight/miniconda3/envs/hummingbot/lib/python3.8/site-packages/aiohttp/helpers.py", line 656, in __exit__
    raise asyncio.TimeoutError from None
asyncio.exceptions.TimeoutError
2022-06-28 17:58:37,278 - 7844 - hummingbot.core.utils.trading_pair_fetcher - ERROR - Connector wazirx failed to retrieve its trading pairs. Trading pairs autocompletion won't work.
Traceback (most recent call last):
  File "/mnt/e/Projects/hummingbot/hummingbot/hummingbot/core/utils/trading_pair_fetcher.py", line 74, in call_fetch_pairs
    self.trading_pairs[exchange_name] = await fetch_fn
  File "/mnt/e/Projects/hummingbot/hummingbot/hummingbot/connector/exchange/wazirx/wazirx_api_order_book_data_source.py", line 82, in fetch_trading_pairs
    async with client.get(f"{CONSTANTS.WAZIRX_API_BASE}/{CONSTANTS.GET_EXCHANGE_INFO}", timeout=10) as response:
  File "/home/knight/miniconda3/envs/hummingbot/lib/python3.8/site-packages/aiohttp/client.py", line 1117, in __aenter__
    self._resp = await self._coro
  File "/home/knight/miniconda3/envs/hummingbot/lib/python3.8/site-packages/aiohttp/client.py", line 619, in _request
    break
  File "/home/knight/miniconda3/envs/hummingbot/lib/python3.8/site-packages/aiohttp/helpers.py", line 656, in __exit__
    raise asyncio.TimeoutError from None
asyncio.exceptions.TimeoutError
2022-06-28 17:58:40,083 - 7844 - hummingbot.connector.derivative.binance_perpetual.binance_perpetual_api_order_book_data_source - ERROR - There was an error requesting exchange info ()
Traceback (most recent call last):
  File "/mnt/e/Projects/hummingbot/hummingbot/hummingbot/connector/derivative/binance_perpetual/binance_perpetual_api_order_book_data_source.py", line 143, in init_trading_pair_symbols
    data = await web_utils.api_request(
  File "/mnt/e/Projects/hummingbot/hummingbot/hummingbot/connector/derivative/binance_perpetual/binance_perpetual_web_utils.py", line 101, in api_request
    response = await rest_assistant.call(request=request, timeout=timeout)
  File "/mnt/e/Projects/hummingbot/hummingbot/hummingbot/core/web_assistant/rest_assistant.py", line 35, in call
    resp = await wait_for(self._connection.call(request), timeout)
  File "/home/knight/miniconda3/envs/hummingbot/lib/python3.8/asyncio/tasks.py", line 490, in wait_for
    raise exceptions.TimeoutError()
asyncio.exceptions.TimeoutError
2022-06-28 17:58:40,609 - 7844 - hummingbot.connector.time_synchronizer - NETWORK - Error getting server time.
Traceback (most recent call last):
  File "/home/knight/miniconda3/envs/hummingbot/lib/python3.8/site-packages/aiohttp/connector.py", line 999, in _create_direct_connection
    hosts = await asyncio.shield(host_resolved)
  File "/home/knight/miniconda3/envs/hummingbot/lib/python3.8/site-packages/aiohttp/connector.py", line 865, in _resolve_host
    addrs = await self._resolver.resolve(host, port, family=self._family)
  File "/home/knight/miniconda3/envs/hummingbot/lib/python3.8/site-packages/aiohttp/resolver.py", line 31, in resolve
    infos = await self._loop.getaddrinfo(
  File "/home/knight/miniconda3/envs/hummingbot/lib/python3.8/asyncio/base_events.py", line 825, in getaddrinfo
    return await self.run_in_executor(
  File "/home/knight/miniconda3/envs/hummingbot/lib/python3.8/concurrent/futures/thread.py", line 57, in run
    result = self.fn(*self.args, **self.kwargs)
  File "/home/knight/miniconda3/envs/hummingbot/lib/python3.8/socket.py", line 918, in getaddrinfo
    for res in _socket.getaddrinfo(host, port, family, type, proto, flags):
socket.gaierror: [Errno -3] Temporary failure in name resolution

The above exception was the direct cause of the following exception:

Traceback (most recent call last):
  File "/mnt/e/Projects/hummingbot/hummingbot/hummingbot/connector/time_synchronizer.py", line 59, in update_server_time_offset_with_time_provider
    server_time_ms: float = await time_provider
  File "/mnt/e/Projects/hummingbot/hummingbot/hummingbot/connector/exchange/kucoin/kucoin_web_utils.py", line 121, in get_current_server_time
    response = await api_request(
  File "/mnt/e/Projects/hummingbot/hummingbot/hummingbot/connector/exchange/kucoin/kucoin_web_utils.py", line 99, in api_request
    response = await rest_assistant.call(request=request, timeout=timeout)
  File "/mnt/e/Projects/hummingbot/hummingbot/hummingbot/core/web_assistant/rest_assistant.py", line 35, in call
    resp = await wait_for(self._connection.call(request), timeout)
  File "/home/knight/miniconda3/envs/hummingbot/lib/python3.8/asyncio/tasks.py", line 455, in wait_for
    return await fut
  File "/mnt/e/Projects/hummingbot/hummingbot/hummingbot/core/web_assistant/connections/rest_connection.py", line 10, in call
    aiohttp_resp = await self._client_session.request(
  File "/home/knight/miniconda3/envs/hummingbot/lib/python3.8/site-packages/aiohttp/client.py", line 520, in _request
    conn = await self._connector.connect(
  File "/home/knight/miniconda3/envs/hummingbot/lib/python3.8/site-packages/aiohttp/connector.py", line 535, in connect
    proto = await self._create_connection(req, traces, timeout)
  File "/home/knight/miniconda3/envs/hummingbot/lib/python3.8/site-packages/aiohttp/connector.py", line 892, in _create_connection
    _, proto = await self._create_direct_connection(req, traces, timeout)
  File "/home/knight/miniconda3/envs/hummingbot/lib/python3.8/site-packages/aiohttp/connector.py", line 1011, in _create_direct_connection
    raise ClientConnectorError(req.connection_key, exc) from exc
aiohttp.client_exceptions.ClientConnectorError: Cannot connect to host api.kucoin.com:443 ssl:default [Temporary failure in name resolution]
2022-06-28 17:58:40,646 - 7844 - hummingbot.connector.time_synchronizer - WARNING - Could not refresh server time. Check network connection.
2022-06-28 17:58:44,742 - 7844 - hummingbot.core.utils.trading_pair_fetcher - ERROR - Connector ndax_testnet failed to retrieve its trading pairs. Trading pairs autocompletion won't work.
Traceback (most recent call last):
  File "/home/knight/miniconda3/envs/hummingbot/lib/python3.8/site-packages/aiohttp/connector.py", line 999, in _create_direct_connection
    hosts = await asyncio.shield(host_resolved)
  File "/home/knight/miniconda3/envs/hummingbot/lib/python3.8/site-packages/aiohttp/connector.py", line 865, in _resolve_host
    addrs = await self._resolver.resolve(host, port, family=self._family)
  File "/home/knight/miniconda3/envs/hummingbot/lib/python3.8/site-packages/aiohttp/resolver.py", line 31, in resolve
    infos = await self._loop.getaddrinfo(
  File "/home/knight/miniconda3/envs/hummingbot/lib/python3.8/asyncio/base_events.py", line 825, in getaddrinfo
    return await self.run_in_executor(
  File "/home/knight/miniconda3/envs/hummingbot/lib/python3.8/concurrent/futures/thread.py", line 57, in run
    result = self.fn(*self.args, **self.kwargs)
  File "/home/knight/miniconda3/envs/hummingbot/lib/python3.8/socket.py", line 918, in getaddrinfo
    for res in _socket.getaddrinfo(host, port, family, type, proto, flags):
socket.gaierror: [Errno -3] Temporary failure in name resolution

The above exception was the direct cause of the following exception:

Traceback (most recent call last):
  File "/mnt/e/Projects/hummingbot/hummingbot/hummingbot/core/utils/trading_pair_fetcher.py", line 74, in call_fetch_pairs
    self.trading_pairs[exchange_name] = await fetch_fn
  File "/mnt/e/Projects/hummingbot/hummingbot/hummingbot/connector/exchange/ndax/ndax_api_order_book_data_source.py", line 140, in fetch_trading_pairs
    async with client.get(
  File "/home/knight/miniconda3/envs/hummingbot/lib/python3.8/site-packages/aiohttp/client.py", line 1117, in __aenter__
    self._resp = await self._coro
  File "/home/knight/miniconda3/envs/hummingbot/lib/python3.8/site-packages/aiohttp/client.py", line 520, in _request
    conn = await self._connector.connect(
  File "/home/knight/miniconda3/envs/hummingbot/lib/python3.8/site-packages/aiohttp/connector.py", line 535, in connect
    proto = await self._create_connection(req, traces, timeout)
  File "/home/knight/miniconda3/envs/hummingbot/lib/python3.8/site-packages/aiohttp/connector.py", line 892, in _create_connection
    _, proto = await self._create_direct_connection(req, traces, timeout)
  File "/home/knight/miniconda3/envs/hummingbot/lib/python3.8/site-packages/aiohttp/connector.py", line 1011, in _create_direct_connection
    raise ClientConnectorError(req.connection_key, exc) from exc
aiohttp.client_exceptions.ClientConnectorError: Cannot connect to host ndaxmarginstaging.cdnhop.net:8443 ssl:default [Temporary failure in name resolution]
2022-06-28 17:58:46,074 - 7844 - hummingbot.core.utils.trading_pair_fetcher - ERROR - Connector okex failed to retrieve its trading pairs. Trading pairs autocompletion won't work.
Traceback (most recent call last):
  File "/home/knight/miniconda3/envs/hummingbot/lib/python3.8/site-packages/aiohttp/connector.py", line 999, in _create_direct_connection
    hosts = await asyncio.shield(host_resolved)
  File "/home/knight/miniconda3/envs/hummingbot/lib/python3.8/site-packages/aiohttp/connector.py", line 865, in _resolve_host
    addrs = await self._resolver.resolve(host, port, family=self._family)
  File "/home/knight/miniconda3/envs/hummingbot/lib/python3.8/site-packages/aiohttp/resolver.py", line 31, in resolve
    infos = await self._loop.getaddrinfo(
  File "/home/knight/miniconda3/envs/hummingbot/lib/python3.8/asyncio/base_events.py", line 825, in getaddrinfo
    return await self.run_in_executor(
  File "/home/knight/miniconda3/envs/hummingbot/lib/python3.8/concurrent/futures/thread.py", line 57, in run
    result = self.fn(*self.args, **self.kwargs)
  File "/home/knight/miniconda3/envs/hummingbot/lib/python3.8/socket.py", line 918, in getaddrinfo
    for res in _socket.getaddrinfo(host, port, family, type, proto, flags):
socket.gaierror: [Errno -3] Temporary failure in name resolution

The above exception was the direct cause of the following exception:

Traceback (most recent call last):
  File "/mnt/e/Projects/hummingbot/hummingbot/hummingbot/core/utils/trading_pair_fetcher.py", line 74, in call_fetch_pairs
    self.trading_pairs[exchange_name] = await fetch_fn
  File "/mnt/e/Projects/hummingbot/hummingbot/hummingbot/connector/exchange/okex/okex_api_order_book_data_source.py", line 56, in fetch_trading_pairs
    async with client.get(OKEX_INSTRUMENTS_URL) as products_response:
  File "/home/knight/miniconda3/envs/hummingbot/lib/python3.8/site-packages/aiohttp/client.py", line 1117, in __aenter__
    self._resp = await self._coro
  File "/home/knight/miniconda3/envs/hummingbot/lib/python3.8/site-packages/aiohttp/client.py", line 520, in _request
    conn = await self._connector.connect(
  File "/home/knight/miniconda3/envs/hummingbot/lib/python3.8/site-packages/aiohttp/connector.py", line 535, in connect
    proto = await self._create_connection(req, traces, timeout)
  File "/home/knight/miniconda3/envs/hummingbot/lib/python3.8/site-packages/aiohttp/connector.py", line 892, in _create_connection
    _, proto = await self._create_direct_connection(req, traces, timeout)
  File "/home/knight/miniconda3/envs/hummingbot/lib/python3.8/site-packages/aiohttp/connector.py", line 1011, in _create_direct_connection
    raise ClientConnectorError(req.connection_key, exc) from exc
aiohttp.client_exceptions.ClientConnectorError: Cannot connect to host www.okex.com:443 ssl:default [Temporary failure in name resolution]
2022-06-28 17:58:46,402 - 7844 - hummingbot.core.utils.trading_pair_fetcher - ERROR - Connector probit failed to retrieve its trading pairs. Trading pairs autocompletion won't work.
Traceback (most recent call last):
  File "/home/knight/miniconda3/envs/hummingbot/lib/python3.8/site-packages/aiohttp/connector.py", line 999, in _create_direct_connection
    hosts = await asyncio.shield(host_resolved)
  File "/home/knight/miniconda3/envs/hummingbot/lib/python3.8/site-packages/aiohttp/connector.py", line 865, in _resolve_host
    addrs = await self._resolver.resolve(host, port, family=self._family)
  File "/home/knight/miniconda3/envs/hummingbot/lib/python3.8/site-packages/aiohttp/resolver.py", line 31, in resolve
    infos = await self._loop.getaddrinfo(
  File "/home/knight/miniconda3/envs/hummingbot/lib/python3.8/asyncio/base_events.py", line 825, in getaddrinfo
    return await self.run_in_executor(
  File "/home/knight/miniconda3/envs/hummingbot/lib/python3.8/concurrent/futures/thread.py", line 57, in run
    result = self.fn(*self.args, **self.kwargs)
  File "/home/knight/miniconda3/envs/hummingbot/lib/python3.8/socket.py", line 918, in getaddrinfo
    for res in _socket.getaddrinfo(host, port, family, type, proto, flags):
socket.gaierror: [Errno -3] Temporary failure in name resolution

The above exception was the direct cause of the following exception:

Traceback (most recent call last):
  File "/mnt/e/Projects/hummingbot/hummingbot/hummingbot/core/utils/trading_pair_fetcher.py", line 74, in call_fetch_pairs
    self.trading_pairs[exchange_name] = await fetch_fn
  File "/mnt/e/Projects/hummingbot/hummingbot/hummingbot/connector/exchange/probit/probit_api_order_book_data_source.py", line 81, in fetch_trading_pairs
    async with client.get(f"{CONSTANTS.MARKETS_URL.format(domain)}") as response:
  File "/home/knight/miniconda3/envs/hummingbot/lib/python3.8/site-packages/aiohttp/client.py", line 1117, in __aenter__
    self._resp = await self._coro
  File "/home/knight/miniconda3/envs/hummingbot/lib/python3.8/site-packages/aiohttp/client.py", line 520, in _request
    conn = await self._connector.connect(
  File "/home/knight/miniconda3/envs/hummingbot/lib/python3.8/site-packages/aiohttp/connector.py", line 535, in connect
    proto = await self._create_connection(req, traces, timeout)
  File "/home/knight/miniconda3/envs/hummingbot/lib/python3.8/site-packages/aiohttp/connector.py", line 892, in _create_connection
    _, proto = await self._create_direct_connection(req, traces, timeout)
  File "/home/knight/miniconda3/envs/hummingbot/lib/python3.8/site-packages/aiohttp/connector.py", line 1011, in _create_direct_connection
    raise ClientConnectorError(req.connection_key, exc) from exc
aiohttp.client_exceptions.ClientConnectorError: Cannot connect to host api.probit.com:443 ssl:default [Temporary failure in name resolution]
2022-06-28 17:58:46,459 - 7844 - hummingbot.core.utils.trading_pair_fetcher - ERROR - Connector probit_kr failed to retrieve its trading pairs. Trading pairs autocompletion won't work.
Traceback (most recent call last):
  File "/home/knight/miniconda3/envs/hummingbot/lib/python3.8/site-packages/aiohttp/connector.py", line 999, in _create_direct_connection
    hosts = await asyncio.shield(host_resolved)
  File "/home/knight/miniconda3/envs/hummingbot/lib/python3.8/site-packages/aiohttp/connector.py", line 865, in _resolve_host
    addrs = await self._resolver.resolve(host, port, family=self._family)
  File "/home/knight/miniconda3/envs/hummingbot/lib/python3.8/site-packages/aiohttp/resolver.py", line 31, in resolve
    infos = await self._loop.getaddrinfo(
  File "/home/knight/miniconda3/envs/hummingbot/lib/python3.8/asyncio/base_events.py", line 825, in getaddrinfo
    return await self.run_in_executor(
  File "/home/knight/miniconda3/envs/hummingbot/lib/python3.8/concurrent/futures/thread.py", line 57, in run
    result = self.fn(*self.args, **self.kwargs)
  File "/home/knight/miniconda3/envs/hummingbot/lib/python3.8/socket.py", line 918, in getaddrinfo
    for res in _socket.getaddrinfo(host, port, family, type, proto, flags):
socket.gaierror: [Errno -3] Temporary failure in name resolution

The above exception was the direct cause of the following exception:

Traceback (most recent call last):
  File "/mnt/e/Projects/hummingbot/hummingbot/hummingbot/core/utils/trading_pair_fetcher.py", line 74, in call_fetch_pairs
    self.trading_pairs[exchange_name] = await fetch_fn
  File "/mnt/e/Projects/hummingbot/hummingbot/hummingbot/connector/exchange/probit/probit_api_order_book_data_source.py", line 81, in fetch_trading_pairs
    async with client.get(f"{CONSTANTS.MARKETS_URL.format(domain)}") as response:
  File "/home/knight/miniconda3/envs/hummingbot/lib/python3.8/site-packages/aiohttp/client.py", line 1117, in __aenter__
    self._resp = await self._coro
  File "/home/knight/miniconda3/envs/hummingbot/lib/python3.8/site-packages/aiohttp/client.py", line 520, in _request
    conn = await self._connector.connect(
  File "/home/knight/miniconda3/envs/hummingbot/lib/python3.8/site-packages/aiohttp/connector.py", line 535, in connect
    proto = await self._create_connection(req, traces, timeout)
  File "/home/knight/miniconda3/envs/hummingbot/lib/python3.8/site-packages/aiohttp/connector.py", line 892, in _create_connection
    _, proto = await self._create_direct_connection(req, traces, timeout)
  File "/home/knight/miniconda3/envs/hummingbot/lib/python3.8/site-packages/aiohttp/connector.py", line 1011, in _create_direct_connection
    raise ClientConnectorError(req.connection_key, exc) from exc
aiohttp.client_exceptions.ClientConnectorError: Cannot connect to host api.probit.kr:443 ssl:default [Temporary failure in name resolution]
2022-06-28 17:58:48,231 - 7844 - hummingbot.connector.exchange.altmarkets.altmarkets_api_order_book_data_source - NETWORK - Error fetching data from https://v2.altmarkets.io/api/v2/peatio/public/markets. HTTP status is None. Retrying in 7s. 
2022-06-28 17:58:53,923 - 7844 - hummingbot.connector.time_synchronizer - NETWORK - Error getting server time.
Traceback (most recent call last):
  File "/mnt/e/Projects/hummingbot/hummingbot/hummingbot/connector/time_synchronizer.py", line 59, in update_server_time_offset_with_time_provider
    server_time_ms: float = await time_provider
  File "/mnt/e/Projects/hummingbot/hummingbot/hummingbot/connector/exchange/binance/binance_web_utils.py", line 127, in get_current_server_time
    response = await api_request(
  File "/mnt/e/Projects/hummingbot/hummingbot/hummingbot/connector/exchange/binance/binance_web_utils.py", line 115, in api_request
    raise IOError(f"Error executing request {method.name} {path}. "
OSError: Error executing request GET /time. HTTP status is 403. Error: <!DOCTYPE HTML PUBLIC "-//W3C//DTD HTML 4.01 Transitional//EN" "http://www.w3.org/TR/html4/loose.dtd">
<HTML><HEAD><META HTTP-EQUIV="Content-Type" CONTENT="text/html; charset=iso-8859-1">
<TITLE>ERROR: The request could not be satisfied</TITLE>
</HEAD><BODY>
<H1>403 ERROR</H1>
<H2>The request could not be satisfied.</H2>
<HR noshade size="1px">
The Amazon CloudFront distribution is configured to block access from your country.
We can't connect to the server for this app or website at this time. There might be too much traffic or a configuration error. Try again later, or contact the app or website owner.
<BR clear="all">
If you provide content to customers through CloudFront, you can find steps to troubleshoot and help prevent this error by reviewing the CloudFront documentation.
<BR clear="all">
<HR noshade size="1px">
<PRE>
Generated by cloudfront (CloudFront)
Request ID: VI9npDoEBJoS1j43iNGtJ-FEQ6csU33K7zm0dpokVODs2juZAubxrg==
</PRE>
<ADDRESS>
</ADDRESS>
</BODY></HTML>
2022-06-28 17:58:53,972 - 7844 - hummingbot.connector.time_synchronizer - WARNING - Could not refresh server time. Check network connection.
2022-06-28 17:58:55,571 - 7844 - hummingbot.connector.exchange.binance.binance_api_order_book_data_source - ERROR - There was an error requesting exchange info (Error executing request GET /exchangeInfo. HTTP status is 403. Error: <!DOCTYPE HTML PUBLIC "-//W3C//DTD HTML 4.01 Transitional//EN" "http://www.w3.org/TR/html4/loose.dtd">
<HTML><HEAD><META HTTP-EQUIV="Content-Type" CONTENT="text/html; charset=iso-8859-1">
<TITLE>ERROR: The request could not be satisfied</TITLE>
</HEAD><BODY>
<H1>403 ERROR</H1>
<H2>The request could not be satisfied.</H2>
<HR noshade size="1px">
The Amazon CloudFront distribution is configured to block access from your country.
We can't connect to the server for this app or website at this time. There might be too much traffic or a configuration error. Try again later, or contact the app or website owner.
<BR clear="all">
If you provide content to customers through CloudFront, you can find steps to troubleshoot and help prevent this error by reviewing the CloudFront documentation.
<BR clear="all">
<HR noshade size="1px">
<PRE>
Generated by cloudfront (CloudFront)
Request ID: 7INVkS5i-s1MQenekp1cxPDYsMrwXOQJYBfoKXZVRr0dgac7AwG0lw==
</PRE>
<ADDRESS>
</ADDRESS>
</BODY></HTML>)
2022-06-28 17:58:59,302 - 7844 - hummingbot.connector.exchange.altmarkets.altmarkets_api_order_book_data_source - NETWORK - Error fetching data from https://v2.altmarkets.io/api/v2/peatio/public/markets. HTTP status is 403. Retrying in 31s. <!DOCTYPE html>
<html lang="en">
<head>
    <meta charset="utf-8" />
    <title>AltMarkets.io | Sche ... (truncated)
2022-06-28 17:59:32,075 - 7844 - hummingbot.connector.exchange.altmarkets.altmarkets_api_order_book_data_source - NETWORK - Error fetching data from https://v2.altmarkets.io/api/v2/peatio/public/markets. HTTP status is 403. Retrying in 274s. <!DOCTYPE html>
<html lang="en">
<head>
    <meta charset="utf-8" />
    <title>AltMarkets.io | Sche ... (truncated)
2022-06-28 18:16:55,037 - 8935 - root - ERROR - Cannot find corresponding config to key dexfin_api_key in template.
2022-06-28 18:16:55,066 - 8935 - root - ERROR - Cannot find corresponding config to key dexfin_secret_key in template.
2022-06-28 18:17:04,571 - 8935 - hummingbot.connector.exchange.altmarkets.altmarkets_api_order_book_data_source - NETWORK - Error fetching data from https://v2.altmarkets.io/api/v2/peatio/public/markets. HTTP status is 403. Retrying in 4s. <!DOCTYPE html>
<html lang="en">
<head>
    <meta charset="utf-8" />
    <title>AltMarkets.io | Sche ... (truncated)
2022-06-28 18:17:07,760 - 8935 - hummingbot.core.utils.trading_pair_fetcher - ERROR - Connector bitmart failed to retrieve its trading pairs. Trading pairs autocompletion won't work.
Traceback (most recent call last):
  File "/mnt/e/Projects/hummingbot/hummingbot/hummingbot/core/utils/trading_pair_fetcher.py", line 74, in call_fetch_pairs
    self.trading_pairs[exchange_name] = await fetch_fn
  File "/mnt/e/Projects/hummingbot/hummingbot/hummingbot/connector/exchange/bitmart/bitmart_api_order_book_data_source.py", line 89, in fetch_trading_pairs
    response = await rest_assistant.call(request=request, timeout=10)
  File "/mnt/e/Projects/hummingbot/hummingbot/hummingbot/core/web_assistant/rest_assistant.py", line 35, in call
    resp = await wait_for(self._connection.call(request), timeout)
  File "/home/knight/miniconda3/envs/hummingbot/lib/python3.8/asyncio/tasks.py", line 490, in wait_for
    raise exceptions.TimeoutError()
asyncio.exceptions.TimeoutError
2022-06-28 18:17:07,866 - 8935 - root - INFO - Error fetching data from https://api.gateio.ws/api/v4/spot/currency_pairs. HTTP status is None. Retrying in 4s.
2022-06-28 18:17:07,867 - 8935 - root - INFO - Error fetching data from https://api.gateio.ws/api/v4/spot/currency_pairs. HTTP status is None. Retrying in 4s.
2022-06-28 18:17:08,232 - 8935 - hummingbot.core.utils.trading_pair_fetcher - ERROR - Connector wazirx failed to retrieve its trading pairs. Trading pairs autocompletion won't work.
Traceback (most recent call last):
  File "/mnt/e/Projects/hummingbot/hummingbot/hummingbot/core/utils/trading_pair_fetcher.py", line 74, in call_fetch_pairs
    self.trading_pairs[exchange_name] = await fetch_fn
  File "/mnt/e/Projects/hummingbot/hummingbot/hummingbot/connector/exchange/wazirx/wazirx_api_order_book_data_source.py", line 82, in fetch_trading_pairs
    async with client.get(f"{CONSTANTS.WAZIRX_API_BASE}/{CONSTANTS.GET_EXCHANGE_INFO}", timeout=10) as response:
  File "/home/knight/miniconda3/envs/hummingbot/lib/python3.8/site-packages/aiohttp/client.py", line 1117, in __aenter__
    self._resp = await self._coro
  File "/home/knight/miniconda3/envs/hummingbot/lib/python3.8/site-packages/aiohttp/client.py", line 619, in _request
    break
  File "/home/knight/miniconda3/envs/hummingbot/lib/python3.8/site-packages/aiohttp/helpers.py", line 656, in __exit__
    raise asyncio.TimeoutError from None
asyncio.exceptions.TimeoutError
2022-06-28 18:17:09,741 - 8935 - hummingbot.connector.derivative.binance_perpetual.binance_perpetual_api_order_book_data_source - ERROR - There was an error requesting exchange info ()
Traceback (most recent call last):
  File "/mnt/e/Projects/hummingbot/hummingbot/hummingbot/connector/derivative/binance_perpetual/binance_perpetual_api_order_book_data_source.py", line 143, in init_trading_pair_symbols
    data = await web_utils.api_request(
  File "/mnt/e/Projects/hummingbot/hummingbot/hummingbot/connector/derivative/binance_perpetual/binance_perpetual_web_utils.py", line 101, in api_request
    response = await rest_assistant.call(request=request, timeout=timeout)
  File "/mnt/e/Projects/hummingbot/hummingbot/hummingbot/core/web_assistant/rest_assistant.py", line 35, in call
    resp = await wait_for(self._connection.call(request), timeout)
  File "/home/knight/miniconda3/envs/hummingbot/lib/python3.8/asyncio/tasks.py", line 490, in wait_for
    raise exceptions.TimeoutError()
asyncio.exceptions.TimeoutError
2022-06-28 18:17:14,952 - 8935 - hummingbot.connector.exchange.altmarkets.altmarkets_api_order_book_data_source - NETWORK - Error fetching data from https://v2.altmarkets.io/api/v2/peatio/public/markets. HTTP status is 403. Retrying in 7s. <!DOCTYPE html>
<html lang="en">
<head>
    <meta charset="utf-8" />
    <title>AltMarkets.io | Sche ... (truncated)
2022-06-28 18:35:41,417 - 10195 - root - ERROR - Cannot find corresponding config to key dexfin_api_key in template.
2022-06-28 18:35:41,465 - 10195 - root - ERROR - Cannot find corresponding config to key dexfin_secret_key in template.
2022-06-28 18:35:55,214 - 10195 - hummingbot.core.utils.trading_pair_fetcher - ERROR - Connector bitmart failed to retrieve its trading pairs. Trading pairs autocompletion won't work.
Traceback (most recent call last):
  File "/mnt/e/Projects/hummingbot/hummingbot/hummingbot/core/utils/trading_pair_fetcher.py", line 74, in call_fetch_pairs
    self.trading_pairs[exchange_name] = await fetch_fn
  File "/mnt/e/Projects/hummingbot/hummingbot/hummingbot/connector/exchange/bitmart/bitmart_api_order_book_data_source.py", line 89, in fetch_trading_pairs
    response = await rest_assistant.call(request=request, timeout=10)
  File "/mnt/e/Projects/hummingbot/hummingbot/hummingbot/core/web_assistant/rest_assistant.py", line 35, in call
    resp = await wait_for(self._connection.call(request), timeout)
  File "/home/knight/miniconda3/envs/hummingbot/lib/python3.8/asyncio/tasks.py", line 490, in wait_for
    raise exceptions.TimeoutError()
asyncio.exceptions.TimeoutError
2022-06-28 18:35:55,258 - 10195 - hummingbot.core.utils.trading_pair_fetcher - ERROR - Connector k2 failed to retrieve its trading pairs. Trading pairs autocompletion won't work.
Traceback (most recent call last):
  File "/mnt/e/Projects/hummingbot/hummingbot/hummingbot/core/utils/trading_pair_fetcher.py", line 74, in call_fetch_pairs
    self.trading_pairs[exchange_name] = await fetch_fn
  File "/mnt/e/Projects/hummingbot/hummingbot/hummingbot/connector/exchange/k2/k2_api_order_book_data_source.py", line 62, in fetch_trading_pairs
    async with client.get(f"{constants.REST_URL}{constants.GET_TRADING_PAIRS}",
  File "/home/knight/miniconda3/envs/hummingbot/lib/python3.8/site-packages/aiohttp/client.py", line 1117, in __aenter__
    self._resp = await self._coro
  File "/home/knight/miniconda3/envs/hummingbot/lib/python3.8/site-packages/aiohttp/client.py", line 544, in _request
    await resp.start(conn)
  File "/home/knight/miniconda3/envs/hummingbot/lib/python3.8/site-packages/aiohttp/client_reqrep.py", line 905, in start
    self._continue = None
  File "/home/knight/miniconda3/envs/hummingbot/lib/python3.8/site-packages/aiohttp/helpers.py", line 656, in __exit__
    raise asyncio.TimeoutError from None
asyncio.exceptions.TimeoutError
2022-06-28 18:35:55,275 - 10195 - hummingbot.core.utils.trading_pair_fetcher - ERROR - Connector wazirx failed to retrieve its trading pairs. Trading pairs autocompletion won't work.
Traceback (most recent call last):
  File "/mnt/e/Projects/hummingbot/hummingbot/hummingbot/core/utils/trading_pair_fetcher.py", line 74, in call_fetch_pairs
    self.trading_pairs[exchange_name] = await fetch_fn
  File "/mnt/e/Projects/hummingbot/hummingbot/hummingbot/connector/exchange/wazirx/wazirx_api_order_book_data_source.py", line 82, in fetch_trading_pairs
    async with client.get(f"{CONSTANTS.WAZIRX_API_BASE}/{CONSTANTS.GET_EXCHANGE_INFO}", timeout=10) as response:
  File "/home/knight/miniconda3/envs/hummingbot/lib/python3.8/site-packages/aiohttp/client.py", line 1117, in __aenter__
    self._resp = await self._coro
  File "/home/knight/miniconda3/envs/hummingbot/lib/python3.8/site-packages/aiohttp/client.py", line 619, in _request
    break
  File "/home/knight/miniconda3/envs/hummingbot/lib/python3.8/site-packages/aiohttp/helpers.py", line 656, in __exit__
    raise asyncio.TimeoutError from None
asyncio.exceptions.TimeoutError
2022-06-28 18:35:55,307 - 10195 - root - INFO - Error fetching data from https://api.gateio.ws/api/v4/spot/currency_pairs. HTTP status is None. Retrying in 4s.
2022-06-28 18:35:55,308 - 10195 - root - INFO - Error fetching data from https://api.gateio.ws/api/v4/spot/currency_pairs. HTTP status is None. Retrying in 4s.
2022-06-28 18:36:02,726 - 10195 - hummingbot.connector.derivative.binance_perpetual.binance_perpetual_api_order_book_data_source - ERROR - There was an error requesting exchange info ()
Traceback (most recent call last):
  File "/mnt/e/Projects/hummingbot/hummingbot/hummingbot/connector/derivative/binance_perpetual/binance_perpetual_api_order_book_data_source.py", line 143, in init_trading_pair_symbols
    data = await web_utils.api_request(
  File "/mnt/e/Projects/hummingbot/hummingbot/hummingbot/connector/derivative/binance_perpetual/binance_perpetual_web_utils.py", line 101, in api_request
    response = await rest_assistant.call(request=request, timeout=timeout)
  File "/mnt/e/Projects/hummingbot/hummingbot/hummingbot/core/web_assistant/rest_assistant.py", line 35, in call
    resp = await wait_for(self._connection.call(request), timeout)
  File "/home/knight/miniconda3/envs/hummingbot/lib/python3.8/asyncio/tasks.py", line 490, in wait_for
    raise exceptions.TimeoutError()
asyncio.exceptions.TimeoutError
2022-06-28 18:36:07,365 - 10195 - hummingbot.connector.exchange.altmarkets.altmarkets_api_order_book_data_source - NETWORK - Error fetching data from https://v2.altmarkets.io/api/v2/peatio/public/markets. HTTP status is 403. Retrying in 7s. <!DOCTYPE html>
<html lang="en">
<head>
    <meta charset="utf-8" />
    <title>AltMarkets.io | Sche ... (truncated)
2022-06-28 18:36:18,512 - 10195 - hummingbot.connector.exchange.altmarkets.altmarkets_api_order_book_data_source - NETWORK - Error fetching data from https://v2.altmarkets.io/api/v2/peatio/public/markets. HTTP status is 403. Retrying in 31s. <!DOCTYPE html>
<html lang="en">
<head>
    <meta charset="utf-8" />
    <title>AltMarkets.io | Sche ... (truncated)
2022-06-28 18:36:54,292 - 10195 - hummingbot.connector.exchange.altmarkets.altmarkets_api_order_book_data_source - NETWORK - Error fetching data from https://v2.altmarkets.io/api/v2/peatio/public/markets. HTTP status is 403. Retrying in 280s. <!DOCTYPE html>
<html lang="en">
<head>
    <meta charset="utf-8" />
    <title>AltMarkets.io | Sche ... (truncated)
2022-06-28 18:38:10,827 - 10195 - hummingbot.core.utils.trading_pair_fetcher - ERROR - Connector probit_kr failed to retrieve its trading pairs. Trading pairs autocompletion won't work.
Traceback (most recent call last):
  File "/home/knight/miniconda3/envs/hummingbot/lib/python3.8/site-packages/aiohttp/connector.py", line 969, in _wrap_create_connection
    return await self._loop.create_connection(*args, **kwargs)  # type: ignore  # noqa
  File "/home/knight/miniconda3/envs/hummingbot/lib/python3.8/asyncio/base_events.py", line 1025, in create_connection
    raise exceptions[0]
  File "/home/knight/miniconda3/envs/hummingbot/lib/python3.8/asyncio/base_events.py", line 1010, in create_connection
    sock = await self._connect_sock(
  File "/home/knight/miniconda3/envs/hummingbot/lib/python3.8/asyncio/base_events.py", line 924, in _connect_sock
    await self.sock_connect(sock, address)
  File "/home/knight/miniconda3/envs/hummingbot/lib/python3.8/asyncio/selector_events.py", line 494, in sock_connect
    return await fut
  File "/home/knight/miniconda3/envs/hummingbot/lib/python3.8/asyncio/selector_events.py", line 526, in _sock_connect_cb
    raise OSError(err, f'Connect call failed {address}')
TimeoutError: [Errno 110] Connect call failed ('55.28.36.18', 443)

The above exception was the direct cause of the following exception:

Traceback (most recent call last):
  File "/mnt/e/Projects/hummingbot/hummingbot/hummingbot/core/utils/trading_pair_fetcher.py", line 74, in call_fetch_pairs
    self.trading_pairs[exchange_name] = await fetch_fn
  File "/mnt/e/Projects/hummingbot/hummingbot/hummingbot/connector/exchange/probit/probit_api_order_book_data_source.py", line 81, in fetch_trading_pairs
    async with client.get(f"{CONSTANTS.MARKETS_URL.format(domain)}") as response:
  File "/home/knight/miniconda3/envs/hummingbot/lib/python3.8/site-packages/aiohttp/client.py", line 1117, in __aenter__
    self._resp = await self._coro
  File "/home/knight/miniconda3/envs/hummingbot/lib/python3.8/site-packages/aiohttp/client.py", line 520, in _request
    conn = await self._connector.connect(
  File "/home/knight/miniconda3/envs/hummingbot/lib/python3.8/site-packages/aiohttp/connector.py", line 535, in connect
    proto = await self._create_connection(req, traces, timeout)
  File "/home/knight/miniconda3/envs/hummingbot/lib/python3.8/site-packages/aiohttp/connector.py", line 892, in _create_connection
    _, proto = await self._create_direct_connection(req, traces, timeout)
  File "/home/knight/miniconda3/envs/hummingbot/lib/python3.8/site-packages/aiohttp/connector.py", line 1051, in _create_direct_connection
    raise last_exc
  File "/home/knight/miniconda3/envs/hummingbot/lib/python3.8/site-packages/aiohttp/connector.py", line 1020, in _create_direct_connection
    transp, proto = await self._wrap_create_connection(
  File "/home/knight/miniconda3/envs/hummingbot/lib/python3.8/site-packages/aiohttp/connector.py", line 975, in _wrap_create_connection
    raise client_error(req.connection_key, exc) from exc
aiohttp.client_exceptions.ClientConnectorError: Cannot connect to host api.probit.kr:443 ssl:default [Connect call failed ('55.28.36.18', 443)]
2022-06-28 18:38:15,161 - 10195 - hummingbot.core.utils.async_utils - ERROR - Unhandled error in background task: module 'hummingbot.connector.exchange.dexfin.dexfin_exchange' has no attribute 'DexfinExchange'
Traceback (most recent call last):
  File "/mnt/e/Projects/hummingbot/hummingbot/hummingbot/core/utils/async_utils.py", line 9, in safe_wrapper
    return await c
  File "/mnt/e/Projects/hummingbot/hummingbot/hummingbot/client/command/connect_command.py", line 76, in connect_exchange
    err_msg = await asyncio.wait_for(
  File "/home/knight/miniconda3/envs/hummingbot/lib/python3.8/asyncio/tasks.py", line 483, in wait_for
    return fut.result()
  File "/mnt/e/Projects/hummingbot/hummingbot/hummingbot/user/user_balances.py", line 55, in add_exchange
    market = UserBalances.connect_market(exchange, **api_details)
  File "/mnt/e/Projects/hummingbot/hummingbot/hummingbot/user/user_balances.py", line 20, in connect_market
    connector_class = get_connector_class(exchange)
  File "/mnt/e/Projects/hummingbot/hummingbot/hummingbot/client/config/config_helpers.py", line 168, in get_connector_class
    return getattr(mod, conn_setting.class_name())
AttributeError: module 'hummingbot.connector.exchange.dexfin.dexfin_exchange' has no attribute 'DexfinExchange'
